Workbook

Sheet 읽는 법
A1: 외벽 화재위험성 다척도 평가 계산서 — 소형시료(콘·TGA–DSC·FT-IR) · 중규모 · 시뮬레이션 → 건물 위험도
A3: 목적 | B3: 소형시료 시험, 중규모 성능시험, 시뮬레이션이 각각 화재위험성평가 결과를 내고, 같은 단위로 결합되도록 만든 계산서입니다. TGA–DSC는 확산(r_max,air)·지속(f400,air)·급발(용융형) 인자로 위험도에 정량 반영됩니다.
A4: 공통 단위 | B4: 모든 척도의 결과를 '중규모 등가값'으로 바꿉니다: 층당 확산시간 t600(3 m 중공층 시험의 3000 mm 600 K 도달시각)과 버너 소화 후 자립 연소 확률 p_B. 이 두 값이 건물 위험도 모델(facade_fra, NFPA 551 정량법 R = Σ F·C)의 재료 입력입니다.
A5: 척도 | B5: L1 소형시료: 콘칼로리미터(착화·발열·성장, 국내 준불연 판정), TGA–DSC(분해속도·탄화층 산화·용융형), FT-IR(고분자·난연제 식별, 유해가스) / L2 중규모: 3 m 중공층 시험 / L3 시뮬레이션: FDS(PyroSim)로 중규모 재현 → 건물 외벽 시나리오, 시험→실물 비 s 확정 / L4 건물: 사건수목 × 층간 확산 모델, 2중 몬테카를로
A6: 게이트 | B6: 가연성 등급(콘 준불연 기준 미달)이면 TGA 전이함수를 쓰지 않습니다(가연성 PIR(PUR): TGA 예측 812 s, 시험 30 s). 용융형(f400,air < 0.5, EPS)이면 확산 전이함수를 쓰지 않습니다. FT-IR은 고분자·난연제를 확인해 게이트를 검증합니다.
A7: 칸 색 | B7: 노란 바탕 = 입력할 칸 · 파란 글자 = 입력·측정값 · 검은 글자 = 계산식 · 초록 글자 = 다른 시트에서 가져온 값 · 연두 바탕 = 주요 결과 · 회색 기울임 = 형식 예시(가상값, 계산식 확인용 — 실측 아님)
A8: 시트 | B8: 1 체계(척도 × 위험차원) · 2 콘(양식) · 3 TGA(입력됨) · 4 FT-IR(양식) · 5 중규모(입력됨) · 6 전이함수(상수·통계) · 7 통합(베이즈 결합·정합성) · 8 시뮬레이션(양식) · 9 시뮬레이션 정보가치 · 10 위험도 결과 · 11 EFFECT 비교 · 12 시험계획 · 13 검증
A9: 현재 자료 | B9: 있음: TGA–DSC 6종(공기·질소 각 2회), 중공층 시험 5종 11회(+ EPS 가연성 4분 기록 2회). 없음: 콘칼로리미터, FT-IR, FDS 결과(양식과 계산식만 제공). 빈도·분기확률 등 건물 입력은 facade_fra 예시값입니다.
A10: 결과 요약 | B10: TGA 예측은 준불연 탄화형 3종에서 시험과 정합(z −1.5 – 0.9), 가연성 PIR(PUR)에서 크게 불일치(z ≈ −18.5) → 게이트가 필요. 재료 평균 t600의 90 % 구간 폭은 등급만 5.3배 → TGA 1.7배 → 중규모 1.24배 → 통합 1.22배로 줄어듭니다. 건물 위험도 구간은 시험→실물 비 s가 지배 → L3(시뮬레이션)가 다음 단계입니다.
A11: 재현 | B11: python multiscale_fra/multiscale.py → python multiscale_fra/report/build_ms_xlsx.py → recalc. 엑셀 수식과 파이썬 값의 일치는 13_검증.

Sheet 1_체계
A1: ① 다척도 평가 체계 — 6개 위험차원 × 척도별 지표와 자료 상태
A2: [측정] 보유 · [미측정] 시험 필요 · [미수행] 해석 필요 · [불가] 현 방법으로 얻을 수 없음. 마지막 열은 건물 위험도 모델에 들어가는 자리입니다.
A4: 위험 차원 | B4: L1 콘칼로리미터 | C4: L1 TGA–DSC | D4: L1 FT-IR | E4: L2 중규모(3 m 중공층) | F4: L3 시뮬레이션(FDS) | G4: L4 건물 모델 입력
A5: D1 착화성 | B5: t_ig(50 kW/m²), TRP·CHF(다열류속) [미측정] | C5: T_onset,air·T_5% [측정] — 중규모 착화는 시스템 상수(준불연 188–288 s)라 예측력 약함 | D5: 난연제(P=O) 유무 [미측정] | E5: t_ig(시스템 착화) [측정] | F5: 외벽 착화시각 [미수행] | G5: t600 = t_ig + t_sp에 포함
A6: D2 확산성 | B6: pHRR/t_pHRR, b = k_f·Q̇″ − 1 − t_b/t_ig, M = Q̇″^(1/3)/TRP [미측정] | C6: r_max,air → t̂_sp = C_sys/r_max (준불연 탄화형) [측정] | D6: 이소시아누레이트 지수(PIR) [미측정] | E6: t_sp, t600, FRI, P [측정] | F6: 층별 도달시각 → s [미수행] | G6: τ_F = s·t600
A7: D3 발열성 | B7: THR_600(준불연 ≤ 8 MJ/m²), pHRR, EHC [미측정] | C7: 절대량 불가(초기 질량 없음), DSC 미보정 [불가] | D7: — | E7: H600(3000 mm 초과 열량), 최고온도 [측정] | F7: 외벽 HRR, 창 열류속 [미수행] | G7: (현 모델 미반영: 확장 항목)
A8: D4 지속성 | B8: 연소 종료·작열 시간 [미측정] | C8: f400,air(탄화층 산화 몫) → p̂_B [측정] | D8: — | E8: 플래그 B(소화 후 ssr ≥ 1, 3/6 높이) [측정] | F8: 화원 소멸 후 연소 [미수행] | G8: p_B (자립이면 T_stop = ∞)
A9: D5 급발성 | B9: 용융·적하 관찰 [미측정] | C9: 용융형(f400,air < 0.5) [측정] | D9: — | E9: 플래그 A(τ300→600 ≤ 30 s) [측정] | F9: 용융 흐름은 모델 한계 [불가] | G9: (현 모델 미반영: 표시 항목)
A10: D6 유해성 | B10: CO 수율, TSP [미측정] | C10: — | D10: TGA–FTIR: HCN·CO·NCO·HCl [미측정] | E10: 가스 측정 없음 [미측정] | F10: FED(위층 세대) [미수행] | G10: (확장: 노출 인원 → 유해 노출)
A11: G 조성·등급 | B11: 국내 준불연 판정(THR_600 ≤ 8 등) [미측정 · 인증서 등급 사용 중] | C11: 탄화형/용융형 [측정] | D11: 고분자 식별, 난연제 확인 [미측정] | E11: 가연성 PIR(PUR) 30 s 전면 착화 [측정] | F11: — | G11: 게이트: 전이함수 적용 여부
A13: 칸 색: 연두 = 자료 있음, 분홍 = 시험·해석 필요, 회색 = 해당 없음·불가. 지표는 모두 '중규모 등가값'(t600, p_B)으로 바꿔 비교합니다.

Sheet 2_L1_콘
A1: ② L1 콘칼로리미터 (ISO 5660-1) — 입력 양식과 지표 계산
A2: 50 kW/m² 10분 결과로 국내 준불연 판정(게이트)을, 25·35·50·65 kW/m² 착화시간으로 TRP·CHF를 구합니다. 회색 기울임 행은 형식 예시(가상값)입니다.
A4: 변수
A5: A_exp | B5: 노출 면적 (ISO 5660-1, 받침틀 사용) | C5: 0.0088 | D5: m²
A6: k_f | B6: 벽면 화염 길이 계수 (Quintiere) | C6: 0.01 | D6: m²/kW
A7: thr_lim | B7: 준불연: 10분 총방출열량 상한 | C7: 8 | D7: MJ/m²
A8: dur_lim | B8: 준불연: 200 kW/m² 초과 연속시간 상한(미만) | C8: 10 | D8: s
A9: t600_ref_cone | B9: 콘 상대식 기준 t600 (PIR(PUR) 준불연 기하평균) | C9: 1079 | D9: s
A11: A. 시편별 기록 (반복 3회 권장, 면재 포함 · 심재 각각)
A12: 재료 | B12: 시편 | C12: 열류속 q″ (kW/m²) | D12: 두께 (mm) | E12: 면재 | F12: t_ig (s) | G12: pHRR (kW/m²) | H12: t_pHRR (s) | I12: THR_600 (MJ/m²) | J12: THR_total (MJ/m²) | K12: 질량감소 Δm (g) | L12: 200 kW/m² 초과 최대 연속시간 (s) | M12: 관통 균열·구멍·용융 (Y/N) | N12: TSP (m²) | O12: CO 수율 (kg/kg) | P12: FIGRA_콘 = pHRR/t_pHRR | Q12: t_ig/pHRR (Petrella) | R12: EHC (MJ/kg) | S12: t_b = THR/pHRR (s) | T12: b (Quintiere) | U12: 준불연 판정 (50 kW/m²) | V12: 1/√t_ig
A13: 예시(가상값) | B13: E-1 | C13: 50 | D13: 50 | E13: 유 | F13: 42 | G13: 180 | H13: 65 | I13: 6.5 | J13: 14 | K13: 9.5 | L13: 0 | M13: N | N13: 1.2 | O13: 0.05 | P13: =IF(OR(G13="",H13=""),"",G13/H13) -> 2.7692308 | Q13: =IF(OR(F13="",G13=""),"",F13/G13) -> 0.23333333 | R13: =IF(OR(J13="",K13=""),"",J13*A_exp/(K13/1000)) -> 12.968421 | S13: =IF(OR(J13="",G13=""),"",J13*1000/G13) -> 77.777778 | T13: =IF(OR(F13="",G13="",J13=""),"",k_f*G13-1-S13/F13) -> -1.0518519 | U13: =IF(OR(C13<>50,I13="",L13="",M13=""),"",IF(AND(I13<=thr_lim,L13<dur_lim,M13="N"),"충족","미충족")) -> 충족 | V13: =IF(F13="","",1/SQRT(F13)) -> 0.15430335
P14: =IF(OR(G14="",H14=""),"",G14/H14) | Q14: =IF(OR(F14="",G14=""),"",F14/G14) | R14: =IF(OR(J14="",K14=""),"",J14*A_exp/(K14/1000)) | S14: =IF(OR(J14="",G14=""),"",J14*1000/G14) | T14: =IF(OR(F14="",G14="",J14=""),"",k_f*G14-1-S14/F14) | U14: =IF(OR(C14<>50,I14="",L14="",M14=""),"",IF(AND(I14<=thr_lim,L14<dur_lim,M14="N"),"충족","미충족")) | V14: =IF(F14="","",1/SQRT(F14))
P15: =IF(OR(G15="",H15=""),"",G15/H15) | Q15: =IF(OR(F15="",G15=""),"",F15/G15) | R15: =IF(OR(J15="",K15=""),"",J15*A_exp/(K15/1000)) | S15: =IF(OR(J15="",G15=""),"",J15*1000/G15) | T15: =IF(OR(F15="",G15="",J15=""),"",k_f*G15-1-S15/F15) | U15: =IF(OR(C15<>50,I15="",L15="",M15=""),"",IF(AND(I15<=thr_lim,L15<dur_lim,M15="N"),"충족","미충족")) | V15: =IF(F15="","",1/SQRT(F15))
P16: =IF(OR(G16="",H16=""),"",G16/H16) | Q16: =IF(OR(F16="",G16=""),"",F16/G16) | R16: =IF(OR(J16="",K16=""),"",J16*A_exp/(K16/1000)) | S16: =IF(OR(J16="",G16=""),"",J16*1000/G16) | T16: =IF(OR(F16="",G16="",J16=""),"",k_f*G16-1-S16/F16) | U16: =IF(OR(C16<>50,I16="",L16="",M16=""),"",IF(AND(I16<=thr_lim,L16<dur_lim,M16="N"),"충족","미충족")) | V16: =IF(F16="","",1/SQRT(F16))
P17: =IF(OR(G17="",H17=""),"",G17/H17) | Q17: =IF(OR(F17="",G17=""),"",F17/G17) | R17: =IF(OR(J17="",K17=""),"",J17*A_exp/(K17/1000)) | S17: =IF(OR(J17="",G17=""),"",J17*1000/G17) | T17: =IF(OR(F17="",G17="",J17=""),"",k_f*G17-1-S17/F17) | U17: =IF(OR(C17<>50,I17="",L17="",M17=""),"",IF(AND(I17<=thr_lim,L17<dur_lim,M17="N"),"충족","미충족")) | V17: =IF(F17="","",1/SQRT(F17))
P18: =IF(OR(G18="",H18=""),"",G18/H18) | Q18: =IF(OR(F18="",G18=""),"",F18/G18) | R18: =IF(OR(J18="",K18=""),"",J18*A_exp/(K18/1000)) | S18: =IF(OR(J18="",G18=""),"",J18*1000/G18) | T18: =IF(OR(F18="",G18="",J18=""),"",k_f*G18-1-S18/F18) | U18: =IF(OR(C18<>50,I18="",L18="",M18=""),"",IF(AND(I18<=thr_lim,L18<dur_lim,M18="N"),"충족","미충족")) | V18: =IF(F18="","",1/SQRT(F18))
P19: =IF(OR(G19="",H19=""),"",G19/H19) | Q19: =IF(OR(F19="",G19=""),"",F19/G19) | R19: =IF(OR(J19="",K19=""),"",J19*A_exp/(K19/1000)) | S19: =IF(OR(J19="",G19=""),"",J19*1000/G19) | T19: =IF(OR(F19="",G19="",J19=""),"",k_f*G19-1-S19/F19) | U19: =IF(OR(C19<>50,I19="",L19="",M19=""),"",IF(AND(I19<=thr_lim,L19<dur_lim,M19="N"),"충족","미충족")) | V19: =IF(F19="","",1/SQRT(F19))
P20: =IF(OR(G20="",H20=""),"",G20/H20) | Q20: =IF(OR(F20="",G20=""),"",F20/G20) | R20: =IF(OR(J20="",K20=""),"",J20*A_exp/(K20/1000)) | S20: =IF(OR(J20="",G20=""),"",J20*1000/G20) | T20: =IF(OR(F20="",G20="",J20=""),"",k_f*G20-1-S20/F20) | U20: =IF(OR(C20<>50,I20="",L20="",M20=""),"",IF(AND(I20<=thr_lim,L20<dur_lim,M20="N"),"충족","미충족")) | V20: =IF(F20="","",1/SQRT(F20))
P21: =IF(OR(G21="",H21=""),"",G21/H21) | Q21: =IF(OR(F21="",G21=""),"",F21/G21) | R21: =IF(OR(J21="",K21=""),"",J21*A_exp/(K21/1000)) | S21: =IF(OR(J21="",G21=""),"",J21*1000/G21) | T21: =IF(OR(F21="",G21="",J21=""),"",k_f*G21-1-S21/F21) | U21: =IF(OR(C21<>50,I21="",L21="",M21=""),"",IF(AND(I21<=thr_lim,L21<dur_lim,M21="N"),"충족","미충족")) | V21: =IF(F21="","",1/SQRT(F21))
P22: =IF(OR(G22="",H22=""),"",G22/H22) | Q22: =IF(OR(F22="",G22=""),"",F22/G22) | R22: =IF(OR(J22="",K22=""),"",J22*A_exp/(K22/1000)) | S22: =IF(OR(J22="",G22=""),"",J22*1000/G22) | T22: =IF(OR(F22="",G22="",J22=""),"",k_f*G22-1-S22/F22) | U22: =IF(OR(C22<>50,I22="",L22="",M22=""),"",IF(AND(I22<=thr_lim,L22<dur_lim,M22="N"),"충족","미충족")) | V22: =IF(F22="","",1/SQRT(F22))
P23: =IF(OR(G23="",H23=""),"",G23/H23) | Q23: =IF(OR(F23="",G23=""),"",F23/G23) | R23: =IF(OR(J23="",K23=""),"",J23*A_exp/(K23/1000)) | S23: =IF(OR(J23="",G23=""),"",J23*1000/G23) | T23: =IF(OR(F23="",G23="",J23=""),"",k_f*G23-1-S23/F23) | U23: =IF(OR(C23<>50,I23="",L23="",M23=""),"",IF(AND(I23<=thr_lim,L23<dur_lim,M23="N"),"충족","미충족")) | V23: =IF(F23="","",1/SQRT(F23))
P24: =IF(OR(G24="",H24=""),"",G24/H24) | Q24: =IF(OR(F24="",G24=""),"",F24/G24) | R24: =IF(OR(J24="",K24=""),"",J24*A_exp/(K24/1000)) | S24: =IF(OR(J24="",G24=""),"",J24*1000/G24) | T24: =IF(OR(F24="",G24="",J24=""),"",k_f*G24-1-S24/F24) | U24: =IF(OR(C24<>50,I24="",L24="",M24=""),"",IF(AND(I24<=thr_lim,L24<dur_lim,M24="N"),"충족","미충족")) | V24: =IF(F24="","",1/SQRT(F24))
P25: =IF(OR(G25="",H25=""),"",G25/H25) | Q25: =IF(OR(F25="",G25=""),"",F25/G25) | R25: =IF(OR(J25="",K25=""),"",J25*A_exp/(K25/1000)) | S25: =IF(OR(J25="",G25=""),"",J25*1000/G25) | T25: =IF(OR(F25="",G25="",J25=""),"",k_f*G25-1-S25/F25) | U25: =IF(OR(C25<>50,I25="",L25="",M25=""),"",IF(AND(I25<=thr_lim,L25<dur_lim,M25="N"),"충족","미충족")) | V25: =IF(F25="","",1/SQRT(F25))
... P37: =IF(OR(G37="",H37=""),"",G37/H37) | Q37: =IF(OR(F37="",G37=""),"",F37/G37) | R37: =IF(OR(J37="",K37=""),"",J37*A_exp/(K37/1000)) | S37: =IF(OR(J37="",G37=""),"",J37*1000/G37) | T37: =IF(OR(F37="",G37="",J37=""),"",k_f*G37-1-S37/F37) | U37: =IF(OR(C37<>50,I37="",L37="",M37=""),"",IF(AND(I37<=thr_lim,L37<dur_lim,M37="N"),"충족","미충족")) | V37: =IF(F37="","",1/SQRT(F37))
A39: FIGRA_콘·t_ig/pHRR: Schartel & Hull (2007), Petrella (1994) · b > 0이면 상향 확산 가속(Quintiere 2006, k_f ≈ 0.01 m²/kW) · 준불연: 국토교통부 고시 「건축자재등 품질인정 및 관리기준」(10분 THR ≤ 8 MJ/m², 200 kW/m² 초과 10초 이상 연속 금지, 관통 균열·구멍·용융 없음; 가스유해성 별도)
A41: B. 다열류속 착화시간 → TRP·CHF (1/√t_ig = (q″ − CHF)/TRP, 열적으로 두꺼운 시편)
A42: 재료 | B42: q″ (kW/m²) | C42: 평균 t_ig (s) | D42: 1/√t_ig | E42: TRP (kW·s½/m²) | F42: CHF (kW/m²)
A43: 예시(가상값) | B43: 25 | C43: 330 | D43: =IF(C43="","",1/SQRT(C43)) -> 0.055048188 | E43: =IFERROR(1/SLOPE(D43:D46,B43:B46),"") -> 313.28114 | F43: =IFERROR(-INTERCEPT(D43:D46,B43:B46)/SLOPE(D43:D46,B43:B46),"") -> 6.9135555
A44: 예시(가상값) | B44: 35 | C44: 120 | D44: =IF(C44="","",1/SQRT(C44)) -> 0.091287093
A45: 예시(가상값) | B45: 50 | C45: 50 | D45: =IF(C45="","",1/SQRT(C45)) -> 0.14142136
A46: 예시(가상값) | B46: 65 | C46: 30 | D46: =IF(C46="","",1/SQRT(C46)) -> 0.18257419
A47: EPS 가연성 | B47: 25 | D47: =IF(C47="","",1/SQRT(C47)) | E47: =IFERROR(1/SLOPE(D47:D50,B47:B50),"") | F47: =IFERROR(-INTERCEPT(D47:D50,B47:B50)/SLOPE(D47:D50,B47:B50),"")
A48: EPS 가연성 | B48: 35 | D48: =IF(C48="","",1/SQRT(C48))
A49: EPS 가연성 | B49: 50 | D49: =IF(C49="","",1/SQRT(C49))
A50: EPS 가연성 | B50: 65 | D50: =IF(C50="","",1/SQRT(C50))
A51: EPS 준불연 | B51: 25 | D51: =IF(C51="","",1/SQRT(C51)) | E51: =IFERROR(1/SLOPE(D51:D54,B51:B54),"") | F51: =IFERROR(-INTERCEPT(D51:D54,B51:B54)/SLOPE(D51:D54,B51:B54),"")
A52: EPS 준불연 | B52: 35 | D52: =IF(C52="","",1/SQRT(C52))
A53: EPS 준불연 | B53: 50 | D53: =IF(C53="","",1/SQRT(C53))
A54: EPS 준불연 | B54: 65 | D54: =IF(C54="","",1/SQRT(C54))
A55: PIR(PUR) 가연성 | B55: 25 | D55: =IF(C55="","",1/SQRT(C55)) | E55: =IFERROR(1/SLOPE(D55:D58,B55:B58),"") | F55: =IFERROR(-INTERCEPT(D55:D58,B55:B58)/SLOPE(D55:D58,B55:B58),"")
...

Sheet 3_L1_TGA
A1: ③ L1 TGA–DSC (5 °C/min, 공기·질소 각 2회 평균) → 재료 인자와 중규모 등가 예측
A2: TGA 값은 tga_dsc/results/tga_summary.csv. 등급은 인증서 등급(콘 자료가 생기면 2_L1_콘의 판정으로 교체). 전이함수 상수는 6_전이함수.
A4: 재료 | B4: 재료명 | C4: 등급 | D4: T_onset,air (°C) | E4: T_5%,air (°C) | F4: r_max,air (%/°C) | G4: ± 반폭 | H4: f400,air | I4: ± 반폭 | J4: r_max,N₂ | K4: f400,N₂ | L4: 공기 자료 판정 | M4: 재료형 | N4: 게이트 | O4: t̂600 전체 보정 (s) | P4: t̂600 사용값 (s) | Q4: FRI^ = 900/t̂600 | R4: P̂ | S4: m (램프) | T4: a₀ = n₀m | U4: b₀ = n₀(1−m) | V4: p̂_B 사전평균 | W4: 급발 예상
A5: EPS_C | B5: EPS 가연성 | C5: c | D5: 274.5113 | E5: 274.5 | F5: 2.4377 | G5: 0.4041 | H5: 0.026 | I5: 0.0056 | J5: 2.6483 | K5: 0.279 | L5: 재측정 | M5: =IF(H5<f_melt,"용융형","탄화형") -> 용융형 | N5: =IF(C5="c","가연성 → TGA 미적용",IF(H5<f_melt,"용융형 → 확산식 미적용","적용")) -> 가연성 → TGA 미적용 | O5: =t_ig_sys+C_sys/F5 -> 421.01048 | P5: =IFERROR(INDEX(loo_t600,MATCH(A5,loo_key,0)),O5) -> 421.01048 | Q5: =t_ref/P5 -> 2.137714 | R5: =IF(N5<>"적용","—",IF(Q5>=2,4,IF(Q5>=1,3,IF(Q5>=0.5,2,1)))) -> — | S5: =MIN(0.95,MAX(0.05,(H5-f_lo)/(f_hi-f_lo))) -> 0.05 | T5: =n0*S5 -> 0.1 | U5: =n0*(1-S5) -> 1.9 | V5: =T5/(T5+U5) -> 0.05 | W5: =IF(M5="용융형","A 예상(용융·순간연소)",IF(C5="c","A 예상(가연성 전면착화)","—")) -> A 예상(용융·순간연소)
A6: EPS_SC | B6: EPS 준불연 | C6: sc | D6: 301.4463 | E6: 245.75 | F6: 1.0224 | G6: 0.0423 | H6: 0.3333 | I6: 0.0171 | J6: 1.1513 | K6: 0.5378 | L6: 종점 의존 | M6: =IF(H6<f_melt,"용융형","탄화형") -> 용융형 | N6: =IF(C6="c","가연성 → TGA 미적용",IF(H6<f_melt,"용융형 → 확산식 미적용","적용")) -> 용융형 → 확산식 미적용 | O6: =t_ig_sys+C_sys/F6 -> 661.19963 | P6: =IFERROR(INDEX(loo_t600,MATCH(A6,loo_key,0)),O6) -> 661.19963 | Q6: =t_ref/P6 -> 1.3611623 | R6: =IF(N6<>"적용","—",IF(Q6>=2,4,IF(Q6>=1,3,IF(Q6>=0.5,2,1)))) -> — | S6: =MIN(0.95,MAX(0.05,(H6-f_lo)/(f_hi-f_lo))) -> 0.05 | T6: =n0*S6 -> 0.1 | U6: =n0*(1-S6) -> 1.9 | V6: =T6/(T6+U6) -> 0.05 | W6: =IF(M6="용융형","A 예상(용융·순간연소)",IF(C6="c","A 예상(가연성 전면착화)","—")) -> A 예상(용융·순간연소)
A7: PIR_C | B7: PIR(PUR) 가연성 | C7: c | D7: 463.4172 | E7: 263.25 | F7: 0.7496 | G7: 0.0019 | H7: 0.6655 | I7: 0.0029 | J7: 0.7048 | K7: 0.4603 | L7: 신뢰 | M7: =IF(H7<f_melt,"용융형","탄화형") -> 탄화형 | N7: =IF(C7="c","가연성 → TGA 미적용",IF(H7<f_melt,"용융형 → 확산식 미적용","적용")) -> 가연성 → TGA 미적용 | O7: =t_ig_sys+C_sys/F7 -> 811.75627 | P7: =IFERROR(INDEX(loo_t600,MATCH(A7,loo_key,0)),O7) -> 811.75627 | Q7: =t_ref/P7 -> 1.1087072 | R7: =IF(N7<>"적용","—",IF(Q7>=2,4,IF(Q7>=1,3,IF(Q7>=0.5,2,1)))) -> — | S7: =MIN(0.95,MAX(0.05,(H7-f_lo)/(f_hi-f_lo))) -> 0.655 | T7: =n0*S7 -> 1.31 | U7: =n0*(1-S7) -> 0.69 | V7: =T7/(T7+U7) -> 0.655 | W7: =IF(M7="용융형","A 예상(용융·순간연소)",IF(C7="c","A 예상(가연성 전면착화)","—")) -> A 예상(가연성 전면착화)
A8: PIR_SC | B8: PIR(PUR) 준불연 | C8: sc | D8: 402.9464 | E8: 223.75 | F8: 0.5752 | G8: 0.0559 | H8: 0.6288 | I8: 0.007 | J8: 0.5289 | K8: 0.4298 | L8: 조건부 | M8: =IF(H8<f_melt,"용융형","탄화형") -> 탄화형 | N8: =IF(C8="c","가연성 → TGA 미적용",IF(H8<f_melt,"용융형 → 확산식 미적용","적용")) -> 적용 | O8: =t_ig_sys+C_sys/F8 -> 982.83814 | P8: =IFERROR(INDEX(loo_t600,MATCH(A8,loo_key,0)),O8) -> 925.76 | Q8: =t_ref/P8 -> 0.97217421 | R8: =IF(N8<>"적용","—",IF(Q8>=2,4,IF(Q8>=1,3,IF(Q8>=0.5,2,1)))) -> 2 | S8: =MIN(0.95,MAX(0.05,(H8-f_lo)/(f_hi-f_lo))) -> 0.288 | T8: =n0*S8 -> 0.576 | U8: =n0*(1-S8) -> 1.424 | V8: =T8/(T8+U8) -> 0.288 | W8: =IF(M8="용융형","A 예상(용융·순간연소)",IF(C8="c","A 예상(가연성 전면착화)","—")) -> —
A9: PF_out | B9: PF 준불연 외부용 | C9: sc | D9: 339.5544 | E9: 197.5 | F9: 0.4064 | G9: 0.0026 | H9: 0.7032 | I9: 0.0008 | J9: 0.2732 | K9: 0.6352 | L9: 신뢰 | M9: =IF(H9<f_melt,"용융형","탄화형") -> 탄화형 | N9: =IF(C9="c","가연성 → TGA 미적용",IF(H9<f_melt,"용융형 → 확산식 미적용","적용")) -> 적용 | O9: =t_ig_sys+C_sys/F9 -> 1288.264 | P9: =IFERROR(INDEX(loo_t600,MATCH(A9,loo_key,0)),O9) -> 1260.9 | Q9: =t_ref/P9 -> 0.71377587 | R9: =IF(N9<>"적용","—",IF(Q9>=2,4,IF(Q9>=1,3,IF(Q9>=0.5,2,1)))) -> 2 | S9: =MIN(0.95,MAX(0.05,(H9-f_lo)/(f_hi-f_lo))) -> 0.95 | T9: =n0*S9 -> 1.9 | U9: =n0*(1-S9) -> 0.1 | V9: =T9/(T9+U9) -> 0.95 | W9: =IF(M9="용융형","A 예상(용융·순간연소)",IF(C9="c","A 예상(가연성 전면착화)","—")) -> —
A10: PF_in | B10: PF 준불연 내부용 | C10: sc | D10: 398.3672 | E10: 176 | F10: 1.1737 | G10: 0.0078 | H10: 0.6512 | I10: 0.0031 | J10: 0.2491 | K10: 0.7167 | L10: 신뢰 | M10: =IF(H10<f_melt,"용융형","탄화형") -> 탄화형 | N10: =IF(C10="c","가연성 → TGA 미적용",IF(H10<f_melt,"용융형 → 확산식 미적용","적용")) -> 적용 | O10: =t_ig_sys+C_sys/F10 -> 607.8702 | P10: =IFERROR(INDEX(loo_t600,MATCH(A10,loo_key,0)),O10) -> 664.06 | Q10: =t_ref/P10 -> 1.3552992 | R10: =IF(N10<>"적용","—",IF(Q10>=2,4,IF(Q10>=1,3,IF(Q10>=0.5,2,1)))) -> 3 | S10: =MIN(0.95,MAX(0.05,(H10-f_lo)/(f_hi-f_lo))) -> 0.512 | T10: =n0*S10 -> 1.024 | U10: =n0*(1-S10) -> 0.976 | V10: =T10/(T10+U10) -> 0.512 | W10: =IF(M10="용융형","A 예상(용융·순간연소)",IF(C10="c","A 예상(가연성 전면착화)","—")) -> —
A12: t̂600 사용값: 준불연 탄화형 3종은 해당 제품을 빼고 보정한 상수(6_전이함수의 LOO), 나머지는 전체 보정 상수. P̂ 경계: FRI 0.5·1·2 (7.5·15·30분).
A13: p̂_B 사전분포: f400,air가 0.60 → 0.70으로 갈 때 0.05 → 0.95로 오르는 램프(경계 0.65 = 통합 모델의 B̂ 기준), 무게 n₀ = 2회 시험분. 잠정값입니다.
A14: TGA로 못 보는 것: 기상 난연 효과(가연/준불연 차이), 발열 절대량(초기 질량 미기록), DSC 열량(미보정) → 콘·FT-IR·보정 DSC가 보완합니다.

Sheet 4_L1_FT-IR
A1: ④ L1 FT-IR — 고분자·난연제 식별(게이트 검증)과 유해가스(TGA–FTIR) 입력 양식
A2: 대표 흡수대는 문헌값입니다. 실험실 기준 스펙트럼으로 확인한 뒤 쓰십시오. 회색 기울임 행은 형식 예시(가상값)입니다.
A4: A. ATR 식별 대역 (고체: 심재·면재)
A5: 대상 | B5: 대역 (cm⁻¹) | C5: 귀속 | D5: 용도
A6: 폴리스티렌 (EPS) | B6: 3060 · 3026 | C6: 방향족 C–H 신축 | D6: 식별
A7: 폴리스티렌 (EPS) | B7: 1601 · 1493 · 1452 | C7: 방향족 고리 | D7: 식별
A8: 폴리스티렌 (EPS) | B8: 756 · 698 | C8: 일치환 벤젠 C–H 면외굽힘 | D8: 식별(강함)
A9: PIR/PUR (MDI계) | B9: 3300 | C9: N–H 신축 (우레탄) | D9: PUR 성분
A10: PIR/PUR (MDI계) | B10: 2270 | C10: 잔류 –N=C=O | D10: 미반응 이소시아네이트
A11: PIR/PUR (MDI계) | B11: 1710 – 1730 | C11: C=O (우레탄·이소시아누레이트) | D11: 식별
A12: PIR/PUR (MDI계) | B12: 1595 | C12: 방향족 C=C (내부 기준 대역) | D12: 지수의 분모
A13: PIR/PUR (MDI계) | B13: 1510 – 1530 | C13: 아마이드 II (N–H 굽힘 + C–N) | D13: 우레탄 성분
A14: PIR/PUR (MDI계) | B14: 1410 | C14: 이소시아누레이트 고리 C–N | D14: 이소시아누레이트 지수 A₁₄₁₀/A₁₅₉₅
A15: 페놀 (PF) | B15: 3300 (넓음) | C15: O–H 신축 | D15: 식별
A16: 페놀 (PF) | B16: 1600 · 1500 | C16: 방향족 고리 | D16: 기준 대역
... A24: 브롬계 난연제 | B24: (적외선 감도 낮음) | C24: C–Br | D24: XRF·SEM/EDS로 Br 확인
A26: B. ATR 측정 기록 (흡광도: 기준선 보정 후 피크 높이) → 지수
A27: 재료 | B27: 부위 | C27: 위치 | D27: 선언 고분자 | E27: 판정 고분자 | F27: A₁₄₁₀ | G27: A₁₅₉₅ | H27: A₂₂₇₀ | I27: A_P=O (1270–1290) | J27: A_기준 | K27: A_OH (3620) | L27: 이소시아누레이트 지수 | M27: 잔류 NCO 지수 | N27: 난연(P) 지수 | O27: 무기충전 지수 | P27: 식별 일치
A28: 예시(가상값) | B28: 심재 | C28: 1 | D28: PIR | E28: PIR | F28: 0.42 | G28: 0.6 | H28: 0.02 | I28: 0.15 | J28: 0.6 | L28: =IF(OR(F28="",G28=""),"",F28/G28) -> 0.7 | M28: =IF(OR(H28="",G28=""),"",H28/G28) -> 0.033333333 | N28: =IF(OR(I28="",J28=""),"",I28/J28) -> 0.25 | O28: =IF(OR(K28="",J28=""),"",K28/J28) | P28: =IF(OR(D28="",E28=""),"",IF(D28=E28,"일치","불일치")) -> 일치
L29: =IF(OR(F29="",G29=""),"",F29/G29) | M29: =IF(OR(H29="",G29=""),"",H29/G29) | N29: =IF(OR(I29="",J29=""),"",I29/J29) | O29: =IF(OR(K29="",J29=""),"",K29/J29) | P29: =IF(OR(D29="",E29=""),"",IF(D29=E29,"일치","불일치"))
L30: =IF(OR(F30="",G30=""),"",F30/G30) | M30: =IF(OR(H30="",G30=""),"",H30/G30) | N30: =IF(OR(I30="",J30=""),"",I30/J30) | O30: =IF(OR(K30="",J30=""),"",K30/J30) | P30: =IF(OR(D30="",E30=""),"",IF(D30=E30,"일치","불일치"))
L31: =IF(OR(F31="",G31=""),"",F31/G31) | M31: =IF(OR(H31="",G31=""),"",H31/G31) | N31: =IF(OR(I31="",J31=""),"",I31/J31) | O31: =IF(OR(K31="",J31=""),"",K31/J31) | P31: =IF(OR(D31="",E31=""),"",IF(D31=E31,"일치","불일치"))
L32: =IF(OR(F32="",G32=""),"",F32/G32) | M32: =IF(OR(H32="",G32=""),"",H32/G32) | N32: =IF(OR(I32="",J32=""),"",I32/J32) | O32: =IF(OR(K32="",J32=""),"",K32/J32) | P32: =IF(OR(D32="",E32=""),"",IF(D32=E32,"일치","불일치"))
L33: =IF(OR(F33="",G33=""),"",F33/G33) | M33: =IF(OR(H33="",G33=""),"",H33/G33) | N33: =IF(OR(I33="",J33=""),"",I33/J33) | O33: =IF(OR(K33="",J33=""),"",K33/J33) | P33: =IF(OR(D33="",E33=""),"",IF(D33=E33,"일치","불일치"))
L34: =IF(OR(F34="",G34=""),"",F34/G34) | M34: =IF(OR(H34="",G34=""),"",H34/G34) | N34: =IF(OR(I34="",J34=""),"",I34/J34) | O34: =IF(OR(K34="",J34=""),"",K34/J34) | P34: =IF(OR(D34="",E34=""),"",IF(D34=E34,"일치","불일치"))
L35: =IF(OR(F35="",G35=""),"",F35/G35) | M35: =IF(OR(H35="",G35=""),"",H35/G35) | N35: =IF(OR(I35="",J35=""),"",I35/J35) | O35: =IF(OR(K35="",J35=""),"",K35/J35) | P35: =IF(OR(D35="",E35=""),"",IF(D35=E35,"일치","불일치"))
L36: =IF(OR(F36="",G36=""),"",F36/G36) | M36: =IF(OR(H36="",G36=""),"",H36/G36) | N36: =IF(OR(I36="",J36=""),"",I36/J36) | O36: =IF(OR(K36="",J36=""),"",K36/J36) | P36: =IF(OR(D36="",E36=""),"",IF(D36=E36,"일치","불일치"))
L37: =IF(OR(F37="",G37=""),"",F37/G37) | M37: =IF(OR(H37="",G37=""),"",H37/G37) | N37: =IF(OR(I37="",J37=""),"",I37/J37) | O37: =IF(OR(K37="",J37=""),"",K37/J37) | P37: =IF(OR(D37="",E37=""),"",IF(D37=E37,"일치","불일치"))
L38: =IF(OR(F38="",G38=""),"",F38/G38) | M38: =IF(OR(H38="",G38=""),"",H38/G38) | N38: =IF(OR(I38="",J38=""),"",I38/J38) | O38: =IF(OR(K38="",J38=""),"",K38/J38) | P38: =IF(OR(D38="",E38=""),"",IF(D38=E38,"일치","불일치"))
L39: =IF(OR(F39="",G39=""),"",F39/G39) | M39: =IF(OR(H39="",G39=""),"",H39/G39) | N39: =IF(OR(I39="",J39=""),"",I39/J39) | O39: =IF(OR(K39="",J39=""),"",K39/J39) | P39: =IF(OR(D39="",E39=""),"",IF(D39=E39,"일치","불일치"))
L40: =IF(OR(F40="",G40=""),"",F40/G40) | M40: =IF(OR(H40="",G40=""),"",H40/G40) | N40: =IF(OR(I40="",J40=""),"",I40/J40) | O40: =IF(OR(K40="",J40=""),"",K40/J40) | P40: =IF(OR(D40="",E40=""),"",IF(D40=E40,"일치","불일치"))
... L46: =IF(OR(F46="",G46=""),"",F46/G46) | M46: =IF(OR(H46="",G46=""),"",H46/G46) | N46: =IF(OR(I46="",J46=""),"",I46/J46) | O46: =IF(OR(K46="",J46=""),"",K46/J46) | P46: =IF(OR(D46="",E46=""),"",IF(D46=E46,"일치","불일치"))
A48: C. TGA–FTIR 발생가스 기록 (같은 승온속도 5 K/min 권장)
A49: 재료 | B49: 분위기 | C49: 가스 | D49: 대역 (cm⁻¹) | E49: 최대 발생 온도 (°C) | F49: 적분 면적 (a.u.·s) | G49: 시료 질량 (mg) | H49: 면적/mg | I49: 비고
A50: 예시(가상값) | B50: 공기 | C50: HCN | D50: 713 | E50: 455 | F50: 0.84 | G50: 7 | H50: =IF(OR(F50="",G50=""),"",F50/G50) -> 0.12
A51: EPS 가연성 | B51: 공기 | C51: CO₂ | D51: 2360 · 2340 · 669 | H51: =IF(OR(F51="",G51=""),"",F51/G51)
A52: EPS 가연성 | B52: 공기 | C52: CO | D52: 2180 · 2110 (P·R 가지) | H52: =IF(OR(F52="",G52=""),"",F52/G52)
A53: EPS 가연성 | B53: 공기 | C53: HCN | D53: 713 (Q 가지) | H53: =IF(OR(F53="",G53=""),"",F53/G53)
A54: EPS 가연성 | B54: 공기 | C54: NH₃ | D54: 966 · 931 | H54: =IF(OR(F54="",G54=""),"",F54/G54)
A55: EPS 가연성 | B55: 공기 | C55: –NCO (이소시아네이트) | D55: 2270 – 2250 | H55: =IF(OR(F55="",G55=""),"",F55/G55)
...

Sheet 5_L2_중규모
A1: ⑤ L2 중규모 성능시험 (중공층 100 mm · 외단열 100 mm · 30 kW 20분 · 30분 평가) — 시험별 값
A2: t600 = 3000 mm에서 ΔT ≥ 600 K가 30 s 이상 유지되기 시작한 시각. t_ig·t_sp: coupled_analysis(착화·확산 분해). P·S·R·A: cavity_fire_index. B: integrated_model.
A4: 시험 | B4: 재료 | C4: 재료명 | D4: 등급 | E4: 정량평가 사용 | F4: t_ig (s) | G4: t_sp (s) | H4: t600 (s) | I4: ln t600 | J4: (ln t600)² | K4: FRI = 900/t600 | L4: P | M4: D600 (분) | N4: S | O4: R = P×S | P4: 급발 A | Q4: 자립 B (1/0) | R4: H600 (K·min) | S4: 최고온도 3000 mm (°C)
A5: EPS_C-1 | B5: EPS_C | C5: EPS 가연성 | D5: c | E5: 아니오 | I5: =IF(H5="","",LN(H5)) | J5: =IF(H5="","",LN(H5)^2) | K5: =IF(H5="","",t_ref/H5) | Q5: 0 | R5: 0 | S5: 305.5
A6: EPS_C-2 | B6: EPS_C | C6: EPS 가연성 | D6: c | E6: 아니오 | I6: =IF(H6="","",LN(H6)) | J6: =IF(H6="","",LN(H6)^2) | K6: =IF(H6="","",t_ref/H6) | Q6: 0 | R6: 0 | S6: 252.5
A7: EPS_SC-1 | B7: EPS_SC | C7: EPS 준불연 | D7: sc | E7: 예 | F7: 488 | G7: 474 | H7: 962 | I7: =IF(H7="","",LN(H7)) -> 6.8690145 | J7: =IF(H7="","",LN(H7)^2) -> 47.18336 | K7: =IF(H7="","",t_ref/H7) -> 0.93555094 | L7: 2 | M7: 2.3 | N7: 2 | O7: 4 | P7: A | Q7: 0 | R7: 129.395 | S7: 754.3
A8: EPS_SC-2 | B8: EPS_SC | C8: EPS 준불연 | D8: sc | E8: 예 | F8: 1036 | I8: =IF(H8="","",LN(H8)) | J8: =IF(H8="","",LN(H8)^2) | K8: =IF(H8="","",t_ref/H8) | L8: 1 | M8: 0 | N8: 1 | O8: 1 | Q8: 0 | R8: 0 | S8: 430.6
A9: EPS_SC-3 | B9: EPS_SC | C9: EPS 준불연 | D9: sc | E9: 예 | F9: 868 | G9: 107 | H9: 975 | I9: =IF(H9="","",LN(H9)) -> 6.8824375 | J9: =IF(H9="","",LN(H9)^2) -> 47.367946 | K9: =IF(H9="","",t_ref/H9) -> 0.92307692 | L9: 2 | M9: 0.566667 | N9: 1 | O9: 2 | P9: A | Q9: 0 | R9: 19.675 | S9: 689.6
A10: PIR_C-1 | B10: PIR_C | C10: PIR(PUR) 가연성 | D10: c | E10: 예 | H10: 31 | I10: =IF(H10="","",LN(H10)) -> 3.4339872 | J10: =IF(H10="","",LN(H10)^2) -> 11.792268 | K10: =IF(H10="","",t_ref/H10) -> 29.032258 | L10: 4 | M10: 14.866667 | N10: 4 | O10: 16 | P10: A | Q10: 0 | R10: 3029.3333 | S10: 985.5
A11: PIR_C-2 | B11: PIR_C | C11: PIR(PUR) 가연성 | D11: c | E11: 예 | H11: 29 | I11: =IF(H11="","",LN(H11)) -> 3.3672958 | J11: =IF(H11="","",LN(H11)^2) -> 11.338681 | K11: =IF(H11="","",t_ref/H11) -> 31.034483 | L11: 4 | M11: 16.1 | N11: 4 | O11: 16 | P11: A | Q11: 0 | R11: 3703.75 | S11: 1046
A12: PIR_SC-1 | B12: PIR_SC | C12: PIR(PUR) 준불연 | D12: sc | E12: 예 | F12: 288 | G12: 780 | H12: 1068 | I12: =IF(H12="","",LN(H12)) -> 6.973543 | J12: =IF(H12="","",LN(H12)^2) -> 48.630302 | K12: =IF(H12="","",t_ref/H12) -> 0.84269663 | L12: 2 | M12: 4.65 | N12: 2 | O12: 4 | Q12: 0 | R12: 616.31333 | S12: 861.2
A13: PIR_SC-2 | B13: PIR_SC | C13: PIR(PUR) 준불연 | D13: sc | E13: 예 | F13: 282 | G13: 809 | H13: 1091 | I13: =IF(H13="","",LN(H13)) -> 6.99485 | J13: =IF(H13="","",LN(H13)^2) -> 48.927926 | K13: =IF(H13="","",t_ref/H13) -> 0.82493126 | L13: 2 | M13: 6.866667 | N13: 3 | O13: 6 | Q13: 0 | R13: 1365.6367 | S13: 1148.9
A14: PF_out-1 | B14: PF_out | C14: PF 준불연 외부용 | D14: sc | E14: 예 | F14: 220 | G14: 1025 | H14: 1245 | I14: =IF(H14="","",LN(H14)) -> 7.1268908 | J14: =IF(H14="","",LN(H14)^2) -> 50.792573 | K14: =IF(H14="","",t_ref/H14) -> 0.72289157 | L14: 2 | M14: 2.883333 | N14: 2 | O14: 4 | Q14: 1 | R14: 474.61833 | S14: 998.2
A15: PF_out-2 | B15: PF_out | C15: PF 준불연 외부용 | D15: sc | E15: 예 | F15: 275 | G15: 1180 | H15: 1455 | I15: =IF(H15="","",LN(H15)) -> 7.2827612 | J15: =IF(H15="","",LN(H15)^2) -> 53.03861 | K15: =IF(H15="","",t_ref/H15) -> 0.6185567 | L15: 2 | M15: 4.466667 | N15: 2 | O15: 4 | Q15: 1 | R15: 999.06833 | S15: 1161.6
A16: PF_in-1 | B16: PF_in | C16: PF 준불연 내부용 | D16: sc | E16: 예 | F16: 220 | G16: 336 | H16: 556 | I16: =IF(H16="","",LN(H16)) -> 6.3207683 | J16: =IF(H16="","",LN(H16)^2) -> 39.952112 | K16: =IF(H16="","",t_ref/H16) -> 1.618705 | L16: 3 | M16: 10.866667 | N16: 4 | O16: 12 | Q16: 0 | R16: 2097.9467 | S16: 1135.3
A17: PF_in-2 | B17: PF_in | C17: PF 준불연 내부용 | D17: sc | E17: 예 | F17: 188 | G17: 284 | H17: 472 | I17: =IF(H17="","",LN(H17)) -> 6.156979 | J17: =IF(H17="","",LN(H17)^2) -> 37.90839 | K17: =IF(H17="","",t_ref/H17) -> 1.9067797 | L17: 3 | M17: 17.083333 | N17: 4 | O17: 12 | Q17: 1 | R17: 3768.7167 | S17: 1095.8
A19: PIR(PUR) 가연성은 30 s 만에 전면 착화(착화·확산 분해 불가), EPS 준불연 #2는 30분 안에 600 K 미도달(층간 확산 없음으로 계산). EPS 가연성은 기록 4분 → 정량평가 제외(재시험 필요).

Sheet 6_전이함수
A1: ⑥ 전이함수 — 상수, 시험 반복 편차, TGA 예측 편차 (수식)
A2: 소형시료 지표를 중규모 등가값(t600, p_B)으로 바꾸는 식과 상수입니다. σ_rep·τ·제품 간 SD는 5_L2_중규모의 값에서 수식으로 계산됩니다.
A4: 상수
A5: 이름 | B5: 항목 | C5: 값 | D5: 단위 | E5: 출처
A6: t_ig_sys | B6: 시스템 착화 지연 (준불연 6회 중앙값) | C6: 247.5 | D6: s | E6: integrated_model system_constants
A7: C_sys | B7: 확산 상수 t_sp × r_max,air (6회 평균) | C7: 422.9665 | D7: s·%/°C | E7: integrated_model (변동계수 12.75 %)
A8: t_ref | B8: FRI 기준시간 | C8: 900 | D8: s | E8: cavity_fire_index RISK_MODEL
A9: f_lo | B9: p_B 램프 시작 f400,air | C9: 0.6 | D9: – | E9: B̂ 경계 0.65 − 0.05
A10: f_hi | B10: p_B 램프 끝 f400,air | C10: 0.7 | D10: – | E10: B̂ 경계 0.65 + 0.05
A11: n0 | B11: TGA p_B 사전분포 무게 | C11: 2 | D11: 회 | E11: 잠정
A12: f_melt | B12: 용융형 경계 f400,air | C12: 0.5 | D12: – | E12: integrated_model 식 4
A13: tau_min | B13: τ 하한 | C13: 0.05 | D13: – | E13: 자료 3종 → 과소추정 방지
A14: s_lo | B14: s 범위 하한 | C14: 0.25 | D14: – | E14: facade_fra PARAMS
A15: s_hi | B15: s 범위 상한 | C15: 1 | D15: – | E15: facade_fra PARAMS
A16: crit_conf | B16: 판정 신뢰수준 | C16: 0.9 | D16: – | E16: facade_fra 예시
A18: 제품 제외(LOO) 보정 상수와 시험 통계 — 준불연 탄화형
A19: 제품 | B19: t_ig,sys LOO (s) | C19: C_sys LOO | D19: r_max,air | E19: t̂600 LOO (s) | F19: 시험 수 n | G19: ȳ = 평균 ln t600 | H19: Σ (ln t600)² | I19: SS = Σ(ln t − ȳ)² | J19: 잔차 r = ȳ − ln t̂ | K19: r² − σ_rep²/n | L19: 시험 기하평균 (s) | M19: 검산: t_ig + C/r_max (s)
A20: PIR_SC | B20: 220 | C20: 405.95 | D20: =3_L1_TGA!F8 -> 0.5752 | E20: 925.76 | F20: =COUNTIFS(l2_mat,A20,l2_use,"예",l2_t600,">0") -> 2 | G20: =SUMIFS(l2_ln,l2_mat,A20,l2_use,"예",l2_t600,">0")/F20 -> 6.9841965 | H20: =SUMIFS(l2_lnsq,l2_mat,A20,l2_use,"예",l2_t600,">0") -> 97.558229 | I20: =H20-F20*G20^2 -> 0.00022699341 | J20: =G20-LN(E20) -> 0.15358148 | K20: =J20^2-sigma_rep^2/F20 -> 0.01928923 | L20: =EXP(G20) -> 1079.4387 | M20: =B20+C20/D20 -> 925.75452
A21: PF_out | B21: 251 | C21: 410.42 | D21: =3_L1_TGA!F9 -> 0.4064 | E21: 1260.9 | F21: =COUNTIFS(l2_mat,A21,l2_use,"예",l2_t600,">0") -> 2 | G21: =SUMIFS(l2_ln,l2_mat,A21,l2_use,"예",l2_t600,">0")/F21 -> 7.204826 | H21: =SUMIFS(l2_lnsq,l2_mat,A21,l2_use,"예",l2_t600,">0") -> 103.83118 | I21: =H21-F21*G21^2 -> 0.012147786 | J21: =G21-LN(E21) -> 0.065244964 | K21: =J21^2-sigma_rep^2/F21 -> -4.1136138e-05 | L21: =EXP(G21) -> 1345.9105 | M21: =B21+C21/D21 -> 1260.8917
A22: PF_in | B22: 278.5 | C22: 452.53 | D22: =3_L1_TGA!F10 -> 1.1737 | E22: 664.06 | F22: =COUNTIFS(l2_mat,A22,l2_use,"예",l2_t600,">0") -> 2 | G22: =SUMIFS(l2_ln,l2_mat,A22,l2_use,"예",l2_t600,">0")/F22 -> 6.2388736 | H22: =SUMIFS(l2_lnsq,l2_mat,A22,l2_use,"예",l2_t600,">0") -> 77.860502 | I22: =H22-F22*G22^2 -> 0.013413469 | J22: =G22-LN(E22) -> -0.25949887 | K22: =J22^2-sigma_rep^2/F22 -> 0.063041621 | L22: =EXP(G22) -> 512.28117 | M22: =B22+C22/D22 -> 664.05849
A23: t̂600 LOO: integrated_model이 해당 제품을 빼고 t_ig,sys·C_sys를 다시 맞춰 낸 예측값(원값). 마지막 열은 반올림 상수로 다시 계산한 검산값입니다.
A25: 통계 (수식)
A26: sigma_rep | B26: 시험 반복 편차 σ_rep (ln t600, 반복쌍 합동) | C26: =SQRT(SUM(I20:I22)/(SUM(F20:F22)-COUNT(F20:F22))) -> 0.092715063 | D26: –
A27: tau2_raw | B27: TGA 예측 편차² (제품 평균) = 평균(r² − σ_rep²/n) | C27: =AVERAGE(K20:K22) -> 0.027429905 | D27: –
A28: tau_tga | B28: TGA 예측 편차 τ (ln t600) | C28: =SQRT(MAX(tau2_raw,tau_min^2)) -> 0.16561976 | D28: –
A29: sd_between | B29: 준불연 제품 간 SD (ln t600, 등급만 아는 경우의 사전분포) | C29: =STDEV(G20:G22) -> 0.50616985 | D29: –
A31: 전이함수 목록
A32: 번호 | B32: 연결 | C32: 식 | D32: 적용 범위 | E32: 상태 | F32: 위험 차원
A33: T1 | B33: TGA → 확산 | C33: t̂600 = t_ig,sys + C_sys / r_max,air | D33: 준불연 · 탄화형 (f400,air ≥ 0.5) | E33: 보정·교차검증(제품 제외 오차 −14 – +29 %) | F33: D2
A34: T2 | B34: TGA → 지속 | C34: p̂_B ~ Beta(n₀m, n₀(1−m)), m = 램프(f400,air; 0.60 → 0.70) | D34: 준불연 · 탄화형 | E34: 잠정(제품 3종, B̂ 경계 0.65) | F34: D4
A35: T3 | B35: TGA → 급발 | C35: f400,air < 0.5 → 용융형: 확산식 미적용, A 예상 | D35: 전체 | E35: 관측 일치(EPS 준불연 A 2/3) | F35: D5
A36: T4 | B36: 콘 → 게이트 | C36: 준불연 기준 미달 → 가연성: TGA 미적용, 중규모 필수 | D36: 전체 | E36: 규정 기준 · 콘 자료 필요 | F36: G
A37: T5 | B37: 콘 → 확산 | C37: M = Q̇″^(1/3)/TRP → t̂600 = 1079 s (M_ref/M)², b > 0 → 가속 | D37: 준불연 | E37: 제안(콘 자료로 보정) | F37: D2
A38: T6 | B38: 콘 → 발열 | C38: THR_600 ↔ H600 (3000 mm 초과 열량) | D38: 전체 | E38: 제안 | F38: D3
A39: T7 | B39: FT-IR → 게이트 | C39: 식별 일치 + 난연(P) 지수 > 0 → 준불연 처리 확인; 이소시아누레이트 지수 ↔ T_onset·f400 | D39: 전체 | E39: 제안 | F39: G
A40: T8 | B40: FT-IR·콘 → 유해 | C40: HCN·CO 발생량 → FDS 수율 → 위층 FED | D40: 전체 | E40: 제안 | F40: D6
A41: S | B41: 중규모 → 건물 | C41: τ_F = s · t600 · h / 3 m (s: 실물/시험 비) | D41: 전체 | E41: 가정 LogU(0.25, 1) → L3·실대형으로 대체 | F41: D2

Sheet 7_통합(베이즈)
A1: ⑦ 통합 — TGA 사전분포 × 중규모 시험 (베이즈 결합)과 척도 간 정합성
A2: ln t600: 정규–정규 결합(사전 N(ln t̂_TGA, τ²), 시험 n회 N(μ, σ_rep²)). p_B: 베타–이항 결합. 정합성: |z| ≤ 2, 예측확률 ≥ 0.05.
A4: A. 확산 (t600) — 준불연 탄화형
A5: 제품 | B5: μ₀ = ln t̂_TGA | C5: τ | D5: ȳ (시험) | E5: n | F5: σ_rep | G5: 사전 정밀도 1/τ² | H5: 자료 정밀도 n/σ² | I5: TGA 무게 w | J5: μ_post | K5: σ_post | L5: t600 TGA (s) | M5: t600 시험 (s) | N5: t600 통합 (s) | O5: 90 % 하한 | P5: 90 % 상한 | Q5: z = (ȳ − μ₀)/√(τ² + σ²/n) | R5: 정합
A6: PIR_SC | B6: =LN(6_전이함수!E20) -> 6.830615 | C6: =tau_tga -> 0.16561976 | D6: =6_전이함수!G20 -> 6.9841965 | E6: =6_전이함수!F20 -> 2 | F6: =sigma_rep -> 0.092715063 | G6: =1/C6^2 -> 36.456561 | H6: =E6/F6^2 -> 232.66411 | I6: =G6/(G6+H6) -> 0.13546548 | J6: =I6*B6+(1-I6)*D6 -> 6.9633915 | K6: =1/SQRT(G6+H6) -> 0.060957405 | L6: =EXP(B6) -> 925.76 | M6: =EXP(D6) -> 1079.4387 | N6: =EXP(J6) -> 1057.213 | O6: =EXP(J6-1.645*K6) -> 956.34295 | P6: =EXP(J6+1.645*K6) -> 1168.7224 | Q6: =(D6-B6)/SQRT(C6^2+F6^2/E6) -> 0.86221956 | R6: =IF(ABS(Q6)<=2,"정합","불일치") -> 정합
A7: PF_out | B7: =LN(6_전이함수!E21) -> 7.139581 | C7: =tau_tga -> 0.16561976 | D7: =6_전이함수!G21 -> 7.204826 | E7: =6_전이함수!F21 -> 2 | F7: =sigma_rep -> 0.092715063 | G7: =1/C7^2 -> 36.456561 | H7: =E7/F7^2 -> 232.66411 | I7: =G7/(G7+H7) -> 0.13546548 | J7: =I7*B7+(1-I7)*D7 -> 7.1959876 | K7: =1/SQRT(G7+H7) -> 0.060957405 | L7: =EXP(B7) -> 1260.9 | M7: =EXP(D7) -> 1345.9105 | N7: =EXP(J7) -> 1334.0671 | O7: =EXP(J7-1.645*K7) -> 1206.782 | P7: =EXP(J7+1.645*K7) -> 1474.7776 | Q7: =(D7-B7)/SQRT(C7^2+F7^2/E7) -> 0.3662908 | R7: =IF(ABS(Q7)<=2,"정합","불일치") -> 정합
A8: PF_in | B8: =LN(6_전이함수!E22) -> 6.4983725 | C8: =tau_tga -> 0.16561976 | D8: =6_전이함수!G22 -> 6.2388736 | E8: =6_전이함수!F22 -> 2 | F8: =sigma_rep -> 0.092715063 | G8: =1/C8^2 -> 36.456561 | H8: =E8/F8^2 -> 232.66411 | I8: =G8/(G8+H8) -> 0.13546548 | J8: =I8*B8+(1-I8)*D8 -> 6.2740268 | K8: =1/SQRT(G8+H8) -> 0.060957405 | L8: =EXP(B8) -> 664.06 | M8: =EXP(D8) -> 512.28117 | N8: =EXP(J8) -> 530.60973 | O8: =EXP(J8-1.645*K8) -> 479.98356 | P8: =EXP(J8+1.645*K8) -> 586.57569 | Q8: =(D8-B8)/SQRT(C8^2+F8^2/E8) -> -1.4568488 | R8: =IF(ABS(Q8)<=2,"정합","불일치") -> 정합
A10: B. 게이트 확인 — TGA 전이함수를 게이트 없이 쓰면 (가연성 · 용융형)
A11: 제품 | B11: 등급 | C11: 재료형 | D11: t̂600 전체 보정 (s) | E11: 시험 기하평균 (s, 도달 시험) | F11: 도달/시험 수 | G11: z | H11: 판정 | I11: 해석
A12: PIR_C | B12: =3_L1_TGA!C7 -> c | C12: =3_L1_TGA!M7 -> 탄화형 | D12: =3_L1_TGA!O7 -> 811.75627 | E12: =EXP(SUMIFS(l2_ln,l2_mat,"PIR_C",l2_use,"예",l2_t600,">0")/COUNTIFS(l2_mat,"PIR_C",l2_use,"예",l2_t600,">0")) -> 29.983329 | F12: =COUNTIFS(l2_mat,"PIR_C",l2_use,"예",l2_t600,">0")&" / "&COUNTIFS(l2_mat,"PIR_C",l2_use,"예") -> 2 / 2 | G12: =(LN(E12)-LN(D12))/SQRT(tau_tga^2+sigma_rep^2/COUNTIFS(l2_mat,"PIR_C",l2_use,"예",l2_t600,">0")) -> -18.51839 | H12: =IF(ABS(G12)<=2,"정합","불일치") -> 불일치 | I12: 가연성: 기상 난연 차이를 TGA가 못 봄 → 위험을 6배 낮게 추정(게이트 필요)
A13: EPS_SC | B13: =3_L1_TGA!C6 -> sc | C13: =3_L1_TGA!M6 -> 용융형 | D13: =3_L1_TGA!O6 -> 661.19963 | E13: =EXP(SUMIFS(l2_ln,l2_mat,"EPS_SC",l2_use,"예",l2_t600,">0")/COUNTIFS(l2_mat,"EPS_SC",l2_use,"예",l2_t600,">0")) -> 968.47819 | F13: =COUNTIFS(l2_mat,"EPS_SC",l2_use,"예",l2_t600,">0")&" / "&COUNTIFS(l2_mat,"EPS_SC",l2_use,"예") -> 2 / 3 | G13: =(LN(E13)-LN(D13))/SQRT(tau_tga^2+sigma_rep^2/COUNTIFS(l2_mat,"EPS_SC",l2_use,"예",l2_t600,">0")) -> 2.1427289 | H13: =IF(ABS(G13)<=2,"정합","불일치") -> 불일치 | I13: 용융형: 녹아 물러난 뒤 순간 연소 → 확산식이 위험을 높게 추정(미도달 1회 포함 시 더 큼)
A15: C. 지속 (p_B) — 베타–이항 결합
A16: 제품 | B16: f400,air | C16: m (램프) | D16: a₀ | E16: b₀ | F16: B 횟수 k | G16: 시험 수 n | H16: a = a₀ + k | I16: b = b₀ + n − k | J16: p_B 통합 | K16: p_B 시험만 (Jeffreys) | L16: p_B TGA만 | M16: 예측확률 P(k | 사전) | N16: 정합
A17: EPS_SC | B17: =3_L1_TGA!H6 -> 0.3333 | C17: =3_L1_TGA!S6 -> 0.05 | D17: =3_L1_TGA!T6 -> 0.1 | E17: =3_L1_TGA!U6 -> 1.9 | F17: =SUMIFS(l2_B,l2_mat,A17,l2_use,"예") -> 0 | G17: =COUNTIFS(l2_mat,A17,l2_use,"예") -> 3 | H17: =D17+F17 -> 0.1 | I17: =E17+G17-F17 -> 4.9 | J17: =H17/(H17+I17) -> 0.02 | K17: =(F17+0.5)/(G17+1) -> 0.125 | L17: =D17/(D17+E17) -> 0.05 | M17: =COMBIN(G17,F17)*EXP(GAMMALN(F17+D17)+GAMMALN(G17-F17+E17)-GAMMALN(G17+D17+E17)-GAMMALN(D17)-GAMMALN(E17)+GAMMALN(D17+E17)) -> 0.895375 | N17: =IF(M17>=0.05,"정합","불일치") -> 정합
A18: PIR_SC | B18: =3_L1_TGA!H8 -> 0.6288 | C18: =3_L1_TGA!S8 -> 0.288 | D18: =3_L1_TGA!T8 -> 0.576 | E18: =3_L1_TGA!U8 -> 1.424 | F18: =SUMIFS(l2_B,l2_mat,A18,l2_use,"예") -> 0 | G18: =COUNTIFS(l2_mat,A18,l2_use,"예") -> 2 | H18: =D18+F18 -> 0.576 | I18: =E18+G18-F18 -> 3.424 | J18: =H18/(H18+I18) -> 0.144 | K18: =(F18+0.5)/(G18+1) -> 0.16666667 | L18: =D18/(D18+E18) -> 0.288 | M18: =COMBIN(G18,F18)*EXP(GAMMALN(F18+D18)+GAMMALN(G18-F18+E18)-GAMMALN(G18+D18+E18)-GAMMALN(D18)-GAMMALN(E18)+GAMMALN(D18+E18)) -> 0.575296 | N18: =IF(M18>=0.05,"정합","불일치") -> 정합
A19: PF_out | B19: =3_L1_TGA!H9 -> 0.7032 | C19: =3_L1_TGA!S9 -> 0.95 | D19: =3_L1_TGA!T9 -> 1.9 | E19: =3_L1_TGA!U9 -> 0.1 | F19: =SUMIFS(l2_B,l2_mat,A19,l2_use,"예") -> 2 | G19: =COUNTIFS(l2_mat,A19,l2_use,"예") -> 2 | H19: =D19+F19 -> 3.9 | I19: =E19+G19-F19 -> 0.1 | J19: =H19/(H19+I19) -> 0.975 | K19: =(F19+0.5)/(G19+1) -> 0.83333333 | L19: =D19/(D19+E19) -> 0.95 | M19: =COMBIN(G19,F19)*EXP(GAMMALN(F19+D19)+GAMMALN(G19-F19+E19)-GAMMALN(G19+D19+E19)-GAMMALN(D19)-GAMMALN(E19)+GAMMALN(D19+E19)) -> 0.91833333 | N19: =IF(M19>=0.05,"정합","불일치") -> 정합
A20: PF_in | B20: =3_L1_TGA!H10 -> 0.6512 | C20: =3_L1_TGA!S10 -> 0.512 | D20: =3_L1_TGA!T10 -> 1.024 | E20: =3_L1_TGA!U10 -> 0.976 | F20: =SUMIFS(l2_B,l2_mat,A20,l2_use,"예") -> 1 | G20: =COUNTIFS(l2_mat,A20,l2_use,"예") -> 2 | H20: =D20+F20 -> 2.024 | I20: =E20+G20-F20 -> 1.976 | J20: =H20/(H20+I20) -> 0.506 | K20: =(F20+0.5)/(G20+1) -> 0.5 | L20: =D20/(D20+E20) -> 0.512 | M20: =COMBIN(G20,F20)*EXP(GAMMALN(F20+D20)+GAMMALN(G20-F20+E20)-GAMMALN(G20+D20+E20)-GAMMALN(D20)-GAMMALN(E20)+GAMMALN(D20+E20)) -> 0.33314133 | N20: =IF(M20>=0.05,"정합","불일치") -> 정합
A22: 가연성 PIR(PUR)은 버너 소화 전에 연료가 소진되어 B 판정 대상이 아닙니다(p_B는 위험도에 영향 없음).

Sheet 8_L3_시뮬레이션
A1: ⑧ L3 시뮬레이션 (FDS/PyroSim) — 중규모 재현 검증과 건물 외벽 시나리오 → s 추정 (입력 양식)
A2: 1단계: 중규모 시험 재현으로 모델을 검증합니다. 2단계: 검증된 모델로 건물 외벽(3–6개 층)을 계산해 층별 도달시각에서 s를 구합니다. 회색 기울임 = 예시(가상값).
A4: 검증 허용 기준 (예시값 — 사전협의로 확정)
A5: tol_t600 | B5: t600 상대오차 허용 | C5: 0.3
A6: tol_peak | B6: 3000 mm 최고온도 오차 허용 (K) | C6: 100
A7: h_storey | B7: 층고 (m) | C7: 3
A9: A. 1단계 — 중규모 시험 재현
A10: 재료 | B10: 시험 t600 (s) | C10: FDS t600 (s) | D10: 상대오차 | E10: 시험 최고온도 3000 mm (°C) | F10: FDS 최고온도 (°C) | G10: 온도 오차 (K) | H10: 판정
A11: EPS 준불연 | B11: =EXP(SUMIFS(l2_ln,l2_mat,"EPS_SC",l2_use,"예",l2_t600,">0")/COUNTIFS(l2_mat,"EPS_SC",l2_use,"예",l2_t600,">0")) -> 968.47819 | D11: =IF(C11="","",(C11-B11)/B11) | E11: 689.6 | G11: =IF(F11="","",F11-E11) | H11: =IF(OR(C11="",F11=""),"",IF(AND(ABS(D11)<=tol_t600,ABS(G11)<=tol_peak),"검증 통과","보완 필요"))
A12: PIR(PUR) 가연성 | B12: =EXP(SUMIFS(l2_ln,l2_mat,"PIR_C",l2_use,"예",l2_t600,">0")/COUNTIFS(l2_mat,"PIR_C",l2_use,"예",l2_t600,">0")) -> 29.983329 | D12: =IF(C12="","",(C12-B12)/B12) | E12: 1015.75 | G12: =IF(F12="","",F12-E12) | H12: =IF(OR(C12="",F12=""),"",IF(AND(ABS(D12)<=tol_t600,ABS(G12)<=tol_peak),"검증 통과","보완 필요"))
A13: PIR(PUR) 준불연 | B13: =EXP(SUMIFS(l2_ln,l2_mat,"PIR_SC",l2_use,"예",l2_t600,">0")/COUNTIFS(l2_mat,"PIR_SC",l2_use,"예",l2_t600,">0")) -> 1079.4387 | D13: =IF(C13="","",(C13-B13)/B13) | E13: 1005.05 | G13: =IF(F13="","",F13-E13) | H13: =IF(OR(C13="",F13=""),"",IF(AND(ABS(D13)<=tol_t600,ABS(G13)<=tol_peak),"검증 통과","보완 필요"))
A14: PF 준불연 외부용 | B14: =EXP(SUMIFS(l2_ln,l2_mat,"PF_out",l2_use,"예",l2_t600,">0")/COUNTIFS(l2_mat,"PF_out",l2_use,"예",l2_t600,">0")) -> 1345.9105 | D14: =IF(C14="","",(C14-B14)/B14) | E14: 1079.9 | G14: =IF(F14="","",F14-E14) | H14: =IF(OR(C14="",F14=""),"",IF(AND(ABS(D14)<=tol_t600,ABS(G14)<=tol_peak),"검증 통과","보완 필요"))
A15: PF 준불연 내부용 | B15: =EXP(SUMIFS(l2_ln,l2_mat,"PF_in",l2_use,"예",l2_t600,">0")/COUNTIFS(l2_mat,"PF_in",l2_use,"예",l2_t600,">0")) -> 512.28117 | D15: =IF(C15="","",(C15-B15)/B15) | E15: 1115.55 | G15: =IF(F15="","",F15-E15) | H15: =IF(OR(C15="",F15=""),"",IF(AND(ABS(D15)<=tol_t600,ABS(G15)<=tol_peak),"검증 통과","보완 필요"))
A17: B. 2단계 — 건물 외벽 시나리오: 발화층 위 j층 도달시각 → 층별 s_j = ΔT_j / (t600 · h/3 m) → s 추정 → 판정 예측(M0)
A18: 재료 | B18: 시나리오 | C18: 시험 t600 (s) | D18: T1 (s) | E18: T2 (s) | F18: T3 (s) | G18: T4 (s) | H18: T5 (s) | I18: T6 (s) | J18: s1 | K18: s2 | L18: s3 | M18: s4 | N18: s5 | O18: s6 | P18: s 추정 (중앙값) | Q18: 충족 하한 s_meet | R18: 불충족 상한 s_fail | S18: 판정 예측 (M0)
A19: 예시(가상값) | B19: IE1 창 분출 | C19: 1000 | D19: 480 | E19: 1000 | F19: 1500 | G19: 2050 | J19: =IF(D19="","",D19/($C19*h_storey/3)) -> 0.48 | K19: =IF(OR(E19="",D19=""),"",(E19-D19)/($C19*h_storey/3)) -> 0.52 | L19: =IF(OR(F19="",E19=""),"",(F19-E19)/($C19*h_storey/3)) -> 0.5 | M19: =IF(OR(G19="",F19=""),"",(G19-F19)/($C19*h_storey/3)) -> 0.55 | N19: =IF(OR(H19="",G19=""),"",(H19-G19)/($C19*h_storey/3)) | O19: =IF(OR(I19="",H19=""),"",(I19-H19)/($C19*h_storey/3)) | P19: =IFERROR(MEDIAN(J19:O19),"") -> 0.51 | Q19: 0.69 | R19: 0.38 | S19: =IF(P19="","",IF(AND(Q19<>"",P19>=Q19),"충족",IF(AND(R19<>"",P19<=R19),"불충족","판단 유보"))) -> 판단 유보
A20: EPS 준불연 | B20: IE1 창 분출 | C20: =EXP(SUMIFS(l2_ln,l2_mat,"EPS_SC",l2_use,"예",l2_t600,">0")/COUNTIFS(l2_mat,"EPS_SC",l2_use,"예",l2_t600,">0")) -> 968.47819 | J20: =IF(D20="","",D20/($C20*h_storey/3)) | K20: =IF(OR(E20="",D20=""),"",(E20-D20)/($C20*h_storey/3)) | L20: =IF(OR(F20="",E20=""),"",(F20-E20)/($C20*h_storey/3)) | M20: =IF(OR(G20="",F20=""),"",(G20-F20)/($C20*h_storey/3)) | N20: =IF(OR(H20="",G20=""),"",(H20-G20)/($C20*h_storey/3)) | O20: =IF(OR(I20="",H20=""),"",(I20-H20)/($C20*h_storey/3)) | P20: =IFERROR(MEDIAN(J20:O20),"") | Q20: 0.57526091 | R20: 0.33321358 | S20: =IF(P20="","",IF(AND(Q20<>"",P20>=Q20),"충족",IF(AND(R20<>"",P20<=R20),"불충족","판단 유보")))
A21: EPS 준불연 | B21: IE2 외부 화원 | C21: =EXP(SUMIFS(l2_ln,l2_mat,"EPS_SC",l2_use,"예",l2_t600,">0")/COUNTIFS(l2_mat,"EPS_SC",l2_use,"예",l2_t600,">0")) -> 968.47819 | J21: =IF(D21="","",D21/($C21*h_storey/3)) | K21: =IF(OR(E21="",D21=""),"",(E21-D21)/($C21*h_storey/3)) | L21: =IF(OR(F21="",E21=""),"",(F21-E21)/($C21*h_storey/3)) | M21: =IF(OR(G21="",F21=""),"",(G21-F21)/($C21*h_storey/3)) | N21: =IF(OR(H21="",G21=""),"",(H21-G21)/($C21*h_storey/3)) | O21: =IF(OR(I21="",H21=""),"",(I21-H21)/($C21*h_storey/3)) | P21: =IFERROR(MEDIAN(J21:O21),"") | Q21: 0.57526091 | R21: 0.33321358 | S21: =IF(P21="","",IF(AND(Q21<>"",P21>=Q21),"충족",IF(AND(R21<>"",P21<=R21),"불충족","판단 유보")))
A22: PIR(PUR) 가연성 | B22: IE1 창 분출 | C22: =EXP(SUMIFS(l2_ln,l2_mat,"PIR_C",l2_use,"예",l2_t600,">0")/COUNTIFS(l2_mat,"PIR_C",l2_use,"예",l2_t600,">0")) -> 29.983329 | J22: =IF(D22="","",D22/($C22*h_storey/3)) | K22: =IF(OR(E22="",D22=""),"",(E22-D22)/($C22*h_storey/3)) | L22: =IF(OR(F22="",E22=""),"",(F22-E22)/($C22*h_storey/3)) | M22: =IF(OR(G22="",F22=""),"",(G22-F22)/($C22*h_storey/3)) | N22: =IF(OR(H22="",G22=""),"",(H22-G22)/($C22*h_storey/3)) | O22: =IF(OR(I22="",H22=""),"",(I22-H22)/($C22*h_storey/3)) | P22: =IFERROR(MEDIAN(J22:O22),"") | R22: 1 | S22: =IF(P22="","",IF(AND(Q22<>"",P22>=Q22),"충족",IF(AND(R22<>"",P22<=R22),"불충족","판단 유보")))
A23: PIR(PUR) 가연성 | B23: IE2 외부 화원 | C23: =EXP(SUMIFS(l2_ln,l2_mat,"PIR_C",l2_use,"예",l2_t600,">0")/COUNTIFS(l2_mat,"PIR_C",l2_use,"예",l2_t600,">0")) -> 29.983329 | J23: =IF(D23="","",D23/($C23*h_storey/3)) | K23: =IF(OR(E23="",D23=""),"",(E23-D23)/($C23*h_storey/3)) | L23: =IF(OR(F23="",E23=""),"",(F23-E23)/($C23*h_storey/3)) | M23: =IF(OR(G23="",F23=""),"",(G23-F23)/($C23*h_storey/3)) | N23: =IF(OR(H23="",G23=""),"",(H23-G23)/($C23*h_storey/3)) | O23: =IF(OR(I23="",H23=""),"",(I23-H23)/($C23*h_storey/3)) | P23: =IFERROR(MEDIAN(J23:O23),"") | R23: 1 | S23: =IF(P23="","",IF(AND(Q23<>"",P23>=Q23),"충족",IF(AND(R23<>"",P23<=R23),"불충족","판단 유보")))
A24: PIR(PUR) 준불연 | B24: IE1 창 분출 | C24: =EXP(SUMIFS(l2_ln,l2_mat,"PIR_SC",l2_use,"예",l2_t600,">0")/COUNTIFS(l2_mat,"PIR_SC",l2_use,"예",l2_t600,">0")) -> 1079.4387 | J24: =IF(D24="","",D24/($C24*h_storey/3)) | K24: =IF(OR(E24="",D24=""),"",(E24-D24)/($C24*h_storey/3)) | L24: =IF(OR(F24="",E24=""),"",(F24-E24)/($C24*h_storey/3)) | M24: =IF(OR(G24="",F24=""),"",(G24-F24)/($C24*h_storey/3)) | N24: =IF(OR(H24="",G24=""),"",(H24-G24)/($C24*h_storey/3)) | O24: =IF(OR(I24="",H24=""),"",(I24-H24)/($C24*h_storey/3)) | P24: =IFERROR(MEDIAN(J24:O24),"") | Q24: 0.68619359 | R24: 0.37566685 | S24: =IF(P24="","",IF(AND(Q24<>"",P24>=Q24),"충족",IF(AND(R24<>"",P24<=R24),"불충족","판단 유보")))
A25: PIR(PUR) 준불연 | B25: IE2 외부 화원 | C25: =EXP(SUMIFS(l2_ln,l2_mat,"PIR_SC",l2_use,"예",l2_t600,">0")/COUNTIFS(l2_mat,"PIR_SC",l2_use,"예",l2_t600,">0")) -> 1079.4387 | J25: =IF(D25="","",D25/($C25*h_storey/3)) | K25: =IF(OR(E25="",D25=""),"",(E25-D25)/($C25*h_storey/3)) | L25: =IF(OR(F25="",E25=""),"",(F25-E25)/($C25*h_storey/3)) | M25: =IF(OR(G25="",F25=""),"",(G25-F25)/($C25*h_storey/3)) | N25: =IF(OR(H25="",G25=""),"",(H25-G25)/($C25*h_storey/3)) | O25: =IF(OR(I25="",H25=""),"",(I25-H25)/($C25*h_storey/3)) | P25: =IFERROR(MEDIAN(J25:O25),"") | Q25: 0.68619359 | R25: 0.37566685 | S25: =IF(P25="","",IF(AND(Q25<>"",P25>=Q25),"충족",IF(AND(R25<>"",P25<=R25),"불충족","판단 유보")))
A26: PF 준불연 외부용 | B26: IE1 창 분출 | C26: =EXP(SUMIFS(l2_ln,l2_mat,"PF_out",l2_use,"예",l2_t600,">0")/COUNTIFS(l2_mat,"PF_out",l2_use,"예",l2_t600,">0")) -> 1345.9105 | J26: =IF(D26="","",D26/($C26*h_storey/3)) | K26: =IF(OR(E26="",D26=""),"",(E26-D26)/($C26*h_storey/3)) | L26: =IF(OR(F26="",E26=""),"",(F26-E26)/($C26*h_storey/3)) | M26: =IF(OR(G26="",F26=""),"",(G26-F26)/($C26*h_storey/3)) | N26: =IF(OR(H26="",G26=""),"",(H26-G26)/($C26*h_storey/3)) | O26: =IF(OR(I26="",H26=""),"",(I26-H26)/($C26*h_storey/3)) | P26: =IFERROR(MEDIAN(J26:O26),"") | Q26: 0.94109392 | R26: 0.39834667 | S26: =IF(P26="","",IF(AND(Q26<>"",P26>=Q26),"충족",IF(AND(R26<>"",P26<=R26),"불충족","판단 유보")))
A27: PF 준불연 외부용 | B27: IE2 외부 화원 | C27: =EXP(SUMIFS(l2_ln,l2_mat,"PF_out",l2_use,"예",l2_t600,">0")/COUNTIFS(l2_mat,"PF_out",l2_use,"예",l2_t600,">0")) -> 1345.9105 | J27: =IF(D27="","",D27/($C27*h_storey/3)) | K27: =IF(OR(E27="",D27=""),"",(E27-D27)/($C27*h_storey/3)) | L27: =IF(OR(F27="",E27=""),"",(F27-E27)/($C27*h_storey/3)) | M27: =IF(OR(G27="",F27=""),"",(G27-F27)/($C27*h_storey/3)) | N27: =IF(OR(H27="",G27=""),"",(H27-G27)/($C27*h_storey/3)) | O27: =IF(OR(I27="",H27=""),"",(I27-H27)/($C27*h_storey/3)) | P27: =IFERROR(MEDIAN(J27:O27),"") | Q27: 0.94109392 | R27: 0.39834667 | S27: =IF(P27="","",IF(AND(Q27<>"",P27>=Q27),"충족",IF(AND(R27<>"",P27<=R27),"불충족","판단 유보")))
A28: PF 준불연 내부용 | B28: IE1 창 분출 | C28: =EXP(SUMIFS(l2_ln,l2_mat,"PF_in",l2_use,"예",l2_t600,">0")/COUNTIFS(l2_mat,"PF_in",l2_use,"예",l2_t600,">0")) -> 512.28117 | J28: =IF(D28="","",D28/($C28*h_storey/3)) | K28: =IF(OR(E28="",D28=""),"",(E28-D28)/($C28*h_storey/3)) | L28: =IF(OR(F28="",E28=""),"",(F28-E28)/($C28*h_storey/3)) | M28: =IF(OR(G28="",F28=""),"",(G28-F28)/($C28*h_storey/3)) | N28: =IF(OR(H28="",G28=""),"",(H28-G28)/($C28*h_storey/3)) | O28: =IF(OR(I28="",H28=""),"",(I28-H28)/($C28*h_storey/3)) | P28: =IFERROR(MEDIAN(J28:O28),"") | R28: 0.84417103 | S28: =IF(P28="","",IF(AND(Q28<>"",P28>=Q28),"충족",IF(AND(R28<>"",P28<=R28),"불충족","판단 유보")))
A29: PF 준불연 내부용 | B29: IE2 외부 화원 | C29: =EXP(SUMIFS(l2_ln,l2_mat,"PF_in",l2_use,"예",l2_t600,">0")/COUNTIFS(l2_mat,"PF_in",l2_use,"예",l2_t600,">0")) -> 512.28117 | J29: =IF(D29="","",D29/($C29*h_storey/3)) | K29: =IF(OR(E29="",D29=""),"",(E29-D29)/($C29*h_storey/3)) | L29: =IF(OR(F29="",E29=""),"",(F29-E29)/($C29*h_storey/3)) | M29: =IF(OR(G29="",F29=""),"",(G29-F29)/($C29*h_storey/3)) | N29: =IF(OR(H29="",G29=""),"",(H29-G29)/($C29*h_storey/3)) | O29: =IF(OR(I29="",H29=""),"",(I29-H29)/($C29*h_storey/3)) | P29: =IFERROR(MEDIAN(J29:O29),"") | R29: 0.84417103 | S29: =IF(P29="","",IF(AND(Q29<>"",P29>=Q29),"충족",IF(AND(R29<>"",P29<=R29),"불충족","판단 유보")))
A31: s_meet·s_fail: 9_L3_정보가치(통합 L1+L2, 스프링클러 설치, 대책 없음). 빈칸 = 범위(0.25–1) 안에서 해당 경계 없음. 층별 s_j가 크게 다르면 '층마다 t600' 가정 대신 층별 시간을 위험도 모델에 직접 넣습니다.
A32: 추가 산출(입력란 별도 기록 권장): 위층 창 열류속(kW/m²), 창 파손 시각, 위층 세대 FED(CO·HCN; 4_L1_FT-IR·콘 CO 수율로 수율 설정).

Sheet 9_L3_정보가치
A1: ⑨ 시뮬레이션(L3)의 정보가치 — s를 알면 판정이 어떻게 갈리는가 (통합 L1+L2, 스프링클러 설치)
A2: s를 고정하고 나머지 불확실성으로 몬테카를로(인식론적 1000 × 우연적 200)를 돌린 기준 충족 비율(값). P(…)는 현재 s 사전분포 LogU(0.25, 1)에서의 확률(수식).
A4: M0 대책 없음 — 기준 충족 비율
A5: 재료 | B5: s → | C5: 0.25 | D5: 0.30 | E5: 0.35 | F5: 0.42 | G5: 0.50 | H5: 0.59 | I5: 0.71 | J5: 0.84 | K5: 1.00
A6: EPS 준불연 | C6: 0.021 | D6: 0.053 | E6: 0.122 | F6: 0.27 | G6: 0.573 | H6: 0.959 | I6: 0.995 | J6: 0.999 | K6: 1
A7: PIR(PUR) 가연성 | C7: 0 | D7: 0 | E7: 0 | F7: 0 | G7: 0 | H7: 0 | I7: 0 | J7: 0 | K7: 0
A8: PIR(PUR) 준불연 | C8: 0.003 | D8: 0.012 | E8: 0.041 | F8: 0.193 | G8: 0.513 | H8: 0.807 | I8: 0.921 | J8: 0.955 | K8: 0.988
A9: PF 준불연 외부용 | C9: 0.004 | D9: 0.015 | E9: 0.034 | F9: 0.127 | G9: 0.268 | H9: 0.455 | I9: 0.664 | J9: 0.827 | K9: 0.939
A10: PF 준불연 내부용 | C10: 0 | D10: 0 | E10: 0 | F10: 0 | G10: 0.002 | H10: 0.008 | I10: 0.029 | J10: 0.095 | K10: 0.271
A12: M1 차단재 + 층간 배리어 — 기준 충족 비율
A13: 재료 | B13: s → | C13: 0.25 | D13: 0.30 | E13: 0.35 | F13: 0.42 | G13: 0.50 | H13: 0.59 | I13: 0.71 | J13: 0.84 | K13: 1.00
A14: EPS 준불연 | C14: 0.99 | D14: 0.996 | E14: 0.999 | F14: 1 | G14: 1 | H14: 1 | I14: 1 | J14: 1 | K14: 1
A15: PIR(PUR) 가연성 | C15: 0 | D15: 0 | E15: 0 | F15: 0 | G15: 0 | H15: 0 | I15: 0 | J15: 0 | K15: 0
A16: PIR(PUR) 준불연 | C16: 0.964 | D16: 0.983 | E16: 0.993 | F16: 0.998 | G16: 1 | H16: 1 | I16: 1 | J16: 1 | K16: 1
A17: PF 준불연 외부용 | C17: 0.957 | D17: 0.972 | E17: 0.98 | F17: 0.991 | G17: 0.998 | H17: 1 | I17: 1 | J17: 1 | K17: 1
A18: PF 준불연 내부용 | C18: 0.929 | D18: 0.934 | E18: 0.936 | F18: 0.943 | G18: 0.956 | H18: 0.969 | I18: 0.982 | J18: 0.995 | K18: 0.998
A20: 판정 경계와 L3 이후 판정이 확정될 확률
A21: 재료 | B21: 대책 | C21: s_meet (이상이면 충족) | D21: s_fail (이하면 불충족) | E21: P(충족 확정) | F21: P(불충족 확정) | G21: P(판정 확정) | H21: 해석
A22: EPS 준불연 | B22: M0 | C22: 0.57526091 | D22: 0.33321358 | E22: =IF(C22="",0,MIN(1,MAX(0,LN(s_hi/C22)/LN(s_hi/s_lo)))) -> 0.39885583 | F22: =IF(D22="",0,MIN(1,MAX(0,1-LN(s_hi/D22)/LN(s_hi/s_lo)))) -> 0.20725955 | G22: =MIN(1,E22+F22) -> 0.60611537 | H22: s ≥ 0.58이면 충족, s ≤ 0.33이면 불충족, 그 사이는 유보
A23: PIR(PUR) 가연성 | B23: M0 | D23: 1 | E23: =IF(C23="",0,MIN(1,MAX(0,LN(s_hi/C23)/LN(s_hi/s_lo)))) -> 0 | F23: =IF(D23="",0,MIN(1,MAX(0,1-LN(s_hi/D23)/LN(s_hi/s_lo)))) -> 1 | G23: =MIN(1,E23+F23) -> 1 | H23: s와 무관하게 불충족(가연성)
A24: PIR(PUR) 준불연 | B24: M0 | C24: 0.68619359 | D24: 0.37566685 | E24: =IF(C24="",0,MIN(1,MAX(0,LN(s_hi/C24)/LN(s_hi/s_lo)))) -> 0.27165623 | F24: =IF(D24="",0,MIN(1,MAX(0,1-LN(s_hi/D24)/LN(s_hi/s_lo)))) -> 0.29376285 | G24: =MIN(1,E24+F24) -> 0.56541908 | H24: s ≥ 0.69이면 충족, s ≤ 0.38이면 불충족, 그 사이는 유보
A25: PF 준불연 외부용 | B25: M0 | C25: 0.94109392 | D25: 0.39834667 | E25: =IF(C25="",0,MIN(1,MAX(0,LN(s_hi/C25)/LN(s_hi/s_lo)))) -> 0.043794696 | F25: =IF(D25="",0,MIN(1,MAX(0,1-LN(s_hi/D25)/LN(s_hi/s_lo)))) -> 0.3360482 | G25: =MIN(1,E25+F25) -> 0.3798429 | H25: s ≥ 0.94이면 충족, s ≤ 0.40이면 불충족, 그 사이는 유보
A26: PF 준불연 내부용 | B26: M0 | D26: 0.84417103 | E26: =IF(C26="",0,MIN(1,MAX(0,LN(s_hi/C26)/LN(s_hi/s_lo)))) -> 0 | F26: =IF(D26="",0,MIN(1,MAX(0,1-LN(s_hi/D26)/LN(s_hi/s_lo)))) -> 0.87780361 | G26: =MIN(1,E26+F26) -> 0.87780361 | H26: s ≤ 1 범위에서 충족 불가 · s ≤ 0.84이면 불충족
A27: EPS 준불연 | B27: M1 | C27: 0.25 | E27: =IF(C27="",0,MIN(1,MAX(0,LN(s_hi/C27)/LN(s_hi/s_lo)))) -> 1 | F27: =IF(D27="",0,MIN(1,MAX(0,1-LN(s_hi/D27)/LN(s_hi/s_lo)))) -> 0 | G27: =MIN(1,E27+F27) -> 1 | H27: s와 무관하게 충족 → 대책 적용 시 L3 불필요
A28: PIR(PUR) 가연성 | B28: M1 | D28: 1 | E28: =IF(C28="",0,MIN(1,MAX(0,LN(s_hi/C28)/LN(s_hi/s_lo)))) -> 0 | F28: =IF(D28="",0,MIN(1,MAX(0,1-LN(s_hi/D28)/LN(s_hi/s_lo)))) -> 1 | G28: =MIN(1,E28+F28) -> 1 | H28: s와 무관하게 불충족(가연성)
A29: PIR(PUR) 준불연 | B29: M1 | C29: 0.25 | E29: =IF(C29="",0,MIN(1,MAX(0,LN(s_hi/C29)/LN(s_hi/s_lo)))) -> 1 | F29: =IF(D29="",0,MIN(1,MAX(0,1-LN(s_hi/D29)/LN(s_hi/s_lo)))) -> 0 | G29: =MIN(1,E29+F29) -> 1 | H29: s와 무관하게 충족 → 대책 적용 시 L3 불필요
A30: PF 준불연 외부용 | B30: M1 | C30: 0.25 | E30: =IF(C30="",0,MIN(1,MAX(0,LN(s_hi/C30)/LN(s_hi/s_lo)))) -> 1 | F30: =IF(D30="",0,MIN(1,MAX(0,1-LN(s_hi/D30)/LN(s_hi/s_lo)))) -> 0 | G30: =MIN(1,E30+F30) -> 1 | H30: s와 무관하게 충족 → 대책 적용 시 L3 불필요
A31: PF 준불연 내부용 | B31: M1 | C31: 0.25 | E31: =IF(C31="",0,MIN(1,MAX(0,LN(s_hi/C31)/LN(s_hi/s_lo)))) -> 1 | F31: =IF(D31="",0,MIN(1,MAX(0,1-LN(s_hi/D31)/LN(s_hi/s_lo)))) -> 0 | G31: =MIN(1,E31+F31) -> 1 | H31: s와 무관하게 충족 → 대책 적용 시 L3 불필요

Sheet 10_위험도결과
A1: ⑩ 증거 수준별 건물 위험도 (몬테카를로, 스프링클러 설치 15층 공동주택, 값)
A2: multiscale.py: 인식론적 2000 × 우연적 400. L2(중규모만)는 facade_fra/qfra.py와 같은 난수로 결과가 일치합니다(상대차 3.2e-13).
A4: 증거 수준 | B4: 재료 | C4: 대책 | D4: R_S 점추정 | E4: R_S 평균 | F4: R_S 5 % | G4: R_S 95 % | H4: F(n≥2) 평균 | I4: 재료 인자 MF (중앙값) | J4: MF 5 % | K4: MF 95 % | L4: 기준 충족 비율 | M4: 판정 (신뢰 90 %)
A5: 등급만(인증서) | B5: 불연 단열재(기준안) | C5: M0 | D5: 1.764e-05 | E5: 1.76513e-05 | F5: 3.2349e-06 | G5: 4.74027e-05 | H5: 1.0625e-06 | I5: 1 | J5: 1 | K5: 1 | L5: 1 | M5: 충족
A6: 등급만(인증서) | B6: EPS 준불연 | C6: M0 | D6: 0.000831744 | E6: 0.0016370968 | F6: 8.82403e-05 | G6: 0.0057722822 | H6: 0.0003618252 | I6: 67.877247 | J6: 6.0153772 | K6: 573.19552 | L6: 0.3155 | M6: 판단 유보
A7: 등급만(인증서) | B7: PIR(PUR) 가연성 | C7: M0 | D7: 0.008355564 | E7: 0.011506746 | F7: 0.0027768003 | G7: 0.030184703 | H7: 0.0008772746 | I7: 630.52022 | J7: 134.80322 | K7: 4289.193 | L7: 0.001 | M7: 불충족
A8: 등급만(인증서) | B8: PIR(PUR) 준불연 | C8: M0 | D8: 0.000831744 | E8: 0.001811762 | F8: 9.64903e-05 | G8: 0.0059813897 | H8: 0.000400182 | I8: 74.750079 | J8: 7.3101906 | K8: 673.7422 | L8: 0.2855 | M8: 판단 유보
A9: 등급만(인증서) | B9: PF 준불연 외부용 | C9: M0 | D9: 0.001150884 | E9: 0.0020575148 | F9: 0.000158023 | G9: 0.0069143589 | H9: 0.000450967 | I9: 88.588271 | J9: 9.2107691 | K9: 778.6793 | L9: 0.2335 | M9: 판단 유보
A10: 등급만(인증서) | B10: PF 준불연 내부용 | C10: M0 | D10: 0.000647604 | E10: 0.0011733169 | F10: 3.32305e-05 | G10: 0.0040754765 | H10: 0.0002696936 | I10: 44.308551 | J10: 2.180988 | K10: 427.44425 | L10: 0.4585 | M10: 판단 유보
A11: 소형시료(등급+TGA) | B11: 불연 단열재(기준안) | C11: M0 | D11: 1.764e-05 | E11: 1.76513e-05 | F11: 3.2349e-06 | G11: 4.74027e-05 | H11: 1.0625e-06 | I11: 1 | J11: 1 | K11: 1 | L11: 1 | M11: 충족
A12: 소형시료(등급+TGA) | B12: EPS 준불연 | C12: M0 | D12: 0.000710244 | E12: 0.0012296833 | F12: 3.90366e-05 | G12: 0.0042460588 | H12: 0.0002832332 | I12: 50.871787 | J12: 2.2542613 | K12: 427.14801 | L12: 0.457 | M12: 판단 유보
A13: 소형시료(등급+TGA) | B13: PIR(PUR) 가연성 | C13: M0 | D13: 0.008355564 | E13: 0.011506746 | F13: 0.0027768003 | G13: 0.030184703 | H13: 0.0008772746 | I13: 630.52022 | J13: 134.80322 | K13: 4289.193 | L13: 0.001 | M13: 불충족
A14: 소형시료(등급+TGA) | B14: PIR(PUR) 준불연 | C14: M0 | D14: 0.000774504 | E14: 0.0012307996 | F14: 0.0001493348 | G14: 0.00376627 | H14: 0.0002982853 | I14: 57.540385 | J14: 9.8430949 | K14: 424.8834 | L14: 0.363 | M14: 판단 유보
A15: 소형시료(등급+TGA) | B15: PF 준불연 외부용 | C15: M0 | D15: 0.000647604 | E15: 0.0012345631 | F15: 0.0001513884 | G15: 0.0039617512 | H15: 0.0003005252 | I15: 58.504131 | J15: 9.1593643 | K15: 425.51448 | L15: 0.3395 | M15: 판단 유보
A16: 소형시료(등급+TGA) | B16: PF 준불연 내부용 | C16: M0 | D16: 0.001285884 | E16: 0.0021705466 | F16: 0.0003327304 | G16: 0.0064567912 | H16: 0.0005152647 | I16: 108.71689 | J16: 19.963893 | K16: 742.21498 | L16: 0.111 | M16: 판단 유보
... A64: 통합(TGA+중규모) | B64: PF 준불연 내부용 | C64: M1 | D64: 0.0001042609 | E64: 0.0001506574 | F64: 3.03663e-05 | G64: 0.0004139229 | H64: 2.77782e-05 | I64: 7.6954409 | J64: 2.2237755 | K64: 50.264855 | L64: 0.961 | M64: 충족
A66: 재료 인자 분해 (통합 L1+L2, 몬테카를로 평균): MF = R_S / R_S(불연 기준안), 증가분 = 확산 몫 + 자립 연소(지속) 몫
A67: 재료 | B67: 대책 | C67: R_S 평균 | D67: R_S (p_B = 0) | E67: MF | F67: 확산 몫 | G67: 지속 몫
A68: EPS 준불연 | B68: M0 | C68: 0.0006164261 | D68: 0.0006051827 | E68: 34.92233 | F68: 0.9812226 | G68: 0.018777395
A69: PIR(PUR) 가연성 | B69: M0 | C69: 0.011497767 | D69: 0.011492802 | E69: 651.38187 | F69: 0.99956755 | G69: 0.0004324545
A70: PIR(PUR) 준불연 | B70: M0 | C70: 0.0008951235 | D70: 0.0007854432 | E70: 50.711345 | F70: 0.87500424 | G70: 0.12499576
A71: PF 준불연 외부용 | B71: M0 | C71: 0.0011451974 | D71: 0.0005276824 | E71: 64.878755 | F71: 0.45233727 | G71: 0.54766273
A72: PF 준불연 내부용 | B72: M0 | C72: 0.002740636 | D72: 0.0020063916 | E72: 155.26498 | F72: 0.73035311 | G72: 0.26964689
A73: EPS 준불연 | B73: M1 | C73: 7.05297e-05 | D73: 7.01071e-05 | E73: 3.9957145 | F73: 0.99200786 | G73: 0.0079921374
A74: PIR(PUR) 가연성 | B74: M1 | C74: 0.011497767 | D74: 0.011492802 | E74: 651.38187 | F74: 0.99956755 | G74: 0.0004324545
A75: PIR(PUR) 준불연 | B75: M1 | C75: 9.29956e-05 | D75: 8.86456e-05 | E75: 5.2684693 | F75: 0.94226593 | G75: 0.057734072
A76: PF 준불연 외부용 | B76: M1 | C76: 0.0001026617 | D76: 6.88686e-05 | E76: 5.8160835 | F76: 0.6024827 | G76: 0.3975173
A77: PF 준불연 내부용 | B77: M1 | C77: 0.0001506574 | D77: 0.0001416407 | E77: 8.5351783 | F77: 0.93220826 | G77: 0.067791743
A79: 재료 평균 t600의 불확실성 (90 % 구간 상한/하한 비) — 증거가 쌓일수록 좁아짐
A80: 제품 | B80: 등급만 (L0) | C80: TGA (L1) | D80: 중규모 (L2) | E80: 통합 (L1+L2) | F80: 비고
A81: PIR(PUR) 준불연 | B81: 5.2864695 | C81: 1.7243334 | D81: 1.2406946 | E81: 1.2220527 | F81: 건물 위험도 구간은 s·빈도가 지배(별도)
A82: PF 준불연 외부용 | B82: 5.2864695 | C82: 1.7243334 | D82: 1.2406946 | E82: 1.2220527 | F82: 건물 위험도 구간은 s·빈도가 지배(별도)
A83: PF 준불연 내부용 | B83: 5.2864695 | C83: 1.7243334 | D83: 1.2406946 | E83: 1.2220527 | F83: 건물 위험도 구간은 s·빈도가 지배(별도)

Sheet 11_EFFECT비교
A1: ⑪ EFFECT(Lamont & Ingolfsson 2018) Tier 2를 이 시험 재료에 적용하면 — 범주형 재료 평가의 한계
A2: 가정: 불연 외장재, 공기층 100 mm(> 75 mm), 15층(30–50 m) 주거 all-out, 스프링클러 설치, 외벽 하부 발화원 있음.
A4: 재료 | B4: EFFECT 단열재 계열 | C4: 연료(Fig. 33·34) | D4: 발화원 | E4: 수직 연결 | F4: 가능성 | G4: 결과 | H4: EFFECT 판정 | I4: 시험 t600 (s) | J4: R = P×S (최대) | K4: R_S 중규모 기반 (평균) | L4: 재료 인자 MF
A5: EPS 가연성 | B5: SPF/XPS/EPS/PUR | C5: High | D5: Medium (외벽 하부 발화원) | E5: 연결 > 3 m → 한 단계 상향 | F5: High | G5: Moderate–Extreme (주거 all-out, 30–50 m) | H5: D (Substantial) | I5: — | J5: — | K5: — | L5: —
A6: EPS 준불연 | B6: SPF/XPS/EPS/PUR | C6: High | D6: Medium (외벽 하부 발화원) | E6: 연결 > 3 m → 한 단계 상향 | F6: High | G6: Moderate–Extreme (주거 all-out, 30–50 m) | H6: D (Substantial) | I6: 968.47819 | J6: 4 | K6: 0.0006795255 | L6: 33.136613
A7: PIR(PUR) 가연성 | B7: PIR/Phenolic 또는 PUR | C7: High | D7: Medium (외벽 하부 발화원) | E7: 연결 > 3 m → 한 단계 상향 | F7: High | G7: Moderate–Extreme (주거 all-out, 30–50 m) | H7: D (Substantial) | I7: 29.983329 | J7: 16 | K7: 0.011497477 | L7: 629.90007
A8: PIR(PUR) 준불연 | B8: PIR/Phenolic 또는 PUR | C8: High | D8: Medium (외벽 하부 발화원) | E8: 연결 > 3 m → 한 단계 상향 | F8: High | G8: Moderate–Extreme (주거 all-out, 30–50 m) | H8: D (Substantial) | I8: 1079.4387 | J8: 6 | K8: 0.0008823218 | L8: 41.25614
A9: PF 준불연 외부용 | B9: PIR/Phenolic | C9: High | D9: Medium (외벽 하부 발화원) | E9: 연결 > 3 m → 한 단계 상향 | F9: High | G9: Moderate–Extreme (주거 all-out, 30–50 m) | H9: D (Substantial) | I9: 1345.9105 | J9: 4 | K9: 0.0010462716 | L9: 49.376613
A10: PF 준불연 내부용 | B10: PIR/Phenolic | C10: High | D10: Medium (외벽 하부 발화원) | E10: 연결 > 3 m → 한 단계 상향 | F10: High | G10: Moderate–Extreme (주거 all-out, 30–50 m) | H10: D (Substantial) | I10: 512.28117 | J10: 12 | K10: 0.0028427649 | L10: 146.91249
A12: EFFECT는 정성적 순위 도구입니다(보고서 초록: 통계·시험자료 부족으로 정성 평가 채택). 같은 'D'라도 시험 t600은 30–1350 s, 재료 인자는 33–630배로 갈립니다.
A13: EFFECT 후속 과제(13장): '외벽 시스템 화재시험으로 외장재·단열재·공기층 조합의 점수 보강' → 이 계산서의 중규모·소형시료 자료가 그 근거 역할을 합니다.

Sheet 12_시험계획
A1: ⑫ 시험·해석 계획 — 어떤 불확실성을 줄이는가
A2: 우선순위 1 = 판정을 바꿀 수 있는 항목(민감도·정보가치 기준).
A4: 척도 | B4: 시험·해석 | C4: 규격 | D4: 조건 | E4: 시편·반복 | F4: 산출 지표 | G4: 위험 차원 | H4: 해결하는 불확실성 | I4: 우선순위
A5: L1 | B5: 콘칼로리미터 | C5: ISO 5660-1 (KS F ISO 5660-1) | D5: 50 kW/m² 10분(준불연 판정) + 25·35·65 kW/m²(TRP·CHF) | E5: 100×100 mm, 면재 포함·심재, 각 3회 | F5: t_ig, pHRR, THR_600, EHC, TSP, CO | G5: D1·D2·D3·D6·G | H5: 가연/준불연 게이트, 착화·발열(TGA 사각지대) | I5: 1
A6: L1 | B6: FT-IR (ATR) | C6: 고체 정성분석 (예: ASTM E1252) | D6: 4000–400 cm⁻¹, 분해능 4 cm⁻¹, 32회 누적 | E6: 심재·면재 각 3 위치 | F6: 고분자 식별, 이소시아누레이트·난연(P) 지수 | G6: G (D1·D2) | H6: 제품 식별·난연제 유무 → 전이함수 적용 여부 | I6: 1
A7: L1 | B7: TGA–FTIR (발생가스) | C7: — | D7: N₂·공기, 5 K/min (기존 TGA와 같게), 전송관 200–250 °C | E7: 2회 | F7: HCN·CO·NCO·HCl 발생 온도·상대량 | G7: D6 | H7: 유해가스 → FDS 수율·FED | I7: 2
A8: L1 | B8: TGA–DSC 보완 | C8: ISO 11358-1 · ASTM E1269 / ISO 11357-4 | D8: 초기 질량 기록, 블랭크·사파이어 보정, EPS 가연성 공기 재측정 | E8: 2–3회 | F8: 잔류량(NU_MATL), c_p, 반응열 | G8: D3·D4 (+L3 입력) | H8: '조건부·종점 의존' 판정 해소 | I8: 2
A9: L1 | B9: (선택) MCC | C9: ASTM D7309 | D9: 1 K/s, 750 °C | E9: 3회 | F9: HRC, THR | G9: D2·D3 | H9: r_max 대신 HRC로 확산식 개선 | I9: 3
A10: L1 | B10: (선택) 총발열량 | C10: ISO 1716 | D10: 봄베 열량계 | E10: 3회 | F10: PCS (MJ/kg) | G10: D3 | H10: A2/B 분류 근거 | I10: 3
A11: L1 | B11: (선택) SEM/EDS·XRF | C11: — | D11: 원소 분석 | E11: 2 위치 | F11: P·Br·Al·Mg·Sb | G11: G | H11: 난연제 확인(FT-IR 보완) | I11: 3
A12: L2 | B12: 중공층 시험 보완 | C12: 현행 방법 | D12: 버너 소화 후 60분 관찰, CO/CO₂·열류속 계측, 반복 3회 | E12: 재료당 3회 | F12: B·지속시간, 가스 | G12: D4·D5·D6 | H12: p_B 표본 확대(현재 2–3회) | I12: 1
A13: L2 | B13: EPS 가연성 재시험 | C13: 현행 방법 | D13: 30분 평가 완주 | E13: 2–3회 | F13: t600, B | G13: D2·D4 | H13: 정량평가 제외 해소 | I13: 1
A14: L2 | B14: 배리어·차단재 포함 시험 | C14: 현행 방법 + 층간 배리어 | D14: 배리어 위·아래 열전대 | E14: 재료 2–3종 | F14: 배리어 통과 시각 t_b | G14: — | H14: M1 효과 p_cb·p_e1 근거 | I14: 1
A15: L3 | B15: FDS 중규모 재현 | C15: FDS 6.9 (PyroSim) | D15: 격자 민감도, TGA 반응 입력(PyroSim 자료), 실측 k·ρ·c | E15: 재료 5종 | F15: t600·온도이력 오차 | G15: D1·D2 | H15: 모델 검증(NFPA 551 8.2.2) | I15: 1
... A17: L3+ | B17: (선택) 실대형 시험 | C17: KS F 8414 | D17: 2–3종 | E17: 1회 | F17: 층간 확산시간 | G17: D2 | H17: s 직접 보정 | I17: 2

Sheet 13_검증
A1: ⑬ 검증 — 엑셀 수식과 파이썬(multiscale.py) 값 비교
A2: 두 구현이 같은 값을 내면 계산 단계의 오류가 없다는 근거입니다(NFPA 551 8.2.1.1).
A4: 항목 | B4: 파이썬 | C4: 엑셀 | D4: 상대차
