Workbook

Sheet 읽는 법
A1: 외벽 정량적 화재위험성평가(QFRA) 계산서 — NFPA 551 5.5 정량적 방법, 중공층 외단열 예제
A3: 목적 | B3: NFPA 551(2022)이 요구하는 정량적 화재위험성평가 R = Σ F·C (식 5.5.1.2·5.5.1.3)를 외벽(중공층 외단열)에 적용하는 절차를 칸 단위로 따라갈 수 있게 만든 계산서입니다. 노란 칸을 바꾸면 사건수목 → 결과 → 위험도 → 허용기준 판정이 다시 계산됩니다.
A4: 계산 구조 | B4: 1) 사건수목(3_사건수목): 세대 화재(IE1)·외부 발화원(IE2)이 외벽을 노출시키는 연간 빈도 F. 2) 결과 모델(4_결과모델): 중공층 시험 t₆₀₀ = '중공층 화재가 한 개 층을 올라가는 시간'으로 보고, 진압·배리어·도약 확산과 겨루어 발화층 위로 번지는 층 수와 노출 인원 C를 계산. 3) 위험도(5_위험도): R = Σ F·C, 초과빈도 F(n), 기준안 대비 RR.
A5: 칸 색 | B5: 노란 바탕 = 바꿀 값(가정·예시값 포함) · 파란 글자 = 입력·측정값 · 검은 글자 = 계산식 · 초록 글자 = 다른 시트에서 가져온 값 · 연두 바탕 = 주요 결과
A6: 단계 ↔ 시트 | B6: ① 문제·범위·허용기준 → 1_입력 · ② 시나리오·빈도 → 3_사건수목 · ③ 결과 → 2_시험자료, 4_결과모델 · ④ 위험도·판정 → 5_위험도 · ⑤ 불확실성 → 6_불확실성(MC) · ⑥ 검증 → 7_검증 · ⑦ 문서화·검토 → 8_문서화점검
A7: 예시값 주의 | B7: 빈도·분기확률·시간 입력은 절차를 보이기 위한 예시값입니다(1_입력의 '근거·대체할 자료' 열). 측정값은 중공층 시험의 t₆₀₀(3000 mm)와 플래그 B뿐입니다. 결과 수치를 그대로 인용하지 말고 국내 통계·실대형 시험값으로 바꾼 뒤 쓰십시오.
A8: 점추정과 MC | B8: 이 시트들의 수식은 '점추정'(최적값, 중앙값, 반복시험 동일 가중)입니다. 분포를 넣은 2중 몬테카를로(인식론적 2,000 × 우연적 400 표본)는 파이썬 qfra.py가 계산하며, 그 결과는 6_불확실성(MC)에 값으로 들어 있습니다. 점추정은 꼬리 위험(진압 지연 등)을 보지 못하므로 판정은 MC 결과로 합니다.
A9: 대책 인정 규칙 | B9: M1(개구부 차단재 + 층간 캐비티 배리어)의 효과는 준불연 등급에만 인정합니다. 가연성 등급(PIR(PUR) 가연성)은 3 m 중공층이 30 s 만에 전면 화염이 되었으므로, 배리어가 이를 막는다는 시험 근거가 생기기 전에는 효과를 0으로 둡니다(NFPA 551 5.1.4.5).
A10: 제외 | B10: EPS 가연성: 시험 기록이 4분(240·262 s)뿐이라 t₆₀₀을 구할 수 없어 정량평가에서 뺐습니다(자료 부족, 6.2.1.3). 재시험 후 2_시험자료에 넣고 '정량평가 사용'을 '예'로 바꾸면 계산에 들어갑니다(이때 4_결과모델에 행 추가 필요).
A11: 재현 | B11: python facade_fra/qfra.py → python facade_fra/report/build_qfra_xlsx.py → recalc. 결과 CSV: facade_fra/results/

Sheet 1_입력
A1: ① 입력값 — 건물, 빈도, 분기확률, 시간, 허용기준
A2: 적용값(노란 칸)이 점추정에 쓰입니다. 하한·상한·분포는 몬테카를로(qfra.py)에서 쓰는 인식론적 불확실성 범위입니다.
A4: 기호 | B4: 항목 | C4: 단위 | D4: 적용값 | E4: 하한 | F4: 상한 | G4: 분포 | H4: 계산용 값(초 단위) | I4: NFPA 551 | J4: 근거 · 대체할 자료
A5: 건물
A6: N | B6: 층수 | C6: 층 | D6: 15 | G6: 고정 | H6: =D6 -> 15 | I6: 4.4.1 | J6: 예제 건물(15층 공동주택). 평가 대상 건물 값으로 바꿈
A7: h | B7: 층고 | C7: m | D7: 3 | G7: 고정 | H7: =D7 -> 3 | I7: 4.4.1 | J7: 중공층 시험 높이 3 m = 1개 층. 층고가 다르면 τ를 h/3 m 비율로 늘림
A8: n_u | B8: 층당 세대 수 | C8: 세대 | D8: 4 | G8: 고정 | H8: =D8 -> 4 | I8: 4.4.2.1 | J8: 예제 건물
A9: o | B9: 세대당 재실자 | C9: 명 | D9: 2.5 | G9: 고정 | H9: =D9 -> 2.5 | I9: 4.4.2.1 | J9: 예제 건물(주거). 야간·주간 재실 분포로 바꿀 수 있음
A10: n_a | B10: 확산 띠 안의 층당 세대 수 | C10: 세대 | D10: 2 | G10: 고정 | H10: =D10 -> 2 | I10: 4.4.2.3 | J10: 외벽 화재가 위로 번질 때 한 층에서 닿는 세대(발화 세대 열 + 이웃 1열)
A11: 빈도
A12: λ₁ | B12: 세대 화재 발생빈도 | C12: /세대·년 | D12: 0.0002 | E12: 0.0001 | F12: 0.0004 | G12: 로그균등 | H12: =D12 -> 0.0002 | I12: 5.3.1.1 | J12: 예시값. 국가화재정보시스템(NFDS) 공동주택 화재 건수 ÷ 세대 수(주택총조사)로 대체
A13: λ₂ | B13: 외부 발화원 화재빈도(외벽 하부) | C13: /동·년 | D13: 0.002 | E13: 0.0005 | F13: 0.008 | G13: 로그균등 | H13: =D13 -> 0.002 | I13: 5.3.1.1, 6.2.1.3 | J13: 예시값(자료 부족). 필로티·주차 차량, 쓰레기, 외부 설비 화재 통계로 대체
A14: 분기확률
A15: p_s | B15: 스프링클러 작동·제어 확률 | C15: – | D15: 0.9 | E15: 0.8 | F15: 0.97 | G15: 삼각 | H15: =D15 -> 0.9 | I15: 5.1.4.5 | J15: 예시값. 국내 스프링클러 작동·효과 통계로 대체
A16: p_FO | B16: 제어 실패 화재의 최성기 도달 확률 | C16: – | D16: 0.15 | E16: 0.05 | F16: 0.3 | G16: 삼각 | H16: =D16 -> 0.15 | I16: 5.1.1.4 | J16: 예시값. NFDS 연소 확대 범위(발화실 밖 확대) 비율로 대체
A17: p_v | B17: 최성기 화재의 창 분출화염 확률 | C17: – | D17: 0.7 | E17: 0.5 | F17: 0.9 | G17: 삼각 | H17: =D17 -> 0.7 | I17: 4.4.2.3 | J17: 예시값. 창호 형식(복층유리·방화유리) 반영
A18: p_x | B18: 외부 화원의 외벽 노출 확률 | C18: – | D18: 0.3 | E18: 0.1 | F18: 0.6 | G18: 삼각 | H18: =D18 -> 0.3 | I18: 4.4.2.3 | J18: 예시값. 화원–외벽 거리, 필로티 구조 반영
A19: p_e0 | B19: 중공층·단열재 노출 확률(차단재 없음) | C19: – | D19: 0.9 | E19: 0.7 | F19: 1 | G19: 삼각 | H19: =D19 -> 0.9 | I19: 4.4.2.3 | J19: 개구부 주위·하부가 열려 있을 때. 현장조사(EFFECT Tier 2 수준)로 확인
A20: p_e1 | B20: 중공층·단열재 노출 확률(불연 차단재 설치) | C20: – | D20: 0.3 | E20: 0.1 | F20: 0.5 | G20: 삼각 | H20: =D20 -> 0.3 | I20: 5.1.4.5 | J20: 예시값. 차단재 시공 품질·시험 근거로 대체
A21: p_cb | B21: 캐비티 배리어가 한 층 경계를 막을 확률 | C21: – | D21: 0.7 | E21: 0.4 | F21: 0.9 | G21: 삼각 | H21: =D21 -> 0.7 | I21: 5.1.4.5 | J21: 예시값. 배리어를 넣은 중공층 시험·실대형 시험(KS F 8414)으로 대체
A22: p_L | B22: 창→창 도약 확산 확률(한 층) | C22: – | D22: 0.15 | E22: 0.05 | F22: 0.3 | G22: 삼각 | H22: =D22 -> 0.15 | I22: 4.4.2.3 | J22: 예시값. 스팬드럴 높이·발코니 유무 반영
A23: 시간
A24: τ_L | B24: 도약 확산 한 층 소요시간(중앙값) | C24: 분 | D24: 12 | E24: 8 | F24: 20 | G24: 삼각 | H24: =D24*60 -> 720 | I24: 5.4 | J24: 예시값. 구획화재 성장시간(FDS·CFAST)으로 대체
A25: T_FS | B25: 외벽 화재 진압 유효 시각(중앙값, 분출 기준) | C25: 분 | D25: 15 | E25: 10 | F25: 25 | G25: 삼각 | H25: =D25*60 -> 900 | I25: 5.1.1.4 | J25: 예시값. 관할 소방서 도착시간 + 전개시간(고가사다리 도달 높이 포함)으로 대체
A26: RSET | B26: 상부층 피난 완료 시각(중앙값, 분출 기준) | C26: 분 | D26: 15 | E26: 10 | F26: 25 | G26: 삼각 | H26: =D26*60 -> 900 | I26: 4.4.2.4 | J26: 예시값. 경보 방식·재실자 특성으로 피난 계산해 대체
A27: 시험 → 실물
A28: s | B28: 실물/시험 층당 확산시간 비(τ = s·t₆₀₀) | C28: – | D28: 0.5 | E28: 0.25 | F28: 1 | G28: 로그균등 | H28: =D28 -> 0.5 | I28: 5.4.4, 6.2.2.5 | J28: 가정. 3 m·30 kW 시험을 실물 분출화염 조건으로 옮기는 계수. 실대형 시험(KS F 8414)으로 보정
A29: 인명 환산
A30: p_d | B30: 노출 재실자 사망 확률(선택) | C30: – | D30: 0.05 | E30: 0.01 | F30: 0.2 | G30: 삼각 | H30: =D30 -> 0.05 | I30: A.5.1.2 | J30: 예시값. 인명 지표로 환산할 때만 사용
A31: 사건별 변동 (σ는 MC 전용, 지속시간 중앙값은 점추정에도 사용)
A32: σ_FS | B32: 진압 시각의 사건별 변동(로그 표준편차) | C32: – | D32: 0.5 | G32: 고정 | H32: =D32 -> 0.5 | I32: A.5.5.6 | J32: 우연적 변동 폭(가정)
A33: σ_R | B33: 피난 완료 시각의 사건별 변동(로그 표준편차) | C33: – | D33: 0.5 | G33: 고정 | H33: =D33 -> 0.5 | I33: A.5.5.6 | J33: 우연적 변동 폭(가정)
A34: σ_L | B34: 도약 소요시간의 사건별 변동(로그 표준편차) | C34: – | D34: 0.3 | G34: 고정 | H34: =D34 -> 0.3 | I34: A.5.5.6 | J34: 우연적 변동 폭(가정)
A35: t_e1 | B35: 분출화염 지속시간 하한(IE1) | C35: 분 | D35: 10 | G35: 고정 | H35: =D35*60 -> 600 | I35: A.5.5.6 | J35: 균등분포 하한(가정)
A36: t_e1 | B36: 분출화염 지속시간 상한(IE1) | C36: 분 | D36: 30 | G36: 고정 | H36: =D36*60 -> 1800 | I36: A.5.5.6 | J36: 균등분포 상한(가정)
A37: t_e2 | B37: 외부 화원 지속시간 하한(IE2) | C37: 분 | D37: 5 | G37: 고정 | H37: =D37*60 -> 300 | I37: A.5.5.6 | J37: 균등분포 하한(가정)
A38: t_e2 | B38: 외부 화원 지속시간 상한(IE2) | C38: 분 | D38: 20 | G38: 고정 | H38: =D38*60 -> 1200 | I38: A.5.5.6 | J38: 균등분포 상한(가정)
A39: 허용기준(예시)
A40: F₂* | B40: 허용기준 예시: 발화층 위 2개 층 이상 확산 빈도 | C40: /동·년 | D40: 0.0001 | G40: 고정 | H40: =D40 -> 0.0001 | I40: 4.4.3, A.5.1.2 | J40: 예시값(규제 기준 아님). 사전협의에서 정함
A41: c* | B41: 기준 충족 판단에 쓰는 신뢰수준 | C41: – | D41: 0.9 | G41: 고정 | H41: =D41 -> 0.9 | I41: 4.5 | J41: 인식론적 표본 중 기준을 만족하는 비율의 하한(가정)
...

Sheet 2_시험자료
A1: ③-1 시험 자료 → 결과 모델 입력 (중공층 100 mm · 외단열 100 mm · 30 kW 20분 · 30분 평가)
A2: t₆₀₀ = 3000 mm에서 ΔT ≥ 600 K가 시작되는 시각 = 중공층 화재가 한 개 층(3 m)을 올라가는 시간(FRI 개념). 플래그 B = 버너 소화 후 자립 연소(6개 높이 중 3곳 이상 ssr ≥ 1).
A4: 시험 | B4: 재료 | C4: 등급 | D4: t₆₀₀ 3000 mm (s) | E4: 플래그 B (1/0) | F4: 정량평가 사용 | G4: τ_F = s·t₆₀₀·h/3 m (s) | H4: 비고
A5: EPS_C-1 | B5: EPS 가연성 | C5: c | E5: 0 | F5: 아니오 | G5: =IF(OR(F5="아니오",D5=""),1000000000,s_scale*D5*h_st/3) -> 1000000000 | H5: 기록 240 s – t₆₀₀ 산정 불가, 정량평가 제외(재시험 필요, 6.2.1.3)
A6: EPS_C-2 | B6: EPS 가연성 | C6: c | E6: 0 | F6: 아니오 | G6: =IF(OR(F6="아니오",D6=""),1000000000,s_scale*D6*h_st/3) -> 1000000000 | H6: 기록 262 s – t₆₀₀ 산정 불가, 정량평가 제외(재시험 필요, 6.2.1.3)
A7: EPS_SC-1 | B7: EPS 준불연 | C7: sc | D7: 962 | E7: 0 | F7: 예 | G7: =IF(OR(F7="아니오",D7=""),1000000000,s_scale*D7*h_st/3) -> 481
A8: EPS_SC-2 | B8: EPS 준불연 | C8: sc | E8: 0 | F8: 예 | G8: =IF(OR(F8="아니오",D8=""),1000000000,s_scale*D8*h_st/3) -> 1000000000 | H8: 30분 안에 3000 mm 600 K 미도달 → 이 사건은 층간 확산 없음
A9: EPS_SC-3 | B9: EPS 준불연 | C9: sc | D9: 975 | E9: 0 | F9: 예 | G9: =IF(OR(F9="아니오",D9=""),1000000000,s_scale*D9*h_st/3) -> 487.5
A10: PIR_C-1 | B10: PIR(PUR) 가연성 | C10: c | D10: 31 | E10: 0 | F10: 예 | G10: =IF(OR(F10="아니오",D10=""),1000000000,s_scale*D10*h_st/3) -> 15.5 | H10: 전체 화염(30 s): 소화 전에 연료 소진 → 플래그 B 판정 대상 아님
A11: PIR_C-2 | B11: PIR(PUR) 가연성 | C11: c | D11: 29 | E11: 0 | F11: 예 | G11: =IF(OR(F11="아니오",D11=""),1000000000,s_scale*D11*h_st/3) -> 14.5 | H11: 전체 화염(30 s): 소화 전에 연료 소진 → 플래그 B 판정 대상 아님
A12: PIR_SC-1 | B12: PIR(PUR) 준불연 | C12: sc | D12: 1068 | E12: 0 | F12: 예 | G12: =IF(OR(F12="아니오",D12=""),1000000000,s_scale*D12*h_st/3) -> 534
A13: PIR_SC-2 | B13: PIR(PUR) 준불연 | C13: sc | D13: 1091 | E13: 0 | F13: 예 | G13: =IF(OR(F13="아니오",D13=""),1000000000,s_scale*D13*h_st/3) -> 545.5
A14: PF_out-1 | B14: PF 준불연 외부용 | C14: sc | D14: 1245 | E14: 1 | F14: 예 | G14: =IF(OR(F14="아니오",D14=""),1000000000,s_scale*D14*h_st/3) -> 622.5
A15: PF_out-2 | B15: PF 준불연 외부용 | C15: sc | D15: 1455 | E15: 1 | F15: 예 | G15: =IF(OR(F15="아니오",D15=""),1000000000,s_scale*D15*h_st/3) -> 727.5
A16: PF_in-1 | B16: PF 준불연 내부용 | C16: sc | D16: 556 | E16: 0 | F16: 예 | G16: =IF(OR(F16="아니오",D16=""),1000000000,s_scale*D16*h_st/3) -> 278
A17: PF_in-2 | B17: PF 준불연 내부용 | C17: sc | D17: 472 | E17: 1 | F17: 예 | G17: =IF(OR(F17="아니오",D17=""),1000000000,s_scale*D17*h_st/3) -> 236
A18: τ_F = 1E+9 s: 층간 확산 없음(600 K 미도달 또는 평가 제외). 정량평가 사용이 '아니오'인 시험은 4_결과모델에 들어가지 않습니다.
A19: 재료별 요약 — p_B는 Jeffreys 추정 (k + ½)/(n + 1): 반복 2–3회의 0/2, 2/2를 0·1로 단정하지 않기 위함
A20: 재료 | B20: 재료명 | C20: 등급 | D20: 시험 수 n | E20: B 횟수 k | F20: p_B | G20: t₆₀₀ 평균 (s) | H20: 해석
A21: EPS_SC | B21: EPS 준불연 | C21: sc | D21: =COUNTIFS($B$5:$B$17,B21,$F$5:$F$17,"예") -> 3 | E21: =SUMIFS($E$5:$E$17,$B$5:$B$17,B21,$F$5:$F$17,"예") -> 0 | F21: =(E21+0.5)/(D21+1) -> 0.125 | G21: =IFERROR(AVERAGEIFS($D$5:$D$17,$B$5:$B$17,B21,$F$5:$F$17,"예"),"") -> 968.5 | H21: 용융형: 3회 중 1회는 30분 안에 600 K 미도달, 자립 연소 없음
A22: PIR_C | B22: PIR(PUR) 가연성 | C22: c | D22: =COUNTIFS($B$5:$B$17,B22,$F$5:$F$17,"예") -> 2 | E22: =SUMIFS($E$5:$E$17,$B$5:$B$17,B22,$F$5:$F$17,"예") -> 0 | F22: =(E22+0.5)/(D22+1) -> 0.16666667 | G22: =IFERROR(AVERAGEIFS($D$5:$D$17,$B$5:$B$17,B22,$F$5:$F$17,"예"),"") -> 30 | H22: 가연성: 30 s 만에 전면 화염 → 층당 시간이 가장 짧음
A23: PIR_SC | B23: PIR(PUR) 준불연 | C23: sc | D23: =COUNTIFS($B$5:$B$17,B23,$F$5:$F$17,"예") -> 2 | E23: =SUMIFS($E$5:$E$17,$B$5:$B$17,B23,$F$5:$F$17,"예") -> 0 | F23: =(E23+0.5)/(D23+1) -> 0.16666667 | G23: =IFERROR(AVERAGEIFS($D$5:$D$17,$B$5:$B$17,B23,$F$5:$F$17,"예"),"") -> 1079.5 | H23: 탄화형, 자립 연소 없음
A24: PF_out | B24: PF 준불연 외부용 | C24: sc | D24: =COUNTIFS($B$5:$B$17,B24,$F$5:$F$17,"예") -> 2 | E24: =SUMIFS($E$5:$E$17,$B$5:$B$17,B24,$F$5:$F$17,"예") -> 2 | F24: =(E24+0.5)/(D24+1) -> 0.83333333 | G24: =IFERROR(AVERAGEIFS($D$5:$D$17,$B$5:$B$17,B24,$F$5:$F$17,"예"),"") -> 1350 | H24: 탄화형, 2회 모두 자립 연소(B) → 진압이 늦으면 계속 올라감
A25: PF_in | B25: PF 준불연 내부용 | C25: sc | D25: =COUNTIFS($B$5:$B$17,B25,$F$5:$F$17,"예") -> 2 | E25: =SUMIFS($E$5:$E$17,$B$5:$B$17,B25,$F$5:$F$17,"예") -> 1 | F25: =(E25+0.5)/(D25+1) -> 0.5 | G25: =IFERROR(AVERAGEIFS($D$5:$D$17,$B$5:$B$17,B25,$F$5:$F$17,"예"),"") -> 514 | H25: 탄화형, 확산 빠름(III등급), 2회 중 1회 자립 연소

Sheet 3_사건수목
A1: ② 사건수목 — 외벽이 화염에 노출되는 연간 빈도 (동·년 기준)
A2: 분기확률은 서로 독립이라고 보고 경로를 따라 곱합니다(NFPA 551 5.3.1.2.2). B1 = 세대 스프링클러 설치, B0 = 미설치.
A4: 단계 | B4: 사건 / 분기 | C4: 분기확률 (식) | D4: B1 (/년) | E4: B0 (/년) | F4: 설명
A5: IE1 | B5: 세대 화재 발생 | C5: λ₁ × 세대 수 | D5: =lam_1*n_units -> 0.012 | E5: =lam_1*n_units -> 0.012 | F5: 초기사건(IE1): 실내 발화
B6: 스프링클러 제어 실패(또는 미설치) | C6: 1 − p_s (B0: 1) | D6: =D5*(1-p_spr) -> 0.0012 | E6: =E5 -> 0.012 | F6: 제어되면 실내 국한(외벽 영향 없음)
B7: 최성기(플래시오버) 도달 | C7: p_FO | D7: =D6*p_fo -> 0.00018 | E7: =E6*p_fo -> 0.0018
B8: 창 파손 · 외부 분출화염 = F₁ | C8: p_v | D8: =D7*p_vent -> 0.000126 | E8: =E7*p_vent -> 0.00126 | F8: 외벽 노출 사건(IE1)의 빈도 F₁
B9: ├ 중공층·단열재 노출 (M0) | C9: p_e0 | D9: =D8*p_exp0 -> 0.0001134 | E9: =E8*p_exp0 -> 0.001134 | F9: → 외벽 경로 + 창→창 도약 (4_결과모델: IE1)
B10: ├ 노출 안 됨 (M0) | C10: 1 − p_e0 | D10: =D8*(1-p_exp0) -> 1.26e-05 | E10: =E8*(1-p_exp0) -> 0.000126 | F10: → 창→창 도약만
B11: ├ 중공층·단열재 노출 (M1, 준불연만) | C11: p_e1 | D11: =D8*p_exp1 -> 3.78e-05 | E11: =E8*p_exp1 -> 0.000378 | F11: 개구부 불연 차단재가 있을 때
B12: └ 노출 안 됨 (M1, 준불연만) | C12: 1 − p_e1 | D12: =D8*(1-p_exp1) -> 8.82e-05 | E12: =E8*(1-p_exp1) -> 0.000882
A13: IE2 | B13: 외부 발화원 화재(외벽 하부) | C13: λ₂ | D13: =lam_2 -> 0.002 | E13: =lam_2 -> 0.002 | F13: 초기사건(IE2): 필로티·주차 차량, 쓰레기, 외부 설비
B14: 외벽 화염 노출 = F₂ | C14: p_x | D14: =D13*p_x2 -> 0.0006 | E14: =E13*p_x2 -> 0.0006 | F14: 외벽 노출 사건(IE2)의 빈도 F₂ (스프링클러 무관)
B15: ├ 중공층·단열재 노출 (M0) | C15: p_e0 | D15: =D14*p_exp0 -> 0.00054 | E15: =E14*p_exp0 -> 0.00054 | F15: → 외벽 경로만 (도약 없음; 4_결과모델: IE2)
B16: ├ 노출 안 됨 (M0) | C16: 1 − p_e0 | D16: =D14*(1-p_exp0) -> 6e-05 | E16: =E14*(1-p_exp0) -> 6e-05 | F16: → 확산 없음
B17: ├ 중공층·단열재 노출 (M1, 준불연만) | C17: p_e1 | D17: =D14*p_exp1 -> 0.00018 | E17: =E14*p_exp1 -> 0.00018
B18: └ 노출 안 됨 (M1, 준불연만) | C18: 1 − p_e1 | D18: =D14*(1-p_exp1) -> 0.00042 | E18: =E14*(1-p_exp1) -> 0.00042
A20: 불연 단열재(기준안)는 중공층 경로가 없으므로 IE1은 모두 '도약만', IE2는 확산 없음으로 계산합니다. 가연성 등급은 M1이어도 M0의 분기확률(p_e0, 배리어 없음)을 씁니다.

Sheet 4_결과모델
A1: ③-2 결과 모델 — 발화층 위로 번지는 층 수와 노출 인원 (사건 1회당 기대값)
A2: n_F = ⌊min(T_FS, T_stop)/τ_F⌋, a_j = q^j·[j ≤ n_F], b_j = p_L^j·[j ≤ n_L], P(n ≥ j) = w_j·(1 − (1 − a_j)(1 − b_j)), w_j = (N − j)/N (IE1: 발화층 균등) 또는 1 (IE2: 1층 발화). 층 j는 먼저 닿는 경로의 도달시각이 RSET보다 이르면 노출.
A4: j (발화층 위 층) | B4: 1 | C4: 2 | D4: 3 | E4: 4 | F4: 5 | G4: 6 | H4: 7 | I4: 8 | J4: 9 | K4: 10 | L4: 11 | M4: 12 | N4: 13 | O4: 14 | P4: 15 | Q4: 16 | R4: 17 | S4: 18 | T4: 19 | U4: 20 | V4: 21 | W4: 22 | X4: 23 | Y4: 24 | Z4: 25 | AA4: 26 | AB4: 27 | AC4: 28 | AD4: 29 | AE4: 30 | AF4: 31 | AG4: 32 | AH4: 33 | AI4: 34 | AJ4: 35 | AK4: 36 | AL4: 37 | AM4: 38 | AN4: 39 | AO4: 40 | AP4: 41 | AQ4: 42 | AR4: 43 | AS4: 44 | AT4: 45 | AU4: 46 | AV4: 47 | AW4: 48 | AX4: 49 | AY4: 50 | AZ4: 51 | BA4: 52 | BB4: 53 | BC4: 54 | BD4: 55 | BE4: 56 | BF4: 57 | BG4: 58 | BH4: 59
A5: w_j (IE1) | B5: =IF(B4<N_st,(N_st-B4)/N_st,0) -> 0.93333333 | C5: =IF(C4<N_st,(N_st-C4)/N_st,0) -> 0.86666667 | D5: =IF(D4<N_st,(N_st-D4)/N_st,0) -> 0.8 | E5: =IF(E4<N_st,(N_st-E4)/N_st,0) -> 0.73333333 | F5: =IF(F4<N_st,(N_st-F4)/N_st,0) -> 0.66666667 | G5: =IF(G4<N_st,(N_st-G4)/N_st,0) -> 0.6 | H5: =IF(H4<N_st,(N_st-H4)/N_st,0) -> 0.53333333 | I5: =IF(I4<N_st,(N_st-I4)/N_st,0) -> 0.46666667 | ... BH5: =IF(BH4<N_st,(N_st-BH4)/N_st,0) -> 0
A6: w_j (IE2) | B6: =IF(B4<N_st,1,0) -> 1 | C6: =IF(C4<N_st,1,0) -> 1 | D6: =IF(D4<N_st,1,0) -> 1 | E6: =IF(E4<N_st,1,0) -> 1 | F6: =IF(F4<N_st,1,0) -> 1 | G6: =IF(G4<N_st,1,0) -> 1 | H6: =IF(H4<N_st,1,0) -> 1 | I6: =IF(I4<N_st,1,0) -> 1 | ... BH6: =IF(BH4<N_st,1,0) -> 0
A8: 사건 행: 반복시험 × B 상태 × 사건(IE1/IE2) × 배리어. 가중치 = (1/n) × (B면 p_B, 아니면 1 − p_B). 'L'은 중공층 경로가 없는 창→창 도약만의 경로(IE1, 불연 기준안과 '노출 안 됨' 분기에 사용). | O8: 1 | P8: 2 | Q8: 3 | R8: 4 | S8: 5 | T8: 6 | U8: 7 | V8: 8 | W8: 9 | X8: 10 | Y8: 11 | Z8: 12 | AA8: 13 | AB8: 14 | AC8: 15 | AD8: 16 | AE8: 17 | AF8: 18 | AG8: 19 | AH8: 20
A9: 재료 | B9: 시험 | C9: 사건 | D9: 배리어(1/0) | E9: B 상태(1/0) | F9: 가중치 | G9: τ_F (s) | H9: T_stop (s) | I9: n_F | J9: n_L | K9: q = 1 − p_cb | L9: p_L(사건) | M9: E[확산 층 수] | N9: E[노출 인원] | O9: P(n≥1) | P9: P(n≥2) | Q9: P(n≥3) | R9: P(n≥4) | S9: P(n≥5) | T9: P(n≥6) | U9: P(n≥7) | V9: P(n≥8) | W9: P(n≥9) | X9: P(n≥10) | Y9: P(n≥11) | Z9: P(n≥12) | AA9: P(n≥13) | AB9: P(n≥14) | AC9: P(n≥15) | AD9: P(n≥16) | AE9: P(n≥17) | AF9: P(n≥18) | AG9: P(n≥19) | AH9: P(n≥20)
A10: EPS_SC | B10: EPS_SC-1 | C10: 1 | D10: 0 | E10: 1 | F10: =(1/2_시험자료!$D$21)*2_시험자료!$F$21 -> 0.041666667 | G10: =2_시험자료!G7 -> 481 | H10: =IF(E10=1,1000000000,texp1_s) -> 1000000000 | I10: =FLOOR(MIN(t_fs_s,H10)/G10,1) -> 1 | J10: =IF(C10=1,FLOOR(t_fs_s/tau_L_s,1),0) -> 1 | K10: =IF(D10=1,1-p_cb,1) -> 1 | L10: =IF(C10=1,p_L,0) -> 0.15 | M10: =SUMPRODUCT(w_ie1,1-(1-(j_row<=I10)*K10^j_row)*(1-(j_row<=J10)*L10^j_row)) -> 0.93333333 | N10: =occ_st*SUMPRODUCT(w_ie1,(j_row<=I10)*K10^j_row*(j_row<=J10)*L10^j_row*(((j_row*G10<rset_s)+(j_row*tau_L_s<rset_s))>0)+(j_row<=I10)*K10^j_row*(1-(j_row<=J10)*L10^j_row)*(j_row*G10<rset_s)+(1-(j_row<=I10)*K10^j_row)*(j_row<=J10)*L10^j_row*(j_row*tau_L_s<rset_s)) -> 4.6666667 | O10: =IF(O$8<N_st,(N_st-O$8)/N_st,0)*(1-(1-(O$8<=I10)*K10^O$8)*(1-(O$8<=J10)*L10^O$8)) -> 0.93333333 | P10: =IF(P$8<N_st,(N_st-P$8)/N_st,0)*(1-(1-(P$8<=I10)*K10^P$8)*(1-(P$8<=J10)*L10^P$8)) -> 0 | Q10: =IF(Q$8<N_st,(N_st-Q$8)/N_st,0)*(1-(1-(Q$8<=I10)*K10^Q$8)*(1-(Q$8<=J10)*L10^Q$8)) -> 0 | R10: =IF(R$8<N_st,(N_st-R$8)/N_st,0)*(1-(1-(R$8<=I10)*K10^R$8)*(1-(R$8<=J10)*L10^R$8)) -> 0 | S10: =IF(S$8<N_st,(N_st-S$8)/N_st,0)*(1-(1-(S$8<=I10)*K10^S$8)*(1-(S$8<=J10)*L10^S$8)) -> 0 | T10: =IF(T$8<N_st,(N_st-T$8)/N_st,0)*(1-(1-(T$8<=I10)*K10^T$8)*(1-(T$8<=J10)*L10^T$8)) -> 0 | U10: =IF(U$8<N_st,(N_st-U$8)/N_st,0)*(1-(1-(U$8<=I10)*K10^U$8)*(1-(U$8<=J10)*L10^U$8)) -> 0 | V10: =IF(V$8<N_st,(N_st-V$8)/N_st,0)*(1-(1-(V$8<=I10)*K10^V$8)*(1-(V$8<=J10)*L10^V$8)) -> 0 | W10: =IF(W$8<N_st,(N_st-W$8)/N_st,0)*(1-(1-(W$8<=I10)*K10^W$8)*(1-(W$8<=J10)*L10^W$8)) -> 0 | X10: =IF(X$8<N_st,(N_st-X$8)/N_st,0)*(1-(1-(X$8<=I10)*K10^X$8)*(1-(X$8<=J10)*L10^X$8)) -> 0 | Y10: =IF(Y$8<N_st,(N_st-Y$8)/N_st,0)*(1-(1-(Y$8<=I10)*K10^Y$8)*(1-(Y$8<=J10)*L10^Y$8)) -> 0 | Z10: =IF(Z$8<N_st,(N_st-Z$8)/N_st,0)*(1-(1-(Z$8<=I10)*K10^Z$8)*(1-(Z$8<=J10)*L10^Z$8)) -> 0 | AA10: =IF(AA$8<N_st,(N_st-AA$8)/N_st,0)*(1-(1-(AA$8<=I10)*K10^AA$8)*(1-(AA$8<=J10)*L10^AA$8)) -> 0 | AB10: =IF(AB$8<N_st,(N_st-AB$8)/N_st,0)*(1-(1-(AB$8<=I10)*K10^AB$8)*(1-(AB$8<=J10)*L10^AB$8)) -> 0 | AC10: =IF(AC$8<N_st,(N_st-AC$8)/N_st,0)*(1-(1-(AC$8<=I10)*K10^AC$8)*(1-(AC$8<=J10)*L10^AC$8)) -> 0 | AD10: =IF(AD$8<N_st,(N_st-AD$8)/N_st,0)*(1-(1-(AD$8<=I10)*K10^AD$8)*(1-(AD$8<=J10)*L10^AD$8)) -> 0 | AE10: =IF(AE$8<N_st,(N_st-AE$8)/N_st,0)*(1-(1-(AE$8<=I10)*K10^AE$8)*(1-(AE$8<=J10)*L10^AE$8)) -> 0 | AF10: =IF(AF$8<N_st,(N_st-AF$8)/N_st,0)*(1-(1-(AF$8<=I10)*K10^AF$8)*(1-(AF$8<=J10)*L10^AF$8)) -> 0 | AG10: =IF(AG$8<N_st,(N_st-AG$8)/N_st,0)*(1-(1-(AG$8<=I10)*K10^AG$8)*(1-(AG$8<=J10)*L10^AG$8)) -> 0 | AH10: =IF(AH$8<N_st,(N_st-AH$8)/N_st,0)*(1-(1-(AH$8<=I10)*K10^AH$8)*(1-(AH$8<=J10)*L10^AH$8)) -> 0
A11: EPS_SC | B11: EPS_SC-1 | C11: 1 | D11: 0 | E11: 0 | F11: =(1/2_시험자료!$D$21)*(1-2_시험자료!$F$21) -> 0.29166667 | G11: =2_시험자료!G7 -> 481 | H11: =IF(E11=1,1000000000,texp1_s) -> 1200 | I11: =FLOOR(MIN(t_fs_s,H11)/G11,1) -> 1 | J11: =IF(C11=1,FLOOR(t_fs_s/tau_L_s,1),0) -> 1 | K11: =IF(D11=1,1-p_cb,1) -> 1 | L11: =IF(C11=1,p_L,0) -> 0.15 | M11: =SUMPRODUCT(w_ie1,1-(1-(j_row<=I11)*K11^j_row)*(1-(j_row<=J11)*L11^j_row)) -> 0.93333333 | N11: =occ_st*SUMPRODUCT(w_ie1,(j_row<=I11)*K11^j_row*(j_row<=J11)*L11^j_row*(((j_row*G11<rset_s)+(j_row*tau_L_s<rset_s))>0)+(j_row<=I11)*K11^j_row*(1-(j_row<=J11)*L11^j_row)*(j_row*G11<rset_s)+(1-(j_row<=I11)*K11^j_row)*(j_row<=J11)*L11^j_row*(j_row*tau_L_s<rset_s)) -> 4.6666667 | O11: =IF(O$8<N_st,(N_st-O$8)/N_st,0)*(1-(1-(O$8<=I11)*K11^O$8)*(1-(O$8<=J11)*L11^O$8)) -> 0.93333333 | P11: =IF(P$8<N_st,(N_st-P$8)/N_st,0)*(1-(1-(P$8<=I11)*K11^P$8)*(1-(P$8<=J11)*L11^P$8)) -> 0 | Q11: =IF(Q$8<N_st,(N_st-Q$8)/N_st,0)*(1-(1-(Q$8<=I11)*K11^Q$8)*(1-(Q$8<=J11)*L11^Q$8)) -> 0 | R11: =IF(R$8<N_st,(N_st-R$8)/N_st,0)*(1-(1-(R$8<=I11)*K11^R$8)*(1-(R$8<=J11)*L11^R$8)) -> 0 | S11: =IF(S$8<N_st,(N_st-S$8)/N_st,0)*(1-(1-(S$8<=I11)*K11^S$8)*(1-(S$8<=J11)*L11^S$8)) -> 0 | T11: =IF(T$8<N_st,(N_st-T$8)/N_st,0)*(1-(1-(T$8<=I11)*K11^T$8)*(1-(T$8<=J11)*L11^T$8)) -> 0 | U11: =IF(U$8<N_st,(N_st-U$8)/N_st,0)*(1-(1-(U$8<=I11)*K11^U$8)*(1-(U$8<=J11)*L11^U$8)) -> 0 | V11: =IF(V$8<N_st,(N_st-V$8)/N_st,0)*(1-(1-(V$8<=I11)*K11^V$8)*(1-(V$8<=J11)*L11^V$8)) -> 0 | W11: =IF(W$8<N_st,(N_st-W$8)/N_st,0)*(1-(1-(W$8<=I11)*K11^W$8)*(1-(W$8<=J11)*L11^W$8)) -> 0 | X11: =IF(X$8<N_st,(N_st-X$8)/N_st,0)*(1-(1-(X$8<=I11)*K11^X$8)*(1-(X$8<=J11)*L11^X$8)) -> 0 | Y11: =IF(Y$8<N_st,(N_st-Y$8)/N_st,0)*(1-(1-(Y$8<=I11)*K11^Y$8)*(1-(Y$8<=J11)*L11^Y$8)) -> 0 | Z11: =IF(Z$8<N_st,(N_st-Z$8)/N_st,0)*(1-(1-(Z$8<=I11)*K11^Z$8)*(1-(Z$8<=J11)*L11^Z$8)) -> 0 | AA11: =IF(AA$8<N_st,(N_st-AA$8)/N_st,0)*(1-(1-(AA$8<=I11)*K11^AA$8)*(1-(AA$8<=J11)*L11^AA$8)) -> 0 | AB11: =IF(AB$8<N_st,(N_st-AB$8)/N_st,0)*(1-(1-(AB$8<=I11)*K11^AB$8)*(1-(AB$8<=J11)*L11^AB$8)) -> 0 | AC11: =IF(AC$8<N_st,(N_st-AC$8)/N_st,0)*(1-(1-(AC$8<=I11)*K11^AC$8)*(1-(AC$8<=J11)*L11^AC$8)) -> 0 | AD11: =IF(AD$8<N_st,(N_st-AD$8)/N_st,0)*(1-(1-(AD$8<=I11)*K11^AD$8)*(1-(AD$8<=J11)*L11^AD$8)) -> 0 | AE11: =IF(AE$8<N_st,(N_st-AE$8)/N_st,0)*(1-(1-(AE$8<=I11)*K11^AE$8)*(1-(AE$8<=J11)*L11^AE$8)) -> 0 | AF11: =IF(AF$8<N_st,(N_st-AF$8)/N_st,0)*(1-(1-(AF$8<=I11)*K11^AF$8)*(1-(AF$8<=J11)*L11^AF$8)) -> 0 | AG11: =IF(AG$8<N_st,(N_st-AG$8)/N_st,0)*(1-(1-(AG$8<=I11)*K11^AG$8)*(1-(AG$8<=J11)*L11^AG$8)) -> 0 | AH11: =IF(AH$8<N_st,(N_st-AH$8)/N_st,0)*(1-(1-(AH$8<=I11)*K11^AH$8)*(1-(AH$8<=J11)*L11^AH$8)) -> 0
A12: EPS_SC | B12: EPS_SC-1 | C12: 1 | D12: 1 | E12: 1 | F12: =(1/2_시험자료!$D$21)*2_시험자료!$F$21 -> 0.041666667 | G12: =2_시험자료!G7 -> 481 | H12: =IF(E12=1,1000000000,texp1_s) -> 1000000000 | I12: =FLOOR(MIN(t_fs_s,H12)/G12,1) -> 1 | J12: =IF(C12=1,FLOOR(t_fs_s/tau_L_s,1),0) -> 1 | K12: =IF(D12=1,1-p_cb,1) -> 0.3 | L12: =IF(C12=1,p_L,0) -> 0.15 | M12: =SUMPRODUCT(w_ie1,1-(1-(j_row<=I12)*K12^j_row)*(1-(j_row<=J12)*L12^j_row)) -> 0.378 | N12: =occ_st*SUMPRODUCT(w_ie1,(j_row<=I12)*K12^j_row*(j_row<=J12)*L12^j_row*(((j_row*G12<rset_s)+(j_row*tau_L_s<rset_s))>0)+(j_row<=I12)*K12^j_row*(1-(j_row<=J12)*L12^j_row)*(j_row*G12<rset_s)+(1-(j_row<=I12)*K12^j_row)*(j_row<=J12)*L12^j_row*(j_row*tau_L_s<rset_s)) -> 1.89 | O12: =IF(O$8<N_st,(N_st-O$8)/N_st,0)*(1-(1-(O$8<=I12)*K12^O$8)*(1-(O$8<=J12)*L12^O$8)) -> 0.378 | P12: =IF(P$8<N_st,(N_st-P$8)/N_st,0)*(1-(1-(P$8<=I12)*K12^P$8)*(1-(P$8<=J12)*L12^P$8)) -> 0 | Q12: =IF(Q$8<N_st,(N_st-Q$8)/N_st,0)*(1-(1-(Q$8<=I12)*K12^Q$8)*(1-(Q$8<=J12)*L12^Q$8)) -> 0 | R12: =IF(R$8<N_st,(N_st-R$8)/N_st,0)*(1-(1-(R$8<=I12)*K12^R$8)*(1-(R$8<=J12)*L12^R$8)) -> 0 | S12: =IF(S$8<N_st,(N_st-S$8)/N_st,0)*(1-(1-(S$8<=I12)*K12^S$8)*(1-(S$8<=J12)*L12^S$8)) -> 0 | T12: =IF(T$8<N_st,(N_st-T$8)/N_st,0)*(1-(1-(T$8<=I12)*K12^T$8)*(1-(T$8<=J12)*L12^T$8)) -> 0 | U12: =IF(U$8<N_st,(N_st-U$8)/N_st,0)*(1-(1-(U$8<=I12)*K12^U$8)*(1-(U$8<=J12)*L12^U$8)) -> 0 | V12: =IF(V$8<N_st,(N_st-V$8)/N_st,0)*(1-(1-(V$8<=I12)*K12^V$8)*(1-(V$8<=J12)*L12^V$8)) -> 0 | W12: =IF(W$8<N_st,(N_st-W$8)/N_st,0)*(1-(1-(W$8<=I12)*K12^W$8)*(1-(W$8<=J12)*L12^W$8)) -> 0 | X12: =IF(X$8<N_st,(N_st-X$8)/N_st,0)*(1-(1-(X$8<=I12)*K12^X$8)*(1-(X$8<=J12)*L12^X$8)) -> 0 | Y12: =IF(Y$8<N_st,(N_st-Y$8)/N_st,0)*(1-(1-(Y$8<=I12)*K12^Y$8)*(1-(Y$8<=J12)*L12^Y$8)) -> 0 | Z12: =IF(Z$8<N_st,(N_st-Z$8)/N_st,0)*(1-(1-(Z$8<=I12)*K12^Z$8)*(1-(Z$8<=J12)*L12^Z$8)) -> 0 | AA12: =IF(AA$8<N_st,(N_st-AA$8)/N_st,0)*(1-(1-(AA$8<=I12)*K12^AA$8)*(1-(AA$8<=J12)*L12^AA$8)) -> 0 | AB12: =IF(AB$8<N_st,(N_st-AB$8)/N_st,0)*(1-(1-(AB$8<=I12)*K12^AB$8)*(1-(AB$8<=J12)*L12^AB$8)) -> 0 | AC12: =IF(AC$8<N_st,(N_st-AC$8)/N_st,0)*(1-(1-(AC$8<=I12)*K12^AC$8)*(1-(AC$8<=J12)*L12^AC$8)) -> 0 | AD12: =IF(AD$8<N_st,(N_st-AD$8)/N_st,0)*(1-(1-(AD$8<=I12)*K12^AD$8)*(1-(AD$8<=J12)*L12^AD$8)) -> 0 | AE12: =IF(AE$8<N_st,(N_st-AE$8)/N_st,0)*(1-(1-(AE$8<=I12)*K12^AE$8)*(1-(AE$8<=J12)*L12^AE$8)) -> 0 | AF12: =IF(AF$8<N_st,(N_st-AF$8)/N_st,0)*(1-(1-(AF$8<=I12)*K12^AF$8)*(1-(AF$8<=J12)*L12^AF$8)) -> 0 | AG12: =IF(AG$8<N_st,(N_st-AG$8)/N_st,0)*(1-(1-(AG$8<=I12)*K12^AG$8)*(1-(AG$8<=J12)*L12^AG$8)) -> 0 | AH12: =IF(AH$8<N_st,(N_st-AH$8)/N_st,0)*(1-(1-(AH$8<=I12)*K12^AH$8)*(1-(AH$8<=J12)*L12^AH$8)) -> 0
A13: EPS_SC | B13: EPS_SC-1 | C13: 1 | D13: 1 | E13: 0 | F13: =(1/2_시험자료!$D$21)*(1-2_시험자료!$F$21) -> 0.29166667 | G13: =2_시험자료!G7 -> 481 | H13: =IF(E13=1,1000000000,texp1_s) -> 1200 | I13: =FLOOR(MIN(t_fs_s,H13)/G13,1) -> 1 | J13: =IF(C13=1,FLOOR(t_fs_s/tau_L_s,1),0) -> 1 | K13: =IF(D13=1,1-p_cb,1) -> 0.3 | L13: =IF(C13=1,p_L,0) -> 0.15 | M13: =SUMPRODUCT(w_ie1,1-(1-(j_row<=I13)*K13^j_row)*(1-(j_row<=J13)*L13^j_row)) -> 0.378 | N13: =occ_st*SUMPRODUCT(w_ie1,(j_row<=I13)*K13^j_row*(j_row<=J13)*L13^j_row*(((j_row*G13<rset_s)+(j_row*tau_L_s<rset_s))>0)+(j_row<=I13)*K13^j_row*(1-(j_row<=J13)*L13^j_row)*(j_row*G13<rset_s)+(1-(j_row<=I13)*K13^j_row)*(j_row<=J13)*L13^j_row*(j_row*tau_L_s<rset_s)) -> 1.89 | O13: =IF(O$8<N_st,(N_st-O$8)/N_st,0)*(1-(1-(O$8<=I13)*K13^O$8)*(1-(O$8<=J13)*L13^O$8)) -> 0.378 | P13: =IF(P$8<N_st,(N_st-P$8)/N_st,0)*(1-(1-(P$8<=I13)*K13^P$8)*(1-(P$8<=J13)*L13^P$8)) -> 0 | Q13: =IF(Q$8<N_st,(N_st-Q$8)/N_st,0)*(1-(1-(Q$8<=I13)*K13^Q$8)*(1-(Q$8<=J13)*L13^Q$8)) -> 0 | R13: =IF(R$8<N_st,(N_st-R$8)/N_st,0)*(1-(1-(R$8<=I13)*K13^R$8)*(1-(R$8<=J13)*L13^R$8)) -> 0 | S13: =IF(S$8<N_st,(N_st-S$8)/N_st,0)*(1-(1-(S$8<=I13)*K13^S$8)*(1-(S$8<=J13)*L13^S$8)) -> 0 | T13: =IF(T$8<N_st,(N_st-T$8)/N_st,0)*(1-(1-(T$8<=I13)*K13^T$8)*(1-(T$8<=J13)*L13^T$8)) -> 0 | U13: =IF(U$8<N_st,(N_st-U$8)/N_st,0)*(1-(1-(U$8<=I13)*K13^U$8)*(1-(U$8<=J13)*L13^U$8)) -> 0 | V13: =IF(V$8<N_st,(N_st-V$8)/N_st,0)*(1-(1-(V$8<=I13)*K13^V$8)*(1-(V$8<=J13)*L13^V$8)) -> 0 | W13: =IF(W$8<N_st,(N_st-W$8)/N_st,0)*(1-(1-(W$8<=I13)*K13^W$8)*(1-(W$8<=J13)*L13^W$8)) -> 0 | X13: =IF(X$8<N_st,(N_st-X$8)/N_st,0)*(1-(1-(X$8<=I13)*K13^X$8)*(1-(X$8<=J13)*L13^X$8)) -> 0 | Y13: =IF(Y$8<N_st,(N_st-Y$8)/N_st,0)*(1-(1-(Y$8<=I13)*K13^Y$8)*(1-(Y$8<=J13)*L13^Y$8)) -> 0 | Z13: =IF(Z$8<N_st,(N_st-Z$8)/N_st,0)*(1-(1-(Z$8<=I13)*K13^Z$8)*(1-(Z$8<=J13)*L13^Z$8)) -> 0 | AA13: =IF(AA$8<N_st,(N_st-AA$8)/N_st,0)*(1-(1-(AA$8<=I13)*K13^AA$8)*(1-(AA$8<=J13)*L13^AA$8)) -> 0 | AB13: =IF(AB$8<N_st,(N_st-AB$8)/N_st,0)*(1-(1-(AB$8<=I13)*K13^AB$8)*(1-(AB$8<=J13)*L13^AB$8)) -> 0 | AC13: =IF(AC$8<N_st,(N_st-AC$8)/N_st,0)*(1-(1-(AC$8<=I13)*K13^AC$8)*(1-(AC$8<=J13)*L13^AC$8)) -> 0 | AD13: =IF(AD$8<N_st,(N_st-AD$8)/N_st,0)*(1-(1-(AD$8<=I13)*K13^AD$8)*(1-(AD$8<=J13)*L13^AD$8)) -> 0 | AE13: =IF(AE$8<N_st,(N_st-AE$8)/N_st,0)*(1-(1-(AE$8<=I13)*K13^AE$8)*(1-(AE$8<=J13)*L13^AE$8)) -> 0 | AF13: =IF(AF$8<N_st,(N_st-AF$8)/N_st,0)*(1-(1-(AF$8<=I13)*K13^AF$8)*(1-(AF$8<=J13)*L13^AF$8)) -> 0 | AG13: =IF(AG$8<N_st,(N_st-AG$8)/N_st,0)*(1-(1-(AG$8<=I13)*K13^AG$8)*(1-(AG$8<=J13)*L13^AG$8)) -> 0 | AH13: =IF(AH$8<N_st,(N_st-AH$8)/N_st,0)*(1-(1-(AH$8<=I13)*K13^AH$8)*(1-(AH$8<=J13)*L13^AH$8)) -> 0
A14: EPS_SC | B14: EPS_SC-1 | C14: 2 | D14: 0 | E14: 1 | F14: =(1/2_시험자료!$D$21)*2_시험자료!$F$21 -> 0.041666667 | G14: =2_시험자료!G7 -> 481 | H14: =IF(E14=1,1000000000,texp2_s) -> 1000000000 | I14: =FLOOR(MIN(t_fs_s,H14)/G14,1) -> 1 | J14: =IF(C14=1,FLOOR(t_fs_s/tau_L_s,1),0) -> 0 | K14: =IF(D14=1,1-p_cb,1) -> 1 | L14: =IF(C14=1,p_L,0) -> 0 | M14: =SUMPRODUCT(w_ie2,1-(1-(j_row<=I14)*K14^j_row)*(1-(j_row<=J14)*L14^j_row)) -> 1 | N14: =occ_st*SUMPRODUCT(w_ie2,(j_row<=I14)*K14^j_row*(j_row<=J14)*L14^j_row*(((j_row*G14<rset_s)+(j_row*tau_L_s<rset_s))>0)+(j_row<=I14)*K14^j_row*(1-(j_row<=J14)*L14^j_row)*(j_row*G14<rset_s)+(1-(j_row<=I14)*K14^j_row)*(j_row<=J14)*L14^j_row*(j_row*tau_L_s<rset_s)) -> 5 | O14: =IF(O$8<N_st,1,0)*(1-(1-(O$8<=I14)*K14^O$8)*(1-(O$8<=J14)*L14^O$8)) -> 1 | P14: =IF(P$8<N_st,1,0)*(1-(1-(P$8<=I14)*K14^P$8)*(1-(P$8<=J14)*L14^P$8)) -> 0 | Q14: =IF(Q$8<N_st,1,0)*(1-(1-(Q$8<=I14)*K14^Q$8)*(1-(Q$8<=J14)*L14^Q$8)) -> 0 | R14: =IF(R$8<N_st,1,0)*(1-(1-(R$8<=I14)*K14^R$8)*(1-(R$8<=J14)*L14^R$8)) -> 0 | S14: =IF(S$8<N_st,1,0)*(1-(1-(S$8<=I14)*K14^S$8)*(1-(S$8<=J14)*L14^S$8)) -> 0 | T14: =IF(T$8<N_st,1,0)*(1-(1-(T$8<=I14)*K14^T$8)*(1-(T$8<=J14)*L14^T$8)) -> 0 | U14: =IF(U$8<N_st,1,0)*(1-(1-(U$8<=I14)*K14^U$8)*(1-(U$8<=J14)*L14^U$8)) -> 0 | V14: =IF(V$8<N_st,1,0)*(1-(1-(V$8<=I14)*K14^V$8)*(1-(V$8<=J14)*L14^V$8)) -> 0 | W14: =IF(W$8<N_st,1,0)*(1-(1-(W$8<=I14)*K14^W$8)*(1-(W$8<=J14)*L14^W$8)) -> 0 | X14: =IF(X$8<N_st,1,0)*(1-(1-(X$8<=I14)*K14^X$8)*(1-(X$8<=J14)*L14^X$8)) -> 0 | Y14: =IF(Y$8<N_st,1,0)*(1-(1-(Y$8<=I14)*K14^Y$8)*(1-(Y$8<=J14)*L14^Y$8)) -> 0 | Z14: =IF(Z$8<N_st,1,0)*(1-(1-(Z$8<=I14)*K14^Z$8)*(1-(Z$8<=J14)*L14^Z$8)) -> 0 | AA14: =IF(AA$8<N_st,1,0)*(1-(1-(AA$8<=I14)*K14^AA$8)*(1-(AA$8<=J14)*L14^AA$8)) -> 0 | AB14: =IF(AB$8<N_st,1,0)*(1-(1-(AB$8<=I14)*K14^AB$8)*(1-(AB$8<=J14)*L14^AB$8)) -> 0 | AC14: =IF(AC$8<N_st,1,0)*(1-(1-(AC$8<=I14)*K14^AC$8)*(1-(AC$8<=J14)*L14^AC$8)) -> 0 | AD14: =IF(AD$8<N_st,1,0)*(1-(1-(AD$8<=I14)*K14^AD$8)*(1-(AD$8<=J14)*L14^AD$8)) -> 0 | AE14: =IF(AE$8<N_st,1,0)*(1-(1-(AE$8<=I14)*K14^AE$8)*(1-(AE$8<=J14)*L14^AE$8)) -> 0 | AF14: =IF(AF$8<N_st,1,0)*(1-(1-(AF$8<=I14)*K14^AF$8)*(1-(AF$8<=J14)*L14^AF$8)) -> 0 | AG14: =IF(AG$8<N_st,1,0)*(1-(1-(AG$8<=I14)*K14^AG$8)*(1-(AG$8<=J14)*L14^AG$8)) -> 0 | AH14: =IF(AH$8<N_st,1,0)*(1-(1-(AH$8<=I14)*K14^AH$8)*(1-(AH$8<=J14)*L14^AH$8)) -> 0
A15: EPS_SC | B15: EPS_SC-1 | C15: 2 | D15: 0 | E15: 0 | F15: =(1/2_시험자료!$D$21)*(1-2_시험자료!$F$21) -> 0.29166667 | G15: =2_시험자료!G7 -> 481 | H15: =IF(E15=1,1000000000,texp2_s) -> 750 | I15: =FLOOR(MIN(t_fs_s,H15)/G15,1) -> 1 | J15: =IF(C15=1,FLOOR(t_fs_s/tau_L_s,1),0) -> 0 | K15: =IF(D15=1,1-p_cb,1) -> 1 | L15: =IF(C15=1,p_L,0) -> 0 | M15: =SUMPRODUCT(w_ie2,1-(1-(j_row<=I15)*K15^j_row)*(1-(j_row<=J15)*L15^j_row)) -> 1 | N15: =occ_st*SUMPRODUCT(w_ie2,(j_row<=I15)*K15^j_row*(j_row<=J15)*L15^j_row*(((j_row*G15<rset_s)+(j_row*tau_L_s<rset_s))>0)+(j_row<=I15)*K15^j_row*(1-(j_row<=J15)*L15^j_row)*(j_row*G15<rset_s)+(1-(j_row<=I15)*K15^j_row)*(j_row<=J15)*L15^j_row*(j_row*tau_L_s<rset_s)) -> 5 | O15: =IF(O$8<N_st,1,0)*(1-(1-(O$8<=I15)*K15^O$8)*(1-(O$8<=J15)*L15^O$8)) -> 1 | P15: =IF(P$8<N_st,1,0)*(1-(1-(P$8<=I15)*K15^P$8)*(1-(P$8<=J15)*L15^P$8)) -> 0 | Q15: =IF(Q$8<N_st,1,0)*(1-(1-(Q$8<=I15)*K15^Q$8)*(1-(Q$8<=J15)*L15^Q$8)) -> 0 | R15: =IF(R$8<N_st,1,0)*(1-(1-(R$8<=I15)*K15^R$8)*(1-(R$8<=J15)*L15^R$8)) -> 0 | S15: =IF(S$8<N_st,1,0)*(1-(1-(S$8<=I15)*K15^S$8)*(1-(S$8<=J15)*L15^S$8)) -> 0 | T15: =IF(T$8<N_st,1,0)*(1-(1-(T$8<=I15)*K15^T$8)*(1-(T$8<=J15)*L15^T$8)) -> 0 | U15: =IF(U$8<N_st,1,0)*(1-(1-(U$8<=I15)*K15^U$8)*(1-(U$8<=J15)*L15^U$8)) -> 0 | V15: =IF(V$8<N_st,1,0)*(1-(1-(V$8<=I15)*K15^V$8)*(1-(V$8<=J15)*L15^V$8)) -> 0 | W15: =IF(W$8<N_st,1,0)*(1-(1-(W$8<=I15)*K15^W$8)*(1-(W$8<=J15)*L15^W$8)) -> 0 | X15: =IF(X$8<N_st,1,0)*(1-(1-(X$8<=I15)*K15^X$8)*(1-(X$8<=J15)*L15^X$8)) -> 0 | Y15: =IF(Y$8<N_st,1,0)*(1-(1-(Y$8<=I15)*K15^Y$8)*(1-(Y$8<=J15)*L15^Y$8)) -> 0 | Z15: =IF(Z$8<N_st,1,0)*(1-(1-(Z$8<=I15)*K15^Z$8)*(1-(Z$8<=J15)*L15^Z$8)) -> 0 | AA15: =IF(AA$8<N_st,1,0)*(1-(1-(AA$8<=I15)*K15^AA$8)*(1-(AA$8<=J15)*L15^AA$8)) -> 0 | AB15: =IF(AB$8<N_st,1,0)*(1-(1-(AB$8<=I15)*K15^AB$8)*(1-(AB$8<=J15)*L15^AB$8)) -> 0 | AC15: =IF(AC$8<N_st,1,0)*(1-(1-(AC$8<=I15)*K15^AC$8)*(1-(AC$8<=J15)*L15^AC$8)) -> 0 | AD15: =IF(AD$8<N_st,1,0)*(1-(1-(AD$8<=I15)*K15^AD$8)*(1-(AD$8<=J15)*L15^AD$8)) -> 0 | AE15: =IF(AE$8<N_st,1,0)*(1-(1-(AE$8<=I15)*K15^AE$8)*(1-(AE$8<=J15)*L15^AE$8)) -> 0 | AF15: =IF(AF$8<N_st,1,0)*(1-(1-(AF$8<=I15)*K15^AF$8)*(1-(AF$8<=J15)*L15^AF$8)) -> 0 | AG15: =IF(AG$8<N_st,1,0)*(1-(1-(AG$8<=I15)*K15^AG$8)*(1-(AG$8<=J15)*L15^AG$8)) -> 0 | AH15: =IF(AH$8<N_st,1,0)*(1-(1-(AH$8<=I15)*K15^AH$8)*(1-(AH$8<=J15)*L15^AH$8)) -> 0
A16: EPS_SC | B16: EPS_SC-1 | C16: 2 | D16: 1 | E16: 1 | F16: =(1/2_시험자료!$D$21)*2_시험자료!$F$21 -> 0.041666667 | G16: =2_시험자료!G7 -> 481 | H16: =IF(E16=1,1000000000,texp2_s) -> 1000000000 | I16: =FLOOR(MIN(t_fs_s,H16)/G16,1) -> 1 | J16: =IF(C16=1,FLOOR(t_fs_s/tau_L_s,1),0) -> 0 | K16: =IF(D16=1,1-p_cb,1) -> 0.3 | L16: =IF(C16=1,p_L,0) -> 0 | M16: =SUMPRODUCT(w_ie2,1-(1-(j_row<=I16)*K16^j_row)*(1-(j_row<=J16)*L16^j_row)) -> 0.3 | N16: =occ_st*SUMPRODUCT(w_ie2,(j_row<=I16)*K16^j_row*(j_row<=J16)*L16^j_row*(((j_row*G16<rset_s)+(j_row*tau_L_s<rset_s))>0)+(j_row<=I16)*K16^j_row*(1-(j_row<=J16)*L16^j_row)*(j_row*G16<rset_s)+(1-(j_row<=I16)*K16^j_row)*(j_row<=J16)*L16^j_row*(j_row*tau_L_s<rset_s)) -> 1.5 | O16: =IF(O$8<N_st,1,0)*(1-(1-(O$8<=I16)*K16^O$8)*(1-(O$8<=J16)*L16^O$8)) -> 0.3 | P16: =IF(P$8<N_st,1,0)*(1-(1-(P$8<=I16)*K16^P$8)*(1-(P$8<=J16)*L16^P$8)) -> 0 | Q16: =IF(Q$8<N_st,1,0)*(1-(1-(Q$8<=I16)*K16^Q$8)*(1-(Q$8<=J16)*L16^Q$8)) -> 0 | R16: =IF(R$8<N_st,1,0)*(1-(1-(R$8<=I16)*K16^R$8)*(1-(R$8<=J16)*L16^R$8)) -> 0 | S16: =IF(S$8<N_st,1,0)*(1-(1-(S$8<=I16)*K16^S$8)*(1-(S$8<=J16)*L16^S$8)) -> 0 | T16: =IF(T$8<N_st,1,0)*(1-(1-(T$8<=I16)*K16^T$8)*(1-(T$8<=J16)*L16^T$8)) -> 0 | U16: =IF(U$8<N_st,1,0)*(1-(1-(U$8<=I16)*K16^U$8)*(1-(U$8<=J16)*L16^U$8)) -> 0 | V16: =IF(V$8<N_st,1,0)*(1-(1-(V$8<=I16)*K16^V$8)*(1-(V$8<=J16)*L16^V$8)) -> 0 | W16: =IF(W$8<N_st,1,0)*(1-(1-(W$8<=I16)*K16^W$8)*(1-(W$8<=J16)*L16^W$8)) -> 0 | X16: =IF(X$8<N_st,1,0)*(1-(1-(X$8<=I16)*K16^X$8)*(1-(X$8<=J16)*L16^X$8)) -> 0 | Y16: =IF(Y$8<N_st,1,0)*(1-(1-(Y$8<=I16)*K16^Y$8)*(1-(Y$8<=J16)*L16^Y$8)) -> 0 | Z16: =IF(Z$8<N_st,1,0)*(1-(1-(Z$8<=I16)*K16^Z$8)*(1-(Z$8<=J16)*L16^Z$8)) -> 0 | AA16: =IF(AA$8<N_st,1,0)*(1-(1-(AA$8<=I16)*K16^AA$8)*(1-(AA$8<=J16)*L16^AA$8)) -> 0 | AB16: =IF(AB$8<N_st,1,0)*(1-(1-(AB$8<=I16)*K16^AB$8)*(1-(AB$8<=J16)*L16^AB$8)) -> 0 | AC16: =IF(AC$8<N_st,1,0)*(1-(1-(AC$8<=I16)*K16^AC$8)*(1-(AC$8<=J16)*L16^AC$8)) -> 0 | AD16: =IF(AD$8<N_st,1,0)*(1-(1-(AD$8<=I16)*K16^AD$8)*(1-(AD$8<=J16)*L16^AD$8)) -> 0 | AE16: =IF(AE$8<N_st,1,0)*(1-(1-(AE$8<=I16)*K16^AE$8)*(1-(AE$8<=J16)*L16^AE$8)) -> 0 | AF16: =IF(AF$8<N_st,1,0)*(1-(1-(AF$8<=I16)*K16^AF$8)*(1-(AF$8<=J16)*L16^AF$8)) -> 0 | AG16: =IF(AG$8<N_st,1,0)*(1-(1-(AG$8<=I16)*K16^AG$8)*(1-(AG$8<=J16)*L16^AG$8)) -> 0 | AH16: =IF(AH$8<N_st,1,0)*(1-(1-(AH$8<=I16)*K16^AH$8)*(1-(AH$8<=J16)*L16^AH$8)) -> 0
A17: EPS_SC | B17: EPS_SC-1 | C17: 2 | D17: 1 | E17: 0 | F17: =(1/2_시험자료!$D$21)*(1-2_시험자료!$F$21) -> 0.29166667 | G17: =2_시험자료!G7 -> 481 | H17: =IF(E17=1,1000000000,texp2_s) -> 750 | I17: =FLOOR(MIN(t_fs_s,H17)/G17,1) -> 1 | J17: =IF(C17=1,FLOOR(t_fs_s/tau_L_s,1),0) -> 0 | K17: =IF(D17=1,1-p_cb,1) -> 0.3 | L17: =IF(C17=1,p_L,0) -> 0 | M17: =SUMPRODUCT(w_ie2,1-(1-(j_row<=I17)*K17^j_row)*(1-(j_row<=J17)*L17^j_row)) -> 0.3 | N17: =occ_st*SUMPRODUCT(w_ie2,(j_row<=I17)*K17^j_row*(j_row<=J17)*L17^j_row*(((j_row*G17<rset_s)+(j_row*tau_L_s<rset_s))>0)+(j_row<=I17)*K17^j_row*(1-(j_row<=J17)*L17^j_row)*(j_row*G17<rset_s)+(1-(j_row<=I17)*K17^j_row)*(j_row<=J17)*L17^j_row*(j_row*tau_L_s<rset_s)) -> 1.5 | O17: =IF(O$8<N_st,1,0)*(1-(1-(O$8<=I17)*K17^O$8)*(1-(O$8<=J17)*L17^O$8)) -> 0.3 | P17: =IF(P$8<N_st,1,0)*(1-(1-(P$8<=I17)*K17^P$8)*(1-(P$8<=J17)*L17^P$8)) -> 0 | Q17: =IF(Q$8<N_st,1,0)*(1-(1-(Q$8<=I17)*K17^Q$8)*(1-(Q$8<=J17)*L17^Q$8)) -> 0 | R17: =IF(R$8<N_st,1,0)*(1-(1-(R$8<=I17)*K17^R$8)*(1-(R$8<=J17)*L17^R$8)) -> 0 | S17: =IF(S$8<N_st,1,0)*(1-(1-(S$8<=I17)*K17^S$8)*(1-(S$8<=J17)*L17^S$8)) -> 0 | T17: =IF(T$8<N_st,1,0)*(1-(1-(T$8<=I17)*K17^T$8)*(1-(T$8<=J17)*L17^T$8)) -> 0 | U17: =IF(U$8<N_st,1,0)*(1-(1-(U$8<=I17)*K17^U$8)*(1-(U$8<=J17)*L17^U$8)) -> 0 | V17: =IF(V$8<N_st,1,0)*(1-(1-(V$8<=I17)*K17^V$8)*(1-(V$8<=J17)*L17^V$8)) -> 0 | W17: =IF(W$8<N_st,1,0)*(1-(1-(W$8<=I17)*K17^W$8)*(1-(W$8<=J17)*L17^W$8)) -> 0 | X17: =IF(X$8<N_st,1,0)*(1-(1-(X$8<=I17)*K17^X$8)*(1-(X$8<=J17)*L17^X$8)) -> 0 | Y17: =IF(Y$8<N_st,1,0)*(1-(1-(Y$8<=I17)*K17^Y$8)*(1-(Y$8<=J17)*L17^Y$8)) -> 0 | Z17: =IF(Z$8<N_st,1,0)*(1-(1-(Z$8<=I17)*K17^Z$8)*(1-(Z$8<=J17)*L17^Z$8)) -> 0 | AA17: =IF(AA$8<N_st,1,0)*(1-(1-(AA$8<=I17)*K17^AA$8)*(1-(AA$8<=J17)*L17^AA$8)) -> 0 | AB17: =IF(AB$8<N_st,1,0)*(1-(1-(AB$8<=I17)*K17^AB$8)*(1-(AB$8<=J17)*L17^AB$8)) -> 0 | AC17: =IF(AC$8<N_st,1,0)*(1-(1-(AC$8<=I17)*K17^AC$8)*(1-(AC$8<=J17)*L17^AC$8)) -> 0 | AD17: =IF(AD$8<N_st,1,0)*(1-(1-(AD$8<=I17)*K17^AD$8)*(1-(AD$8<=J17)*L17^AD$8)) -> 0 | AE17: =IF(AE$8<N_st,1,0)*(1-(1-(AE$8<=I17)*K17^AE$8)*(1-(AE$8<=J17)*L17^AE$8)) -> 0 | AF17: =IF(AF$8<N_st,1,0)*(1-(1-(AF$8<=I17)*K17^AF$8)*(1-(AF$8<=J17)*L17^AF$8)) -> 0 | AG17: =IF(AG$8<N_st,1,0)*(1-(1-(AG$8<=I17)*K17^AG$8)*(1-(AG$8<=J17)*L17^AG$8)) -> 0 | AH17: =IF(AH$8<N_st,1,0)*(1-(1-(AH$8<=I17)*K17^AH$8)*(1-(AH$8<=J17)*L17^AH$8)) -> 0
A18: EPS_SC | B18: EPS_SC-2 | C18: 1 | D18: 0 | E18: 1 | F18: =(1/2_시험자료!$D$21)*2_시험자료!$F$21 -> 0.041666667 | G18: =2_시험자료!G8 -> 1000000000 | H18: =IF(E18=1,1000000000,texp1_s) -> 1000000000 | I18: =FLOOR(MIN(t_fs_s,H18)/G18,1) -> 0 | J18: =IF(C18=1,FLOOR(t_fs_s/tau_L_s,1),0) -> 1 | K18: =IF(D18=1,1-p_cb,1) -> 1 | L18: =IF(C18=1,p_L,0) -> 0.15 | M18: =SUMPRODUCT(w_ie1,1-(1-(j_row<=I18)*K18^j_row)*(1-(j_row<=J18)*L18^j_row)) -> 0.14 | N18: =occ_st*SUMPRODUCT(w_ie1,(j_row<=I18)*K18^j_row*(j_row<=J18)*L18^j_row*(((j_row*G18<rset_s)+(j_row*tau_L_s<rset_s))>0)+(j_row<=I18)*K18^j_row*(1-(j_row<=J18)*L18^j_row)*(j_row*G18<rset_s)+(1-(j_row<=I18)*K18^j_row)*(j_row<=J18)*L18^j_row*(j_row*tau_L_s<rset_s)) -> 0.7 | O18: =IF(O$8<N_st,(N_st-O$8)/N_st,0)*(1-(1-(O$8<=I18)*K18^O$8)*(1-(O$8<=J18)*L18^O$8)) -> 0.14 | P18: =IF(P$8<N_st,(N_st-P$8)/N_st,0)*(1-(1-(P$8<=I18)*K18^P$8)*(1-(P$8<=J18)*L18^P$8)) -> 0 | Q18: =IF(Q$8<N_st,(N_st-Q$8)/N_st,0)*(1-(1-(Q$8<=I18)*K18^Q$8)*(1-(Q$8<=J18)*L18^Q$8)) -> 0 | R18: =IF(R$8<N_st,(N_st-R$8)/N_st,0)*(1-(1-(R$8<=I18)*K18^R$8)*(1-(R$8<=J18)*L18^R$8)) -> 0 | S18: =IF(S$8<N_st,(N_st-S$8)/N_st,0)*(1-(1-(S$8<=I18)*K18^S$8)*(1-(S$8<=J18)*L18^S$8)) -> 0 | T18: =IF(T$8<N_st,(N_st-T$8)/N_st,0)*(1-(1-(T$8<=I18)*K18^T$8)*(1-(T$8<=J18)*L18^T$8)) -> 0 | U18: =IF(U$8<N_st,(N_st-U$8)/N_st,0)*(1-(1-(U$8<=I18)*K18^U$8)*(1-(U$8<=J18)*L18^U$8)) -> 0 | V18: =IF(V$8<N_st,(N_st-V$8)/N_st,0)*(1-(1-(V$8<=I18)*K18^V$8)*(1-(V$8<=J18)*L18^V$8)) -> 0 | W18: =IF(W$8<N_st,(N_st-W$8)/N_st,0)*(1-(1-(W$8<=I18)*K18^W$8)*(1-(W$8<=J18)*L18^W$8)) -> 0 | X18: =IF(X$8<N_st,(N_st-X$8)/N_st,0)*(1-(1-(X$8<=I18)*K18^X$8)*(1-(X$8<=J18)*L18^X$8)) -> 0 | Y18: =IF(Y$8<N_st,(N_st-Y$8)/N_st,0)*(1-(1-(Y$8<=I18)*K18^Y$8)*(1-(Y$8<=J18)*L18^Y$8)) -> 0 | Z18: =IF(Z$8<N_st,(N_st-Z$8)/N_st,0)*(1-(1-(Z$8<=I18)*K18^Z$8)*(1-(Z$8<=J18)*L18^Z$8)) -> 0 | AA18: =IF(AA$8<N_st,(N_st-AA$8)/N_st,0)*(1-(1-(AA$8<=I18)*K18^AA$8)*(1-(AA$8<=J18)*L18^AA$8)) -> 0 | AB18: =IF(AB$8<N_st,(N_st-AB$8)/N_st,0)*(1-(1-(AB$8<=I18)*K18^AB$8)*(1-(AB$8<=J18)*L18^AB$8)) -> 0 | AC18: =IF(AC$8<N_st,(N_st-AC$8)/N_st,0)*(1-(1-(AC$8<=I18)*K18^AC$8)*(1-(AC$8<=J18)*L18^AC$8)) -> 0 | AD18: =IF(AD$8<N_st,(N_st-AD$8)/N_st,0)*(1-(1-(AD$8<=I18)*K18^AD$8)*(1-(AD$8<=J18)*L18^AD$8)) -> 0 | AE18: =IF(AE$8<N_st,(N_st-AE$8)/N_st,0)*(1-(1-(AE$8<=I18)*K18^AE$8)*(1-(AE$8<=J18)*L18^AE$8)) -> 0 | AF18: =IF(AF$8<N_st,(N_st-AF$8)/N_st,0)*(1-(1-(AF$8<=I18)*K18^AF$8)*(1-(AF$8<=J18)*L18^AF$8)) -> 0 | AG18: =IF(AG$8<N_st,(N_st-AG$8)/N_st,0)*(1-(1-(AG$8<=I18)*K18^AG$8)*(1-(AG$8<=J18)*L18^AG$8)) -> 0 | AH18: =IF(AH$8<N_st,(N_st-AH$8)/N_st,0)*(1-(1-(AH$8<=I18)*K18^AH$8)*(1-(AH$8<=J18)*L18^AH$8)) -> 0
A19: EPS_SC | B19: EPS_SC-2 | C19: 1 | D19: 0 | E19: 0 | F19: =(1/2_시험자료!$D$21)*(1-2_시험자료!$F$21) -> 0.29166667 | G19: =2_시험자료!G8 -> 1000000000 | H19: =IF(E19=1,1000000000,texp1_s) -> 1200 | I19: =FLOOR(MIN(t_fs_s,H19)/G19,1) -> 0 | J19: =IF(C19=1,FLOOR(t_fs_s/tau_L_s,1),0) -> 1 | K19: =IF(D19=1,1-p_cb,1) -> 1 | L19: =IF(C19=1,p_L,0) -> 0.15 | M19: =SUMPRODUCT(w_ie1,1-(1-(j_row<=I19)*K19^j_row)*(1-(j_row<=J19)*L19^j_row)) -> 0.14 | N19: =occ_st*SUMPRODUCT(w_ie1,(j_row<=I19)*K19^j_row*(j_row<=J19)*L19^j_row*(((j_row*G19<rset_s)+(j_row*tau_L_s<rset_s))>0)+(j_row<=I19)*K19^j_row*(1-(j_row<=J19)*L19^j_row)*(j_row*G19<rset_s)+(1-(j_row<=I19)*K19^j_row)*(j_row<=J19)*L19^j_row*(j_row*tau_L_s<rset_s)) -> 0.7 | O19: =IF(O$8<N_st,(N_st-O$8)/N_st,0)*(1-(1-(O$8<=I19)*K19^O$8)*(1-(O$8<=J19)*L19^O$8)) -> 0.14 | P19: =IF(P$8<N_st,(N_st-P$8)/N_st,0)*(1-(1-(P$8<=I19)*K19^P$8)*(1-(P$8<=J19)*L19^P$8)) -> 0 | Q19: =IF(Q$8<N_st,(N_st-Q$8)/N_st,0)*(1-(1-(Q$8<=I19)*K19^Q$8)*(1-(Q$8<=J19)*L19^Q$8)) -> 0 | R19: =IF(R$8<N_st,(N_st-R$8)/N_st,0)*(1-(1-(R$8<=I19)*K19^R$8)*(1-(R$8<=J19)*L19^R$8)) -> 0 | S19: =IF(S$8<N_st,(N_st-S$8)/N_st,0)*(1-(1-(S$8<=I19)*K19^S$8)*(1-(S$8<=J19)*L19^S$8)) -> 0 | T19: =IF(T$8<N_st,(N_st-T$8)/N_st,0)*(1-(1-(T$8<=I19)*K19^T$8)*(1-(T$8<=J19)*L19^T$8)) -> 0 | U19: =IF(U$8<N_st,(N_st-U$8)/N_st,0)*(1-(1-(U$8<=I19)*K19^U$8)*(1-(U$8<=J19)*L19^U$8)) -> 0 | V19: =IF(V$8<N_st,(N_st-V$8)/N_st,0)*(1-(1-(V$8<=I19)*K19^V$8)*(1-(V$8<=J19)*L19^V$8)) -> 0 | W19: =IF(W$8<N_st,(N_st-W$8)/N_st,0)*(1-(1-(W$8<=I19)*K19^W$8)*(1-(W$8<=J19)*L19^W$8)) -> 0 | X19: =IF(X$8<N_st,(N_st-X$8)/N_st,0)*(1-(1-(X$8<=I19)*K19^X$8)*(1-(X$8<=J19)*L19^X$8)) -> 0 | Y19: =IF(Y$8<N_st,(N_st-Y$8)/N_st,0)*(1-(1-(Y$8<=I19)*K19^Y$8)*(1-(Y$8<=J19)*L19^Y$8)) -> 0 | Z19: =IF(Z$8<N_st,(N_st-Z$8)/N_st,0)*(1-(1-(Z$8<=I19)*K19^Z$8)*(1-(Z$8<=J19)*L19^Z$8)) -> 0 | AA19: =IF(AA$8<N_st,(N_st-AA$8)/N_st,0)*(1-(1-(AA$8<=I19)*K19^AA$8)*(1-(AA$8<=J19)*L19^AA$8)) -> 0 | AB19: =IF(AB$8<N_st,(N_st-AB$8)/N_st,0)*(1-(1-(AB$8<=I19)*K19^AB$8)*(1-(AB$8<=J19)*L19^AB$8)) -> 0 | AC19: =IF(AC$8<N_st,(N_st-AC$8)/N_st,0)*(1-(1-(AC$8<=I19)*K19^AC$8)*(1-(AC$8<=J19)*L19^AC$8)) -> 0 | AD19: =IF(AD$8<N_st,(N_st-AD$8)/N_st,0)*(1-(1-(AD$8<=I19)*K19^AD$8)*(1-(AD$8<=J19)*L19^AD$8)) -> 0 | AE19: =IF(AE$8<N_st,(N_st-AE$8)/N_st,0)*(1-(1-(AE$8<=I19)*K19^AE$8)*(1-(AE$8<=J19)*L19^AE$8)) -> 0 | AF19: =IF(AF$8<N_st,(N_st-AF$8)/N_st,0)*(1-(1-(AF$8<=I19)*K19^AF$8)*(1-(AF$8<=J19)*L19^AF$8)) -> 0 | AG19: =IF(AG$8<N_st,(N_st-AG$8)/N_st,0)*(1-(1-(AG$8<=I19)*K19^AG$8)*(1-(AG$8<=J19)*L19^AG$8)) -> 0 | AH19: =IF(AH$8<N_st,(N_st-AH$8)/N_st,0)*(1-(1-(AH$8<=I19)*K19^AH$8)*(1-(AH$8<=J19)*L19^AH$8)) -> 0
A20: EPS_SC | B20: EPS_SC-2 | C20: 1 | D20: 1 | E20: 1 | F20: =(1/2_시험자료!$D$21)*2_시험자료!$F$21 -> 0.041666667 | G20: =2_시험자료!G8 -> 1000000000 | H20: =IF(E20=1,1000000000,texp1_s) -> 1000000000 | I20: =FLOOR(MIN(t_fs_s,H20)/G20,1) -> 0 | J20: =IF(C20=1,FLOOR(t_fs_s/tau_L_s,1),0) -> 1 | K20: =IF(D20=1,1-p_cb,1) -> 0.3 | L20: =IF(C20=1,p_L,0) -> 0.15 | M20: =SUMPRODUCT(w_ie1,1-(1-(j_row<=I20)*K20^j_row)*(1-(j_row<=J20)*L20^j_row)) -> 0.14 | N20: =occ_st*SUMPRODUCT(w_ie1,(j_row<=I20)*K20^j_row*(j_row<=J20)*L20^j_row*(((j_row*G20<rset_s)+(j_row*tau_L_s<rset_s))>0)+(j_row<=I20)*K20^j_row*(1-(j_row<=J20)*L20^j_row)*(j_row*G20<rset_s)+(1-(j_row<=I20)*K20^j_row)*(j_row<=J20)*L20^j_row*(j_row*tau_L_s<rset_s)) -> 0.7 | O20: =IF(O$8<N_st,(N_st-O$8)/N_st,0)*(1-(1-(O$8<=I20)*K20^O$8)*(1-(O$8<=J20)*L20^O$8)) -> 0.14 | P20: =IF(P$8<N_st,(N_st-P$8)/N_st,0)*(1-(1-(P$8<=I20)*K20^P$8)*(1-(P$8<=J20)*L20^P$8)) -> 0 | Q20: =IF(Q$8<N_st,(N_st-Q$8)/N_st,0)*(1-(1-(Q$8<=I20)*K20^Q$8)*(1-(Q$8<=J20)*L20^Q$8)) -> 0 | R20: =IF(R$8<N_st,(N_st-R$8)/N_st,0)*(1-(1-(R$8<=I20)*K20^R$8)*(1-(R$8<=J20)*L20^R$8)) -> 0 | S20: =IF(S$8<N_st,(N_st-S$8)/N_st,0)*(1-(1-(S$8<=I20)*K20^S$8)*(1-(S$8<=J20)*L20^S$8)) -> 0 | T20: =IF(T$8<N_st,(N_st-T$8)/N_st,0)*(1-(1-(T$8<=I20)*K20^T$8)*(1-(T$8<=J20)*L20^T$8)) -> 0 | U20: =IF(U$8<N_st,(N_st-U$8)/N_st,0)*(1-(1-(U$8<=I20)*K20^U$8)*(1-(U$8<=J20)*L20^U$8)) -> 0 | V20: =IF(V$8<N_st,(N_st-V$8)/N_st,0)*(1-(1-(V$8<=I20)*K20^V$8)*(1-(V$8<=J20)*L20^V$8)) -> 0 | W20: =IF(W$8<N_st,(N_st-W$8)/N_st,0)*(1-(1-(W$8<=I20)*K20^W$8)*(1-(W$8<=J20)*L20^W$8)) -> 0 | X20: =IF(X$8<N_st,(N_st-X$8)/N_st,0)*(1-(1-(X$8<=I20)*K20^X$8)*(1-(X$8<=J20)*L20^X$8)) -> 0 | Y20: =IF(Y$8<N_st,(N_st-Y$8)/N_st,0)*(1-(1-(Y$8<=I20)*K20^Y$8)*(1-(Y$8<=J20)*L20^Y$8)) -> 0 | Z20: =IF(Z$8<N_st,(N_st-Z$8)/N_st,0)*(1-(1-(Z$8<=I20)*K20^Z$8)*(1-(Z$8<=J20)*L20^Z$8)) -> 0 | AA20: =IF(AA$8<N_st,(N_st-AA$8)/N_st,0)*(1-(1-(AA$8<=I20)*K20^AA$8)*(1-(AA$8<=J20)*L20^AA$8)) -> 0 | AB20: =IF(AB$8<N_st,(N_st-AB$8)/N_st,0)*(1-(1-(AB$8<=I20)*K20^AB$8)*(1-(AB$8<=J20)*L20^AB$8)) -> 0 | AC20: =IF(AC$8<N_st,(N_st-AC$8)/N_st,0)*(1-(1-(AC$8<=I20)*K20^AC$8)*(1-(AC$8<=J20)*L20^AC$8)) -> 0 | AD20: =IF(AD$8<N_st,(N_st-AD$8)/N_st,0)*(1-(1-(AD$8<=I20)*K20^AD$8)*(1-(AD$8<=J20)*L20^AD$8)) -> 0 | AE20: =IF(AE$8<N_st,(N_st-AE$8)/N_st,0)*(1-(1-(AE$8<=I20)*K20^AE$8)*(1-(AE$8<=J20)*L20^AE$8)) -> 0 | AF20: =IF(AF$8<N_st,(N_st-AF$8)/N_st,0)*(1-(1-(AF$8<=I20)*K20^AF$8)*(1-(AF$8<=J20)*L20^AF$8)) -> 0 | AG20: =IF(AG$8<N_st,(N_st-AG$8)/N_st,0)*(1-(1-(AG$8<=I20)*K20^AG$8)*(1-(AG$8<=J20)*L20^AG$8)) -> 0 | AH20: =IF(AH$8<N_st,(N_st-AH$8)/N_st,0)*(1-(1-(AH$8<=I20)*K20^AH$8)*(1-(AH$8<=J20)*L20^AH$8)) -> 0
A21: EPS_SC | B21: EPS_SC-2 | C21: 1 | D21: 1 | E21: 0 | F21: =(1/2_시험자료!$D$21)*(1-2_시험자료!$F$21) -> 0.29166667 | G21: =2_시험자료!G8 -> 1000000000 | H21: =IF(E21=1,1000000000,texp1_s) -> 1200 | I21: =FLOOR(MIN(t_fs_s,H21)/G21,1) -> 0 | J21: =IF(C21=1,FLOOR(t_fs_s/tau_L_s,1),0) -> 1 | K21: =IF(D21=1,1-p_cb,1) -> 0.3 | L21: =IF(C21=1,p_L,0) -> 0.15 | M21: =SUMPRODUCT(w_ie1,1-(1-(j_row<=I21)*K21^j_row)*(1-(j_row<=J21)*L21^j_row)) -> 0.14 | N21: =occ_st*SUMPRODUCT(w_ie1,(j_row<=I21)*K21^j_row*(j_row<=J21)*L21^j_row*(((j_row*G21<rset_s)+(j_row*tau_L_s<rset_s))>0)+(j_row<=I21)*K21^j_row*(1-(j_row<=J21)*L21^j_row)*(j_row*G21<rset_s)+(1-(j_row<=I21)*K21^j_row)*(j_row<=J21)*L21^j_row*(j_row*tau_L_s<rset_s)) -> 0.7 | O21: =IF(O$8<N_st,(N_st-O$8)/N_st,0)*(1-(1-(O$8<=I21)*K21^O$8)*(1-(O$8<=J21)*L21^O$8)) -> 0.14 | P21: =IF(P$8<N_st,(N_st-P$8)/N_st,0)*(1-(1-(P$8<=I21)*K21^P$8)*(1-(P$8<=J21)*L21^P$8)) -> 0 | Q21: =IF(Q$8<N_st,(N_st-Q$8)/N_st,0)*(1-(1-(Q$8<=I21)*K21^Q$8)*(1-(Q$8<=J21)*L21^Q$8)) -> 0 | R21: =IF(R$8<N_st,(N_st-R$8)/N_st,0)*(1-(1-(R$8<=I21)*K21^R$8)*(1-(R$8<=J21)*L21^R$8)) -> 0 | S21: =IF(S$8<N_st,(N_st-S$8)/N_st,0)*(1-(1-(S$8<=I21)*K21^S$8)*(1-(S$8<=J21)*L21^S$8)) -> 0 | T21: =IF(T$8<N_st,(N_st-T$8)/N_st,0)*(1-(1-(T$8<=I21)*K21^T$8)*(1-(T$8<=J21)*L21^T$8)) -> 0 | U21: =IF(U$8<N_st,(N_st-U$8)/N_st,0)*(1-(1-(U$8<=I21)*K21^U$8)*(1-(U$8<=J21)*L21^U$8)) -> 0 | V21: =IF(V$8<N_st,(N_st-V$8)/N_st,0)*(1-(1-(V$8<=I21)*K21^V$8)*(1-(V$8<=J21)*L21^V$8)) -> 0 | W21: =IF(W$8<N_st,(N_st-W$8)/N_st,0)*(1-(1-(W$8<=I21)*K21^W$8)*(1-(W$8<=J21)*L21^W$8)) -> 0 | X21: =IF(X$8<N_st,(N_st-X$8)/N_st,0)*(1-(1-(X$8<=I21)*K21^X$8)*(1-(X$8<=J21)*L21^X$8)) -> 0 | Y21: =IF(Y$8<N_st,(N_st-Y$8)/N_st,0)*(1-(1-(Y$8<=I21)*K21^Y$8)*(1-(Y$8<=J21)*L21^Y$8)) -> 0 | Z21: =IF(Z$8<N_st,(N_st-Z$8)/N_st,0)*(1-(1-(Z$8<=I21)*K21^Z$8)*(1-(Z$8<=J21)*L21^Z$8)) -> 0 | AA21: =IF(AA$8<N_st,(N_st-AA$8)/N_st,0)*(1-(1-(AA$8<=I21)*K21^AA$8)*(1-(AA$8<=J21)*L21^AA$8)) -> 0 | AB21: =IF(AB$8<N_st,(N_st-AB$8)/N_st,0)*(1-(1-(AB$8<=I21)*K21^AB$8)*(1-(AB$8<=J21)*L21^AB$8)) -> 0 | AC21: =IF(AC$8<N_st,(N_st-AC$8)/N_st,0)*(1-(1-(AC$8<=I21)*K21^AC$8)*(1-(AC$8<=J21)*L21^AC$8)) -> 0 | AD21: =IF(AD$8<N_st,(N_st-AD$8)/N_st,0)*(1-(1-(AD$8<=I21)*K21^AD$8)*(1-(AD$8<=J21)*L21^AD$8)) -> 0 | AE21: =IF(AE$8<N_st,(N_st-AE$8)/N_st,0)*(1-(1-(AE$8<=I21)*K21^AE$8)*(1-(AE$8<=J21)*L21^AE$8)) -> 0 | AF21: =IF(AF$8<N_st,(N_st-AF$8)/N_st,0)*(1-(1-(AF$8<=I21)*K21^AF$8)*(1-(AF$8<=J21)*L21^AF$8)) -> 0 | AG21: =IF(AG$8<N_st,(N_st-AG$8)/N_st,0)*(1-(1-(AG$8<=I21)*K21^AG$8)*(1-(AG$8<=J21)*L21^AG$8)) -> 0 | AH21: =IF(AH$8<N_st,(N_st-AH$8)/N_st,0)*(1-(1-(AH$8<=I21)*K21^AH$8)*(1-(AH$8<=J21)*L21^AH$8)) -> 0
A22: EPS_SC | B22: EPS_SC-2 | C22: 2 | D22: 0 | E22: 1 | F22: =(1/2_시험자료!$D$21)*2_시험자료!$F$21 -> 0.041666667 | G22: =2_시험자료!G8 -> 1000000000 | H22: =IF(E22=1,1000000000,texp2_s) -> 1000000000 | I22: =FLOOR(MIN(t_fs_s,H22)/G22,1) -> 0 | J22: =IF(C22=1,FLOOR(t_fs_s/tau_L_s,1),0) -> 0 | K22: =IF(D22=1,1-p_cb,1) -> 1 | L22: =IF(C22=1,p_L,0) -> 0 | M22: =SUMPRODUCT(w_ie2,1-(1-(j_row<=I22)*K22^j_row)*(1-(j_row<=J22)*L22^j_row)) -> 0 | N22: =occ_st*SUMPRODUCT(w_ie2,(j_row<=I22)*K22^j_row*(j_row<=J22)*L22^j_row*(((j_row*G22<rset_s)+(j_row*tau_L_s<rset_s))>0)+(j_row<=I22)*K22^j_row*(1-(j_row<=J22)*L22^j_row)*(j_row*G22<rset_s)+(1-(j_row<=I22)*K22^j_row)*(j_row<=J22)*L22^j_row*(j_row*tau_L_s<rset_s)) -> 0 | O22: =IF(O$8<N_st,1,0)*(1-(1-(O$8<=I22)*K22^O$8)*(1-(O$8<=J22)*L22^O$8)) -> 0 | P22: =IF(P$8<N_st,1,0)*(1-(1-(P$8<=I22)*K22^P$8)*(1-(P$8<=J22)*L22^P$8)) -> 0 | Q22: =IF(Q$8<N_st,1,0)*(1-(1-(Q$8<=I22)*K22^Q$8)*(1-(Q$8<=J22)*L22^Q$8)) -> 0 | R22: =IF(R$8<N_st,1,0)*(1-(1-(R$8<=I22)*K22^R$8)*(1-(R$8<=J22)*L22^R$8)) -> 0 | S22: =IF(S$8<N_st,1,0)*(1-(1-(S$8<=I22)*K22^S$8)*(1-(S$8<=J22)*L22^S$8)) -> 0 | T22: =IF(T$8<N_st,1,0)*(1-(1-(T$8<=I22)*K22^T$8)*(1-(T$8<=J22)*L22^T$8)) -> 0 | U22: =IF(U$8<N_st,1,0)*(1-(1-(U$8<=I22)*K22^U$8)*(1-(U$8<=J22)*L22^U$8)) -> 0 | V22: =IF(V$8<N_st,1,0)*(1-(1-(V$8<=I22)*K22^V$8)*(1-(V$8<=J22)*L22^V$8)) -> 0 | W22: =IF(W$8<N_st,1,0)*(1-(1-(W$8<=I22)*K22^W$8)*(1-(W$8<=J22)*L22^W$8)) -> 0 | X22: =IF(X$8<N_st,1,0)*(1-(1-(X$8<=I22)*K22^X$8)*(1-(X$8<=J22)*L22^X$8)) -> 0 | Y22: =IF(Y$8<N_st,1,0)*(1-(1-(Y$8<=I22)*K22^Y$8)*(1-(Y$8<=J22)*L22^Y$8)) -> 0 | Z22: =IF(Z$8<N_st,1,0)*(1-(1-(Z$8<=I22)*K22^Z$8)*(1-(Z$8<=J22)*L22^Z$8)) -> 0 | AA22: =IF(AA$8<N_st,1,0)*(1-(1-(AA$8<=I22)*K22^AA$8)*(1-(AA$8<=J22)*L22^AA$8)) -> 0 | AB22: =IF(AB$8<N_st,1,0)*(1-(1-(AB$8<=I22)*K22^AB$8)*(1-(AB$8<=J22)*L22^AB$8)) -> 0 | AC22: =IF(AC$8<N_st,1,0)*(1-(1-(AC$8<=I22)*K22^AC$8)*(1-(AC$8<=J22)*L22^AC$8)) -> 0 | AD22: =IF(AD$8<N_st,1,0)*(1-(1-(AD$8<=I22)*K22^AD$8)*(1-(AD$8<=J22)*L22^AD$8)) -> 0 | AE22: =IF(AE$8<N_st,1,0)*(1-(1-(AE$8<=I22)*K22^AE$8)*(1-(AE$8<=J22)*L22^AE$8)) -> 0 | AF22: =IF(AF$8<N_st,1,0)*(1-(1-(AF$8<=I22)*K22^AF$8)*(1-(AF$8<=J22)*L22^AF$8)) -> 0 | AG22: =IF(AG$8<N_st,1,0)*(1-(1-(AG$8<=I22)*K22^AG$8)*(1-(AG$8<=J22)*L22^AG$8)) -> 0 | AH22: =IF(AH$8<N_st,1,0)*(1-(1-(AH$8<=I22)*K22^AH$8)*(1-(AH$8<=J22)*L22^AH$8)) -> 0
A23: EPS_SC | B23: EPS_SC-2 | C23: 2 | D23: 0 | E23: 0 | F23: =(1/2_시험자료!$D$21)*(1-2_시험자료!$F$21) -> 0.29166667 | G23: =2_시험자료!G8 -> 1000000000 | H23: =IF(E23=1,1000000000,texp2_s) -> 750 | I23: =FLOOR(MIN(t_fs_s,H23)/G23,1) -> 0 | J23: =IF(C23=1,FLOOR(t_fs_s/tau_L_s,1),0) -> 0 | K23: =IF(D23=1,1-p_cb,1) -> 1 | L23: =IF(C23=1,p_L,0) -> 0 | M23: =SUMPRODUCT(w_ie2,1-(1-(j_row<=I23)*K23^j_row)*(1-(j_row<=J23)*L23^j_row)) -> 0 | N23: =occ_st*SUMPRODUCT(w_ie2,(j_row<=I23)*K23^j_row*(j_row<=J23)*L23^j_row*(((j_row*G23<rset_s)+(j_row*tau_L_s<rset_s))>0)+(j_row<=I23)*K23^j_row*(1-(j_row<=J23)*L23^j_row)*(j_row*G23<rset_s)+(1-(j_row<=I23)*K23^j_row)*(j_row<=J23)*L23^j_row*(j_row*tau_L_s<rset_s)) -> 0 | O23: =IF(O$8<N_st,1,0)*(1-(1-(O$8<=I23)*K23^O$8)*(1-(O$8<=J23)*L23^O$8)) -> 0 | P23: =IF(P$8<N_st,1,0)*(1-(1-(P$8<=I23)*K23^P$8)*(1-(P$8<=J23)*L23^P$8)) -> 0 | Q23: =IF(Q$8<N_st,1,0)*(1-(1-(Q$8<=I23)*K23^Q$8)*(1-(Q$8<=J23)*L23^Q$8)) -> 0 | R23: =IF(R$8<N_st,1,0)*(1-(1-(R$8<=I23)*K23^R$8)*(1-(R$8<=J23)*L23^R$8)) -> 0 | S23: =IF(S$8<N_st,1,0)*(1-(1-(S$8<=I23)*K23^S$8)*(1-(S$8<=J23)*L23^S$8)) -> 0 | T23: =IF(T$8<N_st,1,0)*(1-(1-(T$8<=I23)*K23^T$8)*(1-(T$8<=J23)*L23^T$8)) -> 0 | U23: =IF(U$8<N_st,1,0)*(1-(1-(U$8<=I23)*K23^U$8)*(1-(U$8<=J23)*L23^U$8)) -> 0 | V23: =IF(V$8<N_st,1,0)*(1-(1-(V$8<=I23)*K23^V$8)*(1-(V$8<=J23)*L23^V$8)) -> 0 | W23: =IF(W$8<N_st,1,0)*(1-(1-(W$8<=I23)*K23^W$8)*(1-(W$8<=J23)*L23^W$8)) -> 0 | X23: =IF(X$8<N_st,1,0)*(1-(1-(X$8<=I23)*K23^X$8)*(1-(X$8<=J23)*L23^X$8)) -> 0 | Y23: =IF(Y$8<N_st,1,0)*(1-(1-(Y$8<=I23)*K23^Y$8)*(1-(Y$8<=J23)*L23^Y$8)) -> 0 | Z23: =IF(Z$8<N_st,1,0)*(1-(1-(Z$8<=I23)*K23^Z$8)*(1-(Z$8<=J23)*L23^Z$8)) -> 0 | AA23: =IF(AA$8<N_st,1,0)*(1-(1-(AA$8<=I23)*K23^AA$8)*(1-(AA$8<=J23)*L23^AA$8)) -> 0 | AB23: =IF(AB$8<N_st,1,0)*(1-(1-(AB$8<=I23)*K23^AB$8)*(1-(AB$8<=J23)*L23^AB$8)) -> 0 | AC23: =IF(AC$8<N_st,1,0)*(1-(1-(AC$8<=I23)*K23^AC$8)*(1-(AC$8<=J23)*L23^AC$8)) -> 0 | AD23: =IF(AD$8<N_st,1,0)*(1-(1-(AD$8<=I23)*K23^AD$8)*(1-(AD$8<=J23)*L23^AD$8)) -> 0 | AE23: =IF(AE$8<N_st,1,0)*(1-(1-(AE$8<=I23)*K23^AE$8)*(1-(AE$8<=J23)*L23^AE$8)) -> 0 | AF23: =IF(AF$8<N_st,1,0)*(1-(1-(AF$8<=I23)*K23^AF$8)*(1-(AF$8<=J23)*L23^AF$8)) -> 0 | AG23: =IF(AG$8<N_st,1,0)*(1-(1-(AG$8<=I23)*K23^AG$8)*(1-(AG$8<=J23)*L23^AG$8)) -> 0 | AH23: =IF(AH$8<N_st,1,0)*(1-(1-(AH$8<=I23)*K23^AH$8)*(1-(AH$8<=J23)*L23^AH$8)) -> 0
A24: EPS_SC | B24: EPS_SC-2 | C24: 2 | D24: 1 | E24: 1 | F24: =(1/2_시험자료!$D$21)*2_시험자료!$F$21 -> 0.041666667 | G24: =2_시험자료!G8 -> 1000000000 | H24: =IF(E24=1,1000000000,texp2_s) -> 1000000000 | I24: =FLOOR(MIN(t_fs_s,H24)/G24,1) -> 0 | J24: =IF(C24=1,FLOOR(t_fs_s/tau_L_s,1),0) -> 0 | K24: =IF(D24=1,1-p_cb,1) -> 0.3 | L24: =IF(C24=1,p_L,0) -> 0 | M24: =SUMPRODUCT(w_ie2,1-(1-(j_row<=I24)*K24^j_row)*(1-(j_row<=J24)*L24^j_row)) -> 0 | N24: =occ_st*SUMPRODUCT(w_ie2,(j_row<=I24)*K24^j_row*(j_row<=J24)*L24^j_row*(((j_row*G24<rset_s)+(j_row*tau_L_s<rset_s))>0)+(j_row<=I24)*K24^j_row*(1-(j_row<=J24)*L24^j_row)*(j_row*G24<rset_s)+(1-(j_row<=I24)*K24^j_row)*(j_row<=J24)*L24^j_row*(j_row*tau_L_s<rset_s)) -> 0 | O24: =IF(O$8<N_st,1,0)*(1-(1-(O$8<=I24)*K24^O$8)*(1-(O$8<=J24)*L24^O$8)) -> 0 | P24: =IF(P$8<N_st,1,0)*(1-(1-(P$8<=I24)*K24^P$8)*(1-(P$8<=J24)*L24^P$8)) -> 0 | Q24: =IF(Q$8<N_st,1,0)*(1-(1-(Q$8<=I24)*K24^Q$8)*(1-(Q$8<=J24)*L24^Q$8)) -> 0 | R24: =IF(R$8<N_st,1,0)*(1-(1-(R$8<=I24)*K24^R$8)*(1-(R$8<=J24)*L24^R$8)) -> 0 | S24: =IF(S$8<N_st,1,0)*(1-(1-(S$8<=I24)*K24^S$8)*(1-(S$8<=J24)*L24^S$8)) -> 0 | T24: =IF(T$8<N_st,1,0)*(1-(1-(T$8<=I24)*K24^T$8)*(1-(T$8<=J24)*L24^T$8)) -> 0 | U24: =IF(U$8<N_st,1,0)*(1-(1-(U$8<=I24)*K24^U$8)*(1-(U$8<=J24)*L24^U$8)) -> 0 | V24: =IF(V$8<N_st,1,0)*(1-(1-(V$8<=I24)*K24^V$8)*(1-(V$8<=J24)*L24^V$8)) -> 0 | W24: =IF(W$8<N_st,1,0)*(1-(1-(W$8<=I24)*K24^W$8)*(1-(W$8<=J24)*L24^W$8)) -> 0 | X24: =IF(X$8<N_st,1,0)*(1-(1-(X$8<=I24)*K24^X$8)*(1-(X$8<=J24)*L24^X$8)) -> 0 | Y24: =IF(Y$8<N_st,1,0)*(1-(1-(Y$8<=I24)*K24^Y$8)*(1-(Y$8<=J24)*L24^Y$8)) -> 0 | Z24: =IF(Z$8<N_st,1,0)*(1-(1-(Z$8<=I24)*K24^Z$8)*(1-(Z$8<=J24)*L24^Z$8)) -> 0 | AA24: =IF(AA$8<N_st,1,0)*(1-(1-(AA$8<=I24)*K24^AA$8)*(1-(AA$8<=J24)*L24^AA$8)) -> 0 | AB24: =IF(AB$8<N_st,1,0)*(1-(1-(AB$8<=I24)*K24^AB$8)*(1-(AB$8<=J24)*L24^AB$8)) -> 0 | AC24: =IF(AC$8<N_st,1,0)*(1-(1-(AC$8<=I24)*K24^AC$8)*(1-(AC$8<=J24)*L24^AC$8)) -> 0 | AD24: =IF(AD$8<N_st,1,0)*(1-(1-(AD$8<=I24)*K24^AD$8)*(1-(AD$8<=J24)*L24^AD$8)) -> 0 | AE24: =IF(AE$8<N_st,1,0)*(1-(1-(AE$8<=I24)*K24^AE$8)*(1-(AE$8<=J24)*L24^AE$8)) -> 0 | AF24: =IF(AF$8<N_st,1,0)*(1-(1-(AF$8<=I24)*K24^AF$8)*(1-(AF$8<=J24)*L24^AF$8)) -> 0 | AG24: =IF(AG$8<N_st,1,0)*(1-(1-(AG$8<=I24)*K24^AG$8)*(1-(AG$8<=J24)*L24^AG$8)) -> 0 | AH24: =IF(AH$8<N_st,1,0)*(1-(1-(AH$8<=I24)*K24^AH$8)*(1-(AH$8<=J24)*L24^AH$8)) -> 0
A25: EPS_SC | B25: EPS_SC-2 | C25: 2 | D25: 1 | E25: 0 | F25: =(1/2_시험자료!$D$21)*(1-2_시험자료!$F$21) -> 0.29166667 | G25: =2_시험자료!G8 -> 1000000000 | H25: =IF(E25=1,1000000000,texp2_s) -> 750 | I25: =FLOOR(MIN(t_fs_s,H25)/G25,1) -> 0 | J25: =IF(C25=1,FLOOR(t_fs_s/tau_L_s,1),0) -> 0 | K25: =IF(D25=1,1-p_cb,1) -> 0.3 | L25: =IF(C25=1,p_L,0) -> 0 | M25: =SUMPRODUCT(w_ie2,1-(1-(j_row<=I25)*K25^j_row)*(1-(j_row<=J25)*L25^j_row)) -> 0 | N25: =occ_st*SUMPRODUCT(w_ie2,(j_row<=I25)*K25^j_row*(j_row<=J25)*L25^j_row*(((j_row*G25<rset_s)+(j_row*tau_L_s<rset_s))>0)+(j_row<=I25)*K25^j_row*(1-(j_row<=J25)*L25^j_row)*(j_row*G25<rset_s)+(1-(j_row<=I25)*K25^j_row)*(j_row<=J25)*L25^j_row*(j_row*tau_L_s<rset_s)) -> 0 | O25: =IF(O$8<N_st,1,0)*(1-(1-(O$8<=I25)*K25^O$8)*(1-(O$8<=J25)*L25^O$8)) -> 0 | P25: =IF(P$8<N_st,1,0)*(1-(1-(P$8<=I25)*K25^P$8)*(1-(P$8<=J25)*L25^P$8)) -> 0 | Q25: =IF(Q$8<N_st,1,0)*(1-(1-(Q$8<=I25)*K25^Q$8)*(1-(Q$8<=J25)*L25^Q$8)) -> 0 | R25: =IF(R$8<N_st,1,0)*(1-(1-(R$8<=I25)*K25^R$8)*(1-(R$8<=J25)*L25^R$8)) -> 0 | S25: =IF(S$8<N_st,1,0)*(1-(1-(S$8<=I25)*K25^S$8)*(1-(S$8<=J25)*L25^S$8)) -> 0 | T25: =IF(T$8<N_st,1,0)*(1-(1-(T$8<=I25)*K25^T$8)*(1-(T$8<=J25)*L25^T$8)) -> 0 | U25: =IF(U$8<N_st,1,0)*(1-(1-(U$8<=I25)*K25^U$8)*(1-(U$8<=J25)*L25^U$8)) -> 0 | V25: =IF(V$8<N_st,1,0)*(1-(1-(V$8<=I25)*K25^V$8)*(1-(V$8<=J25)*L25^V$8)) -> 0 | W25: =IF(W$8<N_st,1,0)*(1-(1-(W$8<=I25)*K25^W$8)*(1-(W$8<=J25)*L25^W$8)) -> 0 | X25: =IF(X$8<N_st,1,0)*(1-(1-(X$8<=I25)*K25^X$8)*(1-(X$8<=J25)*L25^X$8)) -> 0 | Y25: =IF(Y$8<N_st,1,0)*(1-(1-(Y$8<=I25)*K25^Y$8)*(1-(Y$8<=J25)*L25^Y$8)) -> 0 | Z25: =IF(Z$8<N_st,1,0)*(1-(1-(Z$8<=I25)*K25^Z$8)*(1-(Z$8<=J25)*L25^Z$8)) -> 0 | AA25: =IF(AA$8<N_st,1,0)*(1-(1-(AA$8<=I25)*K25^AA$8)*(1-(AA$8<=J25)*L25^AA$8)) -> 0 | AB25: =IF(AB$8<N_st,1,0)*(1-(1-(AB$8<=I25)*K25^AB$8)*(1-(AB$8<=J25)*L25^AB$8)) -> 0 | AC25: =IF(AC$8<N_st,1,0)*(1-(1-(AC$8<=I25)*K25^AC$8)*(1-(AC$8<=J25)*L25^AC$8)) -> 0 | AD25: =IF(AD$8<N_st,1,0)*(1-(1-(AD$8<=I25)*K25^AD$8)*(1-(AD$8<=J25)*L25^AD$8)) -> 0 | AE25: =IF(AE$8<N_st,1,0)*(1-(1-(AE$8<=I25)*K25^AE$8)*(1-(AE$8<=J25)*L25^AE$8)) -> 0 | AF25: =IF(AF$8<N_st,1,0)*(1-(1-(AF$8<=I25)*K25^AF$8)*(1-(AF$8<=J25)*L25^AF$8)) -> 0 | AG25: =IF(AG$8<N_st,1,0)*(1-(1-(AG$8<=I25)*K25^AG$8)*(1-(AG$8<=J25)*L25^AG$8)) -> 0 | AH25: =IF(AH$8<N_st,1,0)*(1-(1-(AH$8<=I25)*K25^AH$8)*(1-(AH$8<=J25)*L25^AH$8)) -> 0
A26: EPS_SC | B26: EPS_SC-3 | C26: 1 | D26: 0 | E26: 1 | F26: =(1/2_시험자료!$D$21)*2_시험자료!$F$21 -> 0.041666667 | G26: =2_시험자료!G9 -> 487.5 | H26: =IF(E26=1,1000000000,texp1_s) -> 1000000000 | I26: =FLOOR(MIN(t_fs_s,H26)/G26,1) -> 1 | J26: =IF(C26=1,FLOOR(t_fs_s/tau_L_s,1),0) -> 1 | K26: =IF(D26=1,1-p_cb,1) -> 1 | L26: =IF(C26=1,p_L,0) -> 0.15 | M26: =SUMPRODUCT(w_ie1,1-(1-(j_row<=I26)*K26^j_row)*(1-(j_row<=J26)*L26^j_row)) -> 0.93333333 | N26: =occ_st*SUMPRODUCT(w_ie1,(j_row<=I26)*K26^j_row*(j_row<=J26)*L26^j_row*(((j_row*G26<rset_s)+(j_row*tau_L_s<rset_s))>0)+(j_row<=I26)*K26^j_row*(1-(j_row<=J26)*L26^j_row)*(j_row*G26<rset_s)+(1-(j_row<=I26)*K26^j_row)*(j_row<=J26)*L26^j_row*(j_row*tau_L_s<rset_s)) -> 4.6666667 | O26: =IF(O$8<N_st,(N_st-O$8)/N_st,0)*(1-(1-(O$8<=I26)*K26^O$8)*(1-(O$8<=J26)*L26^O$8)) -> 0.93333333 | P26: =IF(P$8<N_st,(N_st-P$8)/N_st,0)*(1-(1-(P$8<=I26)*K26^P$8)*(1-(P$8<=J26)*L26^P$8)) -> 0 | Q26: =IF(Q$8<N_st,(N_st-Q$8)/N_st,0)*(1-(1-(Q$8<=I26)*K26^Q$8)*(1-(Q$8<=J26)*L26^Q$8)) -> 0 | R26: =IF(R$8<N_st,(N_st-R$8)/N_st,0)*(1-(1-(R$8<=I26)*K26^R$8)*(1-(R$8<=J26)*L26^R$8)) -> 0 | S26: =IF(S$8<N_st,(N_st-S$8)/N_st,0)*(1-(1-(S$8<=I26)*K26^S$8)*(1-(S$8<=J26)*L26^S$8)) -> 0 | T26: =IF(T$8<N_st,(N_st-T$8)/N_st,0)*(1-(1-(T$8<=I26)*K26^T$8)*(1-(T$8<=J26)*L26^T$8)) -> 0 | U26: =IF(U$8<N_st,(N_st-U$8)/N_st,0)*(1-(1-(U$8<=I26)*K26^U$8)*(1-(U$8<=J26)*L26^U$8)) -> 0 | V26: =IF(V$8<N_st,(N_st-V$8)/N_st,0)*(1-(1-(V$8<=I26)*K26^V$8)*(1-(V$8<=J26)*L26^V$8)) -> 0 | W26: =IF(W$8<N_st,(N_st-W$8)/N_st,0)*(1-(1-(W$8<=I26)*K26^W$8)*(1-(W$8<=J26)*L26^W$8)) -> 0 | X26: =IF(X$8<N_st,(N_st-X$8)/N_st,0)*(1-(1-(X$8<=I26)*K26^X$8)*(1-(X$8<=J26)*L26^X$8)) -> 0 | Y26: =IF(Y$8<N_st,(N_st-Y$8)/N_st,0)*(1-(1-(Y$8<=I26)*K26^Y$8)*(1-(Y$8<=J26)*L26^Y$8)) -> 0 | Z26: =IF(Z$8<N_st,(N_st-Z$8)/N_st,0)*(1-(1-(Z$8<=I26)*K26^Z$8)*(1-(Z$8<=J26)*L26^Z$8)) -> 0 | AA26: =IF(AA$8<N_st,(N_st-AA$8)/N_st,0)*(1-(1-(AA$8<=I26)*K26^AA$8)*(1-(AA$8<=J26)*L26^AA$8)) -> 0 | AB26: =IF(AB$8<N_st,(N_st-AB$8)/N_st,0)*(1-(1-(AB$8<=I26)*K26^AB$8)*(1-(AB$8<=J26)*L26^AB$8)) -> 0 | AC26: =IF(AC$8<N_st,(N_st-AC$8)/N_st,0)*(1-(1-(AC$8<=I26)*K26^AC$8)*(1-(AC$8<=J26)*L26^AC$8)) -> 0 | AD26: =IF(AD$8<N_st,(N_st-AD$8)/N_st,0)*(1-(1-(AD$8<=I26)*K26^AD$8)*(1-(AD$8<=J26)*L26^AD$8)) -> 0 | AE26: =IF(AE$8<N_st,(N_st-AE$8)/N_st,0)*(1-(1-(AE$8<=I26)*K26^AE$8)*(1-(AE$8<=J26)*L26^AE$8)) -> 0 | AF26: =IF(AF$8<N_st,(N_st-AF$8)/N_st,0)*(1-(1-(AF$8<=I26)*K26^AF$8)*(1-(AF$8<=J26)*L26^AF$8)) -> 0 | AG26: =IF(AG$8<N_st,(N_st-AG$8)/N_st,0)*(1-(1-(AG$8<=I26)*K26^AG$8)*(1-(AG$8<=J26)*L26^AG$8)) -> 0 | AH26: =IF(AH$8<N_st,(N_st-AH$8)/N_st,0)*(1-(1-(AH$8<=I26)*K26^AH$8)*(1-(AH$8<=J26)*L26^AH$8)) -> 0
A27: EPS_SC | B27: EPS_SC-3 | C27: 1 | D27: 0 | E27: 0 | F27: =(1/2_시험자료!$D$21)*(1-2_시험자료!$F$21) -> 0.29166667 | G27: =2_시험자료!G9 -> 487.5 | H27: =IF(E27=1,1000000000,texp1_s) -> 1200 | I27: =FLOOR(MIN(t_fs_s,H27)/G27,1) -> 1 | J27: =IF(C27=1,FLOOR(t_fs_s/tau_L_s,1),0) -> 1 | K27: =IF(D27=1,1-p_cb,1) -> 1 | L27: =IF(C27=1,p_L,0) -> 0.15 | M27: =SUMPRODUCT(w_ie1,1-(1-(j_row<=I27)*K27^j_row)*(1-(j_row<=J27)*L27^j_row)) -> 0.93333333 | N27: =occ_st*SUMPRODUCT(w_ie1,(j_row<=I27)*K27^j_row*(j_row<=J27)*L27^j_row*(((j_row*G27<rset_s)+(j_row*tau_L_s<rset_s))>0)+(j_row<=I27)*K27^j_row*(1-(j_row<=J27)*L27^j_row)*(j_row*G27<rset_s)+(1-(j_row<=I27)*K27^j_row)*(j_row<=J27)*L27^j_row*(j_row*tau_L_s<rset_s)) -> 4.6666667 | O27: =IF(O$8<N_st,(N_st-O$8)/N_st,0)*(1-(1-(O$8<=I27)*K27^O$8)*(1-(O$8<=J27)*L27^O$8)) -> 0.93333333 | P27: =IF(P$8<N_st,(N_st-P$8)/N_st,0)*(1-(1-(P$8<=I27)*K27^P$8)*(1-(P$8<=J27)*L27^P$8)) -> 0 | Q27: =IF(Q$8<N_st,(N_st-Q$8)/N_st,0)*(1-(1-(Q$8<=I27)*K27^Q$8)*(1-(Q$8<=J27)*L27^Q$8)) -> 0 | R27: =IF(R$8<N_st,(N_st-R$8)/N_st,0)*(1-(1-(R$8<=I27)*K27^R$8)*(1-(R$8<=J27)*L27^R$8)) -> 0 | S27: =IF(S$8<N_st,(N_st-S$8)/N_st,0)*(1-(1-(S$8<=I27)*K27^S$8)*(1-(S$8<=J27)*L27^S$8)) -> 0 | T27: =IF(T$8<N_st,(N_st-T$8)/N_st,0)*(1-(1-(T$8<=I27)*K27^T$8)*(1-(T$8<=J27)*L27^T$8)) -> 0 | U27: =IF(U$8<N_st,(N_st-U$8)/N_st,0)*(1-(1-(U$8<=I27)*K27^U$8)*(1-(U$8<=J27)*L27^U$8)) -> 0 | V27: =IF(V$8<N_st,(N_st-V$8)/N_st,0)*(1-(1-(V$8<=I27)*K27^V$8)*(1-(V$8<=J27)*L27^V$8)) -> 0 | W27: =IF(W$8<N_st,(N_st-W$8)/N_st,0)*(1-(1-(W$8<=I27)*K27^W$8)*(1-(W$8<=J27)*L27^W$8)) -> 0 | X27: =IF(X$8<N_st,(N_st-X$8)/N_st,0)*(1-(1-(X$8<=I27)*K27^X$8)*(1-(X$8<=J27)*L27^X$8)) -> 0 | Y27: =IF(Y$8<N_st,(N_st-Y$8)/N_st,0)*(1-(1-(Y$8<=I27)*K27^Y$8)*(1-(Y$8<=J27)*L27^Y$8)) -> 0 | Z27: =IF(Z$8<N_st,(N_st-Z$8)/N_st,0)*(1-(1-(Z$8<=I27)*K27^Z$8)*(1-(Z$8<=J27)*L27^Z$8)) -> 0 | AA27: =IF(AA$8<N_st,(N_st-AA$8)/N_st,0)*(1-(1-(AA$8<=I27)*K27^AA$8)*(1-(AA$8<=J27)*L27^AA$8)) -> 0 | AB27: =IF(AB$8<N_st,(N_st-AB$8)/N_st,0)*(1-(1-(AB$8<=I27)*K27^AB$8)*(1-(AB$8<=J27)*L27^AB$8)) -> 0 | AC27: =IF(AC$8<N_st,(N_st-AC$8)/N_st,0)*(1-(1-(AC$8<=I27)*K27^AC$8)*(1-(AC$8<=J27)*L27^AC$8)) -> 0 | AD27: =IF(AD$8<N_st,(N_st-AD$8)/N_st,0)*(1-(1-(AD$8<=I27)*K27^AD$8)*(1-(AD$8<=J27)*L27^AD$8)) -> 0 | AE27: =IF(AE$8<N_st,(N_st-AE$8)/N_st,0)*(1-(1-(AE$8<=I27)*K27^AE$8)*(1-(AE$8<=J27)*L27^AE$8)) -> 0 | AF27: =IF(AF$8<N_st,(N_st-AF$8)/N_st,0)*(1-(1-(AF$8<=I27)*K27^AF$8)*(1-(AF$8<=J27)*L27^AF$8)) -> 0 | AG27: =IF(AG$8<N_st,(N_st-AG$8)/N_st,0)*(1-(1-(AG$8<=I27)*K27^AG$8)*(1-(AG$8<=J27)*L27^AG$8)) -> 0 | AH27: =IF(AH$8<N_st,(N_st-AH$8)/N_st,0)*(1-(1-(AH$8<=I27)*K27^AH$8)*(1-(AH$8<=J27)*L27^AH$8)) -> 0
